<?xml version='1.0' encoding='utf-8'?>
<robot name="robot">
  <link name="base_link">
    <visual>
      <origin xyz="0 0 0.125" rpy="0 0 0" />
      <geometry>
        <box size="0.75 0.75 0.25" />
      </geometry>
      <material name="green" />
    </visual>
    <visual>
      <origin xyz="0 0 0.375" rpy="0 0 0" />
      <geometry>
        <cylinder length="0.25" radius="0.25" />
      </geometry>
      <material name="green">
        <color rgba="0 1 0 1" />
      </material>
    </visual>
    <collision>
      <geometry>
        <box size="0.75 0.75 0.5" />
      </geometry>
    </collision>
    <inertial>
      <mass value="0.5" />
      <inertia ixx="0.034" ixy="0.0" ixz="0.0" iyy="0.034" iyz="0.0" izz="0.034" />
    </inertial>
  </link>
  <link name="support_link">
    <visual>
      <origin xyz="0 0 0.5" rpy="0 0 0" />
      <geometry>
        <box size="0.2 0.2 1" />
      </geometry>
      <material name="white">
        <color rgba="1 1 1 1" />
      </material>
    </visual>
    <collision>
      <geometry>
        <box size="0.2 0.2 1" />
      </geometry>
    </collision>
    <inertial>
      <mass value="0.1" />
      <inertia ixx="0.01" ixy="0.0" ixz="0.0" iyy="0.01" iyz="0.0" izz="0.01" />
    </inertial>
  </link>
  <joint name="support_joint" type="continuous">
    <origin xyz="0 0 0.5" rpy="0 0 0" />
    <parent link="base_link" />
    <child link="support_link" />
    <axis xyz="0 0 1" />
  </joint>
  <link name="arm_link">
    <visual>
      <origin xyz="0 0 0.5" rpy="0 0 0" />
      <geometry>
        <box size="0.2 0.2 1" />
      </geometry>
      <material name="blue">
        <color rgba="0 0 1 1" />
      </material>
    </visual>
    <collision>
      <geometry>
        <box size="0.2 0.2 1" />
      </geometry>
    </collision>
    <inertial>
      <mass value="0.1" />
      <inertia ixx="0.01" ixy="0.0" ixz="0.0" iyy="0.01" iyz="0.0" izz="0.01" />
    </inertial>
  </link>
  <joint name="arm_joint" type="revolute">
    <origin xyz="-0.1 0 1" rpy="0 0 0" />
    <parent link="support_link" />
    <child link="arm_link" />
    <axis xyz="0 1 0" />
    <limit lower="-3.14" upper="3.14" effort="1.0" velocity="1.0" />
  </joint>
  <link name="wrist_link">
    <visual>
      <origin xyz="0 0 0.25" rpy="0 0 0" />
      <geometry>
        <box size="0.15 0.15 0.5" />
      </geometry>
      <material name="orange">
        <color rgba="1 0.5 0 1" />
      </material>
    </visual>
    <collision>
      <geometry>
        <box size="0.15 0.15 0.5" />
      </geometry>
    </collision>
    <inertial>
      <mass value="0.1" />
      <inertia ixx="0.01" ixy="0.0" ixz="0.0" iyy="0.01" iyz="0.0" izz="0.01" />
    </inertial>
  </link>
  <joint name="wrist_joint" type="fixed">
    <origin xyz="0 0 0.9" rpy="0 1.571 0" />
    <parent link="arm_link" />
    <child link="wrist_link" />
  </joint>
  <link name="palm_link">
    <visual>
      <origin xyz="0 0 0.05" rpy="0 0 0" />
      <geometry>
        <box size="0.25 0.25 0.1" />
      </geometry>
      <material name="orange" />
    </visual>
    <collision>
      <geometry>
        <box size="0.25 0.25 0.1" />
      </geometry>
    </collision>
    <inertial>
      <mass value="0.1" />
      <inertia ixx="0.01" ixy="0.0" ixz="0.0" iyy="0.01" iyz="0.0" izz="0.01" />
    </inertial>
  </link>
  <joint name="palm_joint" type="fixed">
    <origin xyz="0 0 0.45" rpy="0 0 0" />
    <parent link="wrist_link" />
    <child link="palm_link" />
  </joint>
  <link name="finger_link_0_0">
    <visual>
      <origin xyz="0 0 0.0255" rpy="0 0 0" />
      <geometry>
        <box size="0.036 0.035 0.051" />
      </geometry>
    </visual>
    <collision>
      <geometry>
        <box size="0.036 0.035 0.051" />
      </geometry>
    </collision>
    <inertial>
      <mass value="0.019" />
      <inertia ixx="0.001" iyy="0.001" izz="0.001" ixy="0" ixz="0" iyz="0" />
    </inertial>
  </link>
  <joint name="finger_joint_palm_link_to_finger_link_0_0" type="revolute">
    <origin xyz="0.124 -0.125 0.1" rpy="0 0 0" />
    <parent link="palm_link" />
    <child link="finger_link_0_0" />
    <axis xyz="1.0 0.0 0.0" />
    <limit lower="-3.142" upper="3.142" effort="10" velocity="10" />
  </joint>
  <link name="finger_link_0_1">
    <visual>
      <origin xyz="0 0 0.0355" rpy="0 0 0" />
      <geometry>
        <box size="0.041 0.013 0.071" />
      </geometry>
    </visual>
    <collision>
      <geometry>
        <box size="0.041 0.013 0.071" />
      </geometry>
    </collision>
    <inertial>
      <mass value="0.011" />
      <inertia ixx="0.001" iyy="0.001" izz="0.001" ixy="0" ixz="0" iyz="0" />
    </inertial>
  </link>
  <joint name="finger_joint_finger_link_0_0_to_finger_link_0_1" type="revolute">
    <origin xyz="0.0 0.0 0.051" rpy="0 0 0" />
    <parent link="finger_link_0_0" />
    <child link="finger_link_0_1" />
    <axis xyz="1.0 0.0 0.0" />
    <limit lower="-3.142" upper="3.142" effort="10" velocity="10" />
  </joint>
  <link name="finger_link_0_2">
    <visual>
      <origin xyz="0 0 0.036" rpy="0 0 0" />
      <geometry>
        <box size="0.037 0.024 0.072" />
      </geometry>
    </visual>
    <collision>
      <geometry>
        <box size="0.037 0.024 0.072" />
      </geometry>
    </collision>
    <inertial>
      <mass value="0.019" />
      <inertia ixx="0.001" iyy="0.001" izz="0.001" ixy="0" ixz="0" iyz="0" />
    </inertial>
  </link>
  <joint name="finger_joint_finger_link_0_1_to_finger_link_0_2" type="revolute">
    <origin xyz="0.0 0.0 0.071" rpy="0 0 0" />
    <parent link="finger_link_0_1" />
    <child link="finger_link_0_2" />
    <axis xyz="1.0 0.0 0.0" />
    <limit lower="-3.142" upper="3.142" effort="10" velocity="10" />
  </joint>
  <link name="finger_link_0_3">
    <visual>
      <origin xyz="0 0 0.0485" rpy="0 0 0" />
      <geometry>
        <box size="0.033 0.029 0.097" />
      </geometry>
    </visual>
    <collision>
      <geometry>
        <box size="0.033 0.029 0.097" />
      </geometry>
    </collision>
    <inertial>
      <mass value="0.028" />
      <inertia ixx="0.001" iyy="0.001" izz="0.001" ixy="0" ixz="0" iyz="0" />
    </inertial>
  </link>
  <joint name="finger_joint_finger_link_0_2_to_finger_link_0_3" type="revolute">
    <origin xyz="0.0 0.0 0.072" rpy="0 0 0" />
    <parent link="finger_link_0_2" />
    <child link="finger_link_0_3" />
    <axis xyz="1.0 0.0 0.0" />
    <limit lower="-3.142" upper="3.142" effort="10" velocity="10" />
  </joint>
  <link name="finger_link_0_4">
    <visual>
      <origin xyz="0 0 0.036" rpy="0 0 0" />
      <geometry>
        <box size="0.023 0.044 0.072" />
      </geometry>
    </visual>
    <collision>
      <geometry>
        <box size="0.023 0.044 0.072" />
      </geometry>
    </collision>
    <inertial>
      <mass value="0.022" />
      <inertia ixx="0.001" iyy="0.001" izz="0.001" ixy="0" ixz="0" iyz="0" />
    </inertial>
  </link>
  <joint name="finger_joint_finger_link_0_3_to_finger_link_0_4" type="revolute">
    <origin xyz="0.0 0.0 0.097" rpy="0 0 0" />
    <parent link="finger_link_0_3" />
    <child link="finger_link_0_4" />
    <axis xyz="1.0 0.0 0.0" />
    <limit lower="-3.142" upper="3.142" effort="10" velocity="10" />
  </joint>
  <link name="finger_link_0_5">
    <visual>
      <origin xyz="0 0 0.041" rpy="0 0 0" />
      <geometry>
        <box size="0.036 0.018 0.082" />
      </geometry>
    </visual>
    <collision>
      <geometry>
        <box size="0.036 0.018 0.082" />
      </geometry>
    </collision>
    <inertial>
      <mass value="0.016" />
      <inertia ixx="0.001" iyy="0.001" izz="0.001" ixy="0" ixz="0" iyz="0" />
    </inertial>
  </link>
  <joint name="finger_joint_finger_link_0_4_to_finger_link_0_5" type="revolute">
    <origin xyz="0.0 0.0 0.072" rpy="0 0 0" />
    <parent link="finger_link_0_4" />
    <child link="finger_link_0_5" />
    <axis xyz="1.0 0.0 0.0" />
    <limit lower="-3.142" upper="3.142" effort="10" velocity="10" />
  </joint>
  <link name="finger_link_1_0">
    <visual>
      <origin xyz="0 0 0.0255" rpy="0 0 0" />
      <geometry>
        <box size="0.014 0.047 0.051" />
      </geometry>
    </visual>
    <collision>
      <geometry>
        <box size="0.014 0.047 0.051" />
      </geometry>
    </collision>
    <inertial>
      <mass value="0.01" />
      <inertia ixx="0.001" iyy="0.001" izz="0.001" ixy="0" ixz="0" iyz="0" />
    </inertial>
  </link>
  <joint name="finger_joint_palm_link_to_finger_link_1_0" type="revolute">
    <origin xyz="-0.066 0.125 0.1" rpy="0 0 0" />
    <parent link="palm_link" />
    <child link="finger_link_1_0" />
    <axis xyz="-1.0 0.0 0.0" />
    <limit lower="-3.142" upper="3.142" effort="10" velocity="10" />
  </joint>
  <link name="finger_link_1_1">
    <visual>
      <origin xyz="0 0 0.0305" rpy="0 0 0" />
      <geometry>
        <box size="0.046 0.014 0.061" />
      </geometry>
    </visual>
    <collision>
      <geometry>
        <box size="0.046 0.014 0.061" />
      </geometry>
    </collision>
    <inertial>
      <mass value="0.012" />
      <inertia ixx="0.001" iyy="0.001" izz="0.001" ixy="0" ixz="0" iyz="0" />
    </inertial>
  </link>
  <joint name="finger_joint_finger_link_1_0_to_finger_link_1_1" type="revolute">
    <origin xyz="0.0 0.0 0.051" rpy="0 0 0" />
    <parent link="finger_link_1_0" />
    <child link="finger_link_1_1" />
    <axis xyz="-1.0 0.0 0.0" />
    <limit lower="-3.142" upper="3.142" effort="10" velocity="10" />
  </joint>
  <link name="finger_link_1_2">
    <visual>
      <origin xyz="0 0 0.0385" rpy="0 0 0" />
      <geometry>
        <box size="0.048 0.043 0.077" />
      </geometry>
    </visual>
    <collision>
      <geometry>
        <box size="0.048 0.043 0.077" />
      </geometry>
    </collision>
    <inertial>
      <mass value="0.048" />
      <inertia ixx="0.001" iyy="0.001" izz="0.001" ixy="0" ixz="0" iyz="0" />
    </inertial>
  </link>
  <joint name="finger_joint_finger_link_1_1_to_finger_link_1_2" type="revolute">
    <origin xyz="0.0 0.0 0.061" rpy="0 0 0" />
    <parent link="finger_link_1_1" />
    <child link="finger_link_1_2" />
    <axis xyz="-1.0 0.0 0.0" />
    <limit lower="-3.142" upper="3.142" effort="10" velocity="10" />
  </joint>
  <link name="finger_link_1_3">
    <visual>
      <origin xyz="0 0 0.0275" rpy="0 0 0" />
      <geometry>
        <box size="0.013 0.046 0.055" />
      </geometry>
    </visual>
    <collision>
      <geometry>
        <box size="0.013 0.046 0.055" />
      </geometry>
    </collision>
    <inertial>
      <mass value="0.01" />
      <inertia ixx="0.001" iyy="0.001" izz="0.001" ixy="0" ixz="0" iyz="0" />
    </inertial>
  </link>
  <joint name="finger_joint_finger_link_1_2_to_finger_link_1_3" type="revolute">
    <origin xyz="0.0 0.0 0.077" rpy="0 0 0" />
    <parent link="finger_link_1_2" />
    <child link="finger_link_1_3" />
    <axis xyz="-1.0 0.0 0.0" />
    <limit lower="-3.142" upper="3.142" effort="10" velocity="10" />
  </joint>
  <link name="finger_link_1_4">
    <visual>
      <origin xyz="0 0 0.0375" rpy="0 0 0" />
      <geometry>
        <box size="0.013 0.039 0.075" />
      </geometry>
    </visual>
    <collision>
      <geometry>
        <box size="0.013 0.039 0.075" />
      </geometry>
    </collision>
    <inertial>
      <mass value="0.011" />
      <inertia ixx="0.001" iyy="0.001" izz="0.001" ixy="0" ixz="0" iyz="0" />
    </inertial>
  </link>
  <joint name="finger_joint_finger_link_1_3_to_finger_link_1_4" type="revolute">
    <origin xyz="0.0 0.0 0.055" rpy="0 0 0" />
    <parent link="finger_link_1_3" />
    <child link="finger_link_1_4" />
    <axis xyz="-1.0 0.0 0.0" />
    <limit lower="-3.142" upper="3.142" effort="10" velocity="10" />
  </joint>
  <link name="finger_link_1_5">
    <visual>
      <origin xyz="0 0 0.0435" rpy="0 0 0" />
      <geometry>
        <box size="0.027 0.036 0.087" />
      </geometry>
    </visual>
    <collision>
      <geometry>
        <box size="0.027 0.036 0.087" />
      </geometry>
    </collision>
    <inertial>
      <mass value="0.025" />
      <inertia ixx="0.001" iyy="0.001" izz="0.001" ixy="0" ixz="0" iyz="0" />
    </inertial>
  </link>
  <joint name="finger_joint_finger_link_1_4_to_finger_link_1_5" type="revolute">
    <origin xyz="0.0 0.0 0.075" rpy="0 0 0" />
    <parent link="finger_link_1_4" />
    <child link="finger_link_1_5" />
    <axis xyz="-1.0 0.0 0.0" />
    <limit lower="-3.142" upper="3.142" effort="10" velocity="10" />
  </joint>
  <link name="finger_link_1_6">
    <visual>
      <origin xyz="0 0 0.036" rpy="0 0 0" />
      <geometry>
        <box size="0.04 0.034 0.072" />
      </geometry>
    </visual>
    <collision>
      <geometry>
        <box size="0.04 0.034 0.072" />
      </geometry>
    </collision>
    <inertial>
      <mass value="0.029" />
      <inertia ixx="0.001" iyy="0.001" izz="0.001" ixy="0" ixz="0" iyz="0" />
    </inertial>
  </link>
  <joint name="finger_joint_finger_link_1_5_to_finger_link_1_6" type="revolute">
    <origin xyz="0.0 0.0 0.087" rpy="0 0 0" />
    <parent link="finger_link_1_5" />
    <child link="finger_link_1_6" />
    <axis xyz="-1.0 0.0 0.0" />
    <limit lower="-3.142" upper="3.142" effort="10" velocity="10" />
  </joint>
  <link name="finger_link_1_7">
    <visual>
      <origin xyz="0 0 0.0375" rpy="0 0 0" />
      <geometry>
        <box size="0.017 0.019 0.075" />
      </geometry>
    </visual>
    <collision>
      <geometry>
        <box size="0.017 0.019 0.075" />
      </geometry>
    </collision>
    <inertial>
      <mass value="0.007" />
      <inertia ixx="0.001" iyy="0.001" izz="0.001" ixy="0" ixz="0" iyz="0" />
    </inertial>
  </link>
  <joint name="finger_joint_finger_link_1_6_to_finger_link_1_7" type="revolute">
    <origin xyz="0.0 0.0 0.072" rpy="0 0 0" />
    <parent link="finger_link_1_6" />
    <child link="finger_link_1_7" />
    <axis xyz="-1.0 0.0 0.0" />
    <limit lower="-3.142" upper="3.142" effort="10" velocity="10" />
  </joint>
  <link name="finger_link_2_0">
    <visual>
      <origin xyz="0 0 0.039" rpy="0 0 0" />
      <geometry>
        <box size="0.028 0.05 0.078" />
      </geometry>
    </visual>
    <collision>
      <geometry>
        <box size="0.028 0.05 0.078" />
      </geometry>
    </collision>
    <inertial>
      <mass value="0.033" />
      <inertia ixx="0.001" iyy="0.001" izz="0.001" ixy="0" ixz="0" iyz="0" />
    </inertial>
  </link>
  <joint name="finger_joint_palm_link_to_finger_link_2_0" type="revolute">
    <origin xyz="-0.096 -0.125 0.1" rpy="0 0 0" />
    <parent link="palm_link" />
    <child link="finger_link_2_0" />
    <axis xyz="1.0 0.0 0.0" />
    <limit lower="-3.142" upper="3.142" effort="10" velocity="10" />
  </joint>
  <link name="finger_link_2_1">
    <visual>
      <origin xyz="0 0 0.0475" rpy="0 0 0" />
      <geometry>
        <box size="0.021 0.022 0.095" />
      </geometry>
    </visual>
    <collision>
      <geometry>
        <box size="0.021 0.022 0.095" />
      </geometry>
    </collision>
    <inertial>
      <mass value="0.013" />
      <inertia ixx="0.001" iyy="0.001" izz="0.001" ixy="0" ixz="0" iyz="0" />
    </inertial>
  </link>
  <joint name="finger_joint_finger_link_2_0_to_finger_link_2_1" type="revolute">
    <origin xyz="0.0 0.0 0.078" rpy="0 0 0" />
    <parent link="finger_link_2_0" />
    <child link="finger_link_2_1" />
    <axis xyz="1.0 0.0 0.0" />
    <limit lower="-3.142" upper="3.142" effort="10" velocity="10" />
  </joint>
  <link name="finger_link_2_2">
    <visual>
      <origin xyz="0 0 0.035" rpy="0 0 0" />
      <geometry>
        <box size="0.014 0.043 0.07" />
      </geometry>
    </visual>
    <collision>
      <geometry>
        <box size="0.014 0.043 0.07" />
      </geometry>
    </collision>
    <inertial>
      <mass value="0.013" />
      <inertia ixx="0.001" iyy="0.001" izz="0.001" ixy="0" ixz="0" iyz="0" />
    </inertial>
  </link>
  <joint name="finger_joint_finger_link_2_1_to_finger_link_2_2" type="revolute">
    <origin xyz="0.0 0.0 0.095" rpy="0 0 0" />
    <parent link="finger_link_2_1" />
    <child link="finger_link_2_2" />
    <axis xyz="1.0 0.0 0.0" />
    <limit lower="-3.142" upper="3.142" effort="10" velocity="10" />
  </joint>
  <link name="finger_link_2_3">
    <visual>
      <origin xyz="0 0 0.0365" rpy="0 0 0" />
      <geometry>
        <box size="0.015 0.013 0.073" />
      </geometry>
    </visual>
    <collision>
      <geometry>
        <box size="0.015 0.013 0.073" />
      </geometry>
    </collision>
    <inertial>
      <mass value="0.004" />
      <inertia ixx="0.001" iyy="0.001" izz="0.001" ixy="0" ixz="0" iyz="0" />
    </inertial>
  </link>
  <joint name="finger_joint_finger_link_2_2_to_finger_link_2_3" type="revolute">
    <origin xyz="0.0 0.0 0.07" rpy="0 0 0" />
    <parent link="finger_link_2_2" />
    <child link="finger_link_2_3" />
    <axis xyz="1.0 0.0 0.0" />
    <limit lower="-3.142" upper="3.142" effort="10" velocity="10" />
  </joint>
  <link name="finger_link_3_0">
    <visual>
      <origin xyz="0 0 0.0415" rpy="0 0 0" />
      <geometry>
        <box size="0.021 0.027 0.083" />
      </geometry>
    </visual>
    <collision>
      <geometry>
        <box size="0.021 0.027 0.083" />
      </geometry>
    </collision>
    <inertial>
      <mass value="0.014" />
      <inertia ixx="0.001" iyy="0.001" izz="0.001" ixy="0" ixz="0" iyz="0" />
    </inertial>
  </link>
  <joint name="finger_joint_palm_link_to_finger_link_3_0" type="revolute">
    <origin xyz="0.055 0.125 0.1" rpy="0 0 0" />
    <parent link="palm_link" />
    <child link="finger_link_3_0" />
    <axis xyz="-1.0 0.0 0.0" />
    <limit lower="-3.142" upper="3.142" effort="10" velocity="10" />
  </joint>
  <link name="finger_link_3_1">
    <visual>
      <origin xyz="0 0 0.034" rpy="0 0 0" />
      <geometry>
        <box size="0.039 0.033 0.068" />
      </geometry>
    </visual>
    <collision>
      <geometry>
        <box size="0.039 0.033 0.068" />
      </geometry>
    </collision>
    <inertial>
      <mass value="0.026" />
      <inertia ixx="0.001" iyy="0.001" izz="0.001" ixy="0" ixz="0" iyz="0" />
    </inertial>
  </link>
  <joint name="finger_joint_finger_link_3_0_to_finger_link_3_1" type="revolute">
    <origin xyz="0.0 0.0 0.083" rpy="0 0 0" />
    <parent link="finger_link_3_0" />
    <child link="finger_link_3_1" />
    <axis xyz="-1.0 0.0 0.0" />
    <limit lower="-3.142" upper="3.142" effort="10" velocity="10" />
  </joint>
  <link name="finger_link_3_2">
    <visual>
      <origin xyz="0 0 0.0405" rpy="0 0 0" />
      <geometry>
        <box size="0.019 0.015 0.081" />
      </geometry>
    </visual>
    <collision>
      <geometry>
        <box size="0.019 0.015 0.081" />
      </geometry>
    </collision>
    <inertial>
      <mass value="0.007" />
      <inertia ixx="0.001" iyy="0.001" izz="0.001" ixy="0" ixz="0" iyz="0" />
    </inertial>
  </link>
  <joint name="finger_joint_finger_link_3_1_to_finger_link_3_2" type="revolute">
    <origin xyz="0.0 0.0 0.068" rpy="0 0 0" />
    <parent link="finger_link_3_1" />
    <child link="finger_link_3_2" />
    <axis xyz="-1.0 0.0 0.0" />
    <limit lower="-3.142" upper="3.142" effort="10" velocity="10" />
  </joint>
  <link name="finger_link_3_3">
    <visual>
      <origin xyz="0 0 0.0305" rpy="0 0 0" />
      <geometry>
        <box size="0.014 0.045 0.061" />
      </geometry>
    </visual>
    <collision>
      <geometry>
        <box size="0.014 0.045 0.061" />
      </geometry>
    </collision>
    <inertial>
      <mass value="0.012" />
      <inertia ixx="0.001" iyy="0.001" izz="0.001" ixy="0" ixz="0" iyz="0" />
    </inertial>
  </link>
  <joint name="finger_joint_finger_link_3_2_to_finger_link_3_3" type="revolute">
    <origin xyz="0.0 0.0 0.081" rpy="0 0 0" />
    <parent link="finger_link_3_2" />
    <child link="finger_link_3_3" />
    <axis xyz="-1.0 0.0 0.0" />
    <limit lower="-3.142" upper="3.142" effort="10" velocity="10" />
  </joint>
  <link name="finger_link_3_4">
    <visual>
      <origin xyz="0 0 0.0275" rpy="0 0 0" />
      <geometry>
        <box size="0.013 0.014 0.055" />
      </geometry>
    </visual>
    <collision>
      <geometry>
        <box size="0.013 0.014 0.055" />
      </geometry>
    </collision>
    <inertial>
      <mass value="0.003" />
      <inertia ixx="0.001" iyy="0.001" izz="0.001" ixy="0" ixz="0" iyz="0" />
    </inertial>
  </link>
  <joint name="finger_joint_finger_link_3_3_to_finger_link_3_4" type="revolute">
    <origin xyz="0.0 0.0 0.061" rpy="0 0 0" />
    <parent link="finger_link_3_3" />
    <child link="finger_link_3_4" />
    <axis xyz="-1.0 0.0 0.0" />
    <limit lower="-3.142" upper="3.142" effort="10" velocity="10" />
  </joint>
  <link name="finger_link_3_5">
    <visual>
      <origin xyz="0 0 0.043" rpy="0 0 0" />
      <geometry>
        <box size="0.048 0.032 0.086" />
      </geometry>
    </visual>
    <collision>
      <geometry>
        <box size="0.048 0.032 0.086" />
      </geometry>
    </collision>
    <inertial>
      <mass value="0.04" />
      <inertia ixx="0.001" iyy="0.001" izz="0.001" ixy="0" ixz="0" iyz="0" />
    </inertial>
  </link>
  <joint name="finger_joint_finger_link_3_4_to_finger_link_3_5" type="revolute">
    <origin xyz="0.0 0.0 0.055" rpy="0 0 0" />
    <parent link="finger_link_3_4" />
    <child link="finger_link_3_5" />
    <axis xyz="-1.0 0.0 0.0" />
    <limit lower="-3.142" upper="3.142" effort="10" velocity="10" />
  </joint>
</robot>