<?xml version='1.0' encoding='utf-8'?>
<robot name="robot">
  <link name="base_link">
    <visual>
      <origin xyz="0 0 0.125" rpy="0 0 0" />
      <geometry>
        <box size="0.75 0.75 0.25" />
      </geometry>
      <material name="green" />
    </visual>
    <visual>
      <origin xyz="0 0 0.375" rpy="0 0 0" />
      <geometry>
        <cylinder length="0.25" radius="0.25" />
      </geometry>
      <material name="green">
        <color rgba="0 1 0 1" />
      </material>
    </visual>
    <collision>
      <geometry>
        <box size="0.75 0.75 0.5" />
      </geometry>
    </collision>
    <inertial>
      <mass value="0.5" />
      <inertia ixx="0.034" ixy="0.0" ixz="0.0" iyy="0.034" iyz="0.0" izz="0.034" />
    </inertial>
  </link>
  <link name="support_link">
    <visual>
      <origin xyz="0 0 0.5" rpy="0 0 0" />
      <geometry>
        <box size="0.2 0.2 1" />
      </geometry>
      <material name="white">
        <color rgba="1 1 1 1" />
      </material>
    </visual>
    <collision>
      <geometry>
        <box size="0.2 0.2 1" />
      </geometry>
    </collision>
    <inertial>
      <mass value="0.1" />
      <inertia ixx="0.01" ixy="0.0" ixz="0.0" iyy="0.01" iyz="0.0" izz="0.01" />
    </inertial>
  </link>
  <joint name="support_joint" type="continuous">
    <origin xyz="0 0 0.5" rpy="0 0 0" />
    <parent link="base_link" />
    <child link="support_link" />
    <axis xyz="0 0 1" />
  </joint>
  <link name="arm_link">
    <visual>
      <origin xyz="0 0 0.5" rpy="0 0 0" />
      <geometry>
        <box size="0.2 0.2 1" />
      </geometry>
      <material name="blue">
        <color rgba="0 0 1 1" />
      </material>
    </visual>
    <collision>
      <geometry>
        <box size="0.2 0.2 1" />
      </geometry>
    </collision>
    <inertial>
      <mass value="0.1" />
      <inertia ixx="0.01" ixy="0.0" ixz="0.0" iyy="0.01" iyz="0.0" izz="0.01" />
    </inertial>
  </link>
  <joint name="arm_joint" type="revolute">
    <origin xyz="-0.1 0 1" rpy="0 0 0" />
    <parent link="support_link" />
    <child link="arm_link" />
    <axis xyz="0 1 0" />
    <limit lower="-3.14" upper="3.14" effort="1.0" velocity="1.0" />
  </joint>
  <link name="wrist_link">
    <visual>
      <origin xyz="0 0 0.25" rpy="0 0 0" />
      <geometry>
        <box size="0.15 0.15 0.5" />
      </geometry>
      <material name="orange">
        <color rgba="1 0.5 0 1" />
      </material>
    </visual>
    <collision>
      <geometry>
        <box size="0.15 0.15 0.5" />
      </geometry>
    </collision>
    <inertial>
      <mass value="0.1" />
      <inertia ixx="0.01" ixy="0.0" ixz="0.0" iyy="0.01" iyz="0.0" izz="0.01" />
    </inertial>
  </link>
  <joint name="wrist_joint" type="fixed">
    <origin xyz="0 0 0.9" rpy="0 1.571 0" />
    <parent link="arm_link" />
    <child link="wrist_link" />
  </joint>
  <link name="palm_link">
    <visual>
      <origin xyz="0 0 0.05" rpy="0 0 0" />
      <geometry>
        <box size="0.25 0.25 0.1" />
      </geometry>
      <material name="orange" />
    </visual>
    <collision>
      <geometry>
        <box size="0.25 0.25 0.1" />
      </geometry>
    </collision>
    <inertial>
      <mass value="0.1" />
      <inertia ixx="0.01" ixy="0.0" ixz="0.0" iyy="0.01" iyz="0.0" izz="0.01" />
    </inertial>
  </link>
  <joint name="palm_joint" type="fixed">
    <origin xyz="0 0 0.45" rpy="0 0 0" />
    <parent link="wrist_link" />
    <child link="palm_link" />
  </joint>
  <link name="link_0_0">
    <visual>
      <origin xyz="0 0 0.0155" rpy="0 0 0" />
      <geometry>
        <box size="0.028 0.031 0.031" />
      </geometry>
    </visual>
    <collision>
      <geometry>
        <box size="0.028 0.031 0.031" />
      </geometry>
    </collision>
    <inertial>
      <mass value="0.008" />
      <inertia ixx="0.0" iyy="0.0" izz="0.0" ixy="0" ixz="0" iyz="0" />
    </inertial>
  </link>
  <joint name="joint_palm_link_to_link_0_0" type="revolute">
    <origin xyz="-0.125 0.081 0.1" rpy="0 0 0" />
    <parent link="palm_link" />
    <child link="link_0_0" />
    <axis xyz="0.533 0.13 0.513" />
    <limit lower="-3.142" upper="3.142" effort="10" velocity="10" />
  </joint>
  <link name="link_0_1">
    <visual>
      <origin xyz="0 0 0.036" rpy="0 0 0" />
      <geometry>
        <box size="0.03 0.045 0.072" />
      </geometry>
    </visual>
    <collision>
      <geometry>
        <box size="0.03 0.045 0.072" />
      </geometry>
    </collision>
    <inertial>
      <mass value="0.029" />
      <inertia ixx="0.0" iyy="0.0" izz="0.0" ixy="0" ixz="0" iyz="0" />
    </inertial>
  </link>
  <joint name="joint_link_0_0_to_link_0_1" type="revolute">
    <origin xyz="0.0 0.0 0.031" rpy="0 0 0" />
    <parent link="link_0_0" />
    <child link="link_0_1" />
    <axis xyz="0.636 0.595 0.588" />
    <limit lower="-3.142" upper="3.142" effort="10" velocity="10" />
  </joint>
  <link name="link_0_2">
    <visual>
      <origin xyz="0 0 0.0" rpy="0 0 0" />
      <geometry>
        <box size="0.0 0.0 0.0" />
      </geometry>
    </visual>
    <collision>
      <geometry>
        <box size="0.0 0.0 0.0" />
      </geometry>
    </collision>
    <inertial>
      <mass value="0.0" />
      <inertia ixx="0.0" iyy="0.0" izz="0.0" ixy="0" ixz="0" iyz="0" />
    </inertial>
  </link>
  <joint name="joint_link_0_1_to_link_0_2" type="revolute">
    <origin xyz="0.0 0.0 0.0" rpy="0 0 0" />
    <parent link="link_0_1" />
    <child link="link_0_2" />
    <axis xyz="0.0 0.0 0.0" />
    <limit lower="-3.142" upper="3.142" effort="10" velocity="10" />
  </joint>
  <link name="link_0_3">
    <visual>
      <origin xyz="0 0 0.0" rpy="0 0 0" />
      <geometry>
        <box size="0.0 0.0 0.0" />
      </geometry>
    </visual>
    <collision>
      <geometry>
        <box size="0.0 0.0 0.0" />
      </geometry>
    </collision>
    <inertial>
      <mass value="0.0" />
      <inertia ixx="0.0" iyy="0.0" izz="0.0" ixy="0" ixz="0" iyz="0" />
    </inertial>
  </link>
  <joint name="joint_link_0_2_to_link_0_3" type="revolute">
    <origin xyz="0.0 0.0 0.0" rpy="0 0 0" />
    <parent link="link_0_2" />
    <child link="link_0_3" />
    <axis xyz="0.0 0.0 0.0" />
    <limit lower="-3.142" upper="3.142" effort="10" velocity="10" />
  </joint>
  <link name="link_0_4">
    <visual>
      <origin xyz="0 0 0.0" rpy="0 0 0" />
      <geometry>
        <box size="0.0 0.0 0.0" />
      </geometry>
    </visual>
    <collision>
      <geometry>
        <box size="0.0 0.0 0.0" />
      </geometry>
    </collision>
    <inertial>
      <mass value="0.0" />
      <inertia ixx="0.0" iyy="0.0" izz="0.0" ixy="0" ixz="0" iyz="0" />
    </inertial>
  </link>
  <joint name="joint_link_0_3_to_link_0_4" type="revolute">
    <origin xyz="0.0 0.0 0.0" rpy="0 0 0" />
    <parent link="link_0_3" />
    <child link="link_0_4" />
    <axis xyz="0.0 0.0 0.0" />
    <limit lower="-3.142" upper="3.142" effort="10" velocity="10" />
  </joint>
  <link name="link_0_5">
    <visual>
      <origin xyz="0 0 0.0" rpy="0 0 0" />
      <geometry>
        <box size="0.0 0.0 0.0" />
      </geometry>
    </visual>
    <collision>
      <geometry>
        <box size="0.0 0.0 0.0" />
      </geometry>
    </collision>
    <inertial>
      <mass value="0.0" />
      <inertia ixx="0.0" iyy="0.0" izz="0.0" ixy="0" ixz="0" iyz="0" />
    </inertial>
  </link>
  <joint name="joint_link_0_4_to_link_0_5" type="revolute">
    <origin xyz="0.0 0.0 0.0" rpy="0 0 0" />
    <parent link="link_0_4" />
    <child link="link_0_5" />
    <axis xyz="0.0 0.0 0.0" />
    <limit lower="-3.142" upper="3.142" effort="10" velocity="10" />
  </joint>
  <link name="link_0_6">
    <visual>
      <origin xyz="0 0 0.0" rpy="0 0 0" />
      <geometry>
        <box size="0.0 0.0 0.0" />
      </geometry>
    </visual>
    <collision>
      <geometry>
        <box size="0.0 0.0 0.0" />
      </geometry>
    </collision>
    <inertial>
      <mass value="0.0" />
      <inertia ixx="0.0" iyy="0.0" izz="0.0" ixy="0" ixz="0" iyz="0" />
    </inertial>
  </link>
  <joint name="joint_link_0_5_to_link_0_6" type="revolute">
    <origin xyz="0.0 0.0 0.0" rpy="0 0 0" />
    <parent link="link_0_5" />
    <child link="link_0_6" />
    <axis xyz="0.0 0.0 0.0" />
    <limit lower="-3.142" upper="3.142" effort="10" velocity="10" />
  </joint>
  <link name="link_0_7">
    <visual>
      <origin xyz="0 0 0.0" rpy="0 0 0" />
      <geometry>
        <box size="0.0 0.0 0.0" />
      </geometry>
    </visual>
    <collision>
      <geometry>
        <box size="0.0 0.0 0.0" />
      </geometry>
    </collision>
    <inertial>
      <mass value="0.0" />
      <inertia ixx="0.0" iyy="0.0" izz="0.0" ixy="0" ixz="0" iyz="0" />
    </inertial>
  </link>
  <joint name="joint_link_0_6_to_link_0_7" type="revolute">
    <origin xyz="0.0 0.0 0.0" rpy="0 0 0" />
    <parent link="link_0_6" />
    <child link="link_0_7" />
    <axis xyz="0.0 0.0 0.0" />
    <limit lower="-3.142" upper="3.142" effort="10" velocity="10" />
  </joint>
  <link name="link_0_8">
    <visual>
      <origin xyz="0 0 0.0" rpy="0 0 0" />
      <geometry>
        <box size="0.0 0.0 0.0" />
      </geometry>
    </visual>
    <collision>
      <geometry>
        <box size="0.0 0.0 0.0" />
      </geometry>
    </collision>
    <inertial>
      <mass value="0.0" />
      <inertia ixx="0.0" iyy="0.0" izz="0.0" ixy="0" ixz="0" iyz="0" />
    </inertial>
  </link>
  <joint name="joint_link_0_7_to_link_0_8" type="revolute">
    <origin xyz="0.0 0.0 0.0" rpy="0 0 0" />
    <parent link="link_0_7" />
    <child link="link_0_8" />
    <axis xyz="0.0 0.0 0.0" />
    <limit lower="-3.142" upper="3.142" effort="10" velocity="10" />
  </joint>
  <link name="link_0_9">
    <visual>
      <origin xyz="0 0 0.0" rpy="0 0 0" />
      <geometry>
        <box size="0.0 0.0 0.0" />
      </geometry>
    </visual>
    <collision>
      <geometry>
        <box size="0.0 0.0 0.0" />
      </geometry>
    </collision>
    <inertial>
      <mass value="0.0" />
      <inertia ixx="0.0" iyy="0.0" izz="0.0" ixy="0" ixz="0" iyz="0" />
    </inertial>
  </link>
  <joint name="joint_link_0_8_to_link_0_9" type="revolute">
    <origin xyz="0.0 0.0 0.0" rpy="0 0 0" />
    <parent link="link_0_8" />
    <child link="link_0_9" />
    <axis xyz="0.0 0.0 0.0" />
    <limit lower="-3.142" upper="3.142" effort="10" velocity="10" />
  </joint>
  <link name="link_1_0">
    <visual>
      <origin xyz="0 0 0.03" rpy="0 0 0" />
      <geometry>
        <box size="0.026 0.013 0.06" />
      </geometry>
    </visual>
    <collision>
      <geometry>
        <box size="0.026 0.013 0.06" />
      </geometry>
    </collision>
    <inertial>
      <mass value="0.006" />
      <inertia ixx="0.0" iyy="0.0" izz="0.0" ixy="0" ixz="0" iyz="0" />
    </inertial>
  </link>
  <joint name="joint_palm_link_to_link_1_0" type="revolute">
    <origin xyz="-0.125 -0.074 0.1" rpy="0 0 0" />
    <parent link="palm_link" />
    <child link="link_1_0" />
    <axis xyz="0.692 0.638 0.179" />
    <limit lower="-3.142" upper="3.142" effort="10" velocity="10" />
  </joint>
  <link name="link_1_1">
    <visual>
      <origin xyz="0 0 0.0085" rpy="0 0 0" />
      <geometry>
        <box size="0.029 0.029 0.017" />
      </geometry>
    </visual>
    <collision>
      <geometry>
        <box size="0.029 0.029 0.017" />
      </geometry>
    </collision>
    <inertial>
      <mass value="0.004" />
      <inertia ixx="0.0" iyy="0.0" izz="0.0" ixy="0" ixz="0" iyz="0" />
    </inertial>
  </link>
  <joint name="joint_link_1_0_to_link_1_1" type="revolute">
    <origin xyz="0.0 0.0 0.06" rpy="0 0 0" />
    <parent link="link_1_0" />
    <child link="link_1_1" />
    <axis xyz="0.608 0.793 0.581" />
    <limit lower="-3.142" upper="3.142" effort="10" velocity="10" />
  </joint>
  <link name="link_1_2">
    <visual>
      <origin xyz="0 0 0.0455" rpy="0 0 0" />
      <geometry>
        <box size="0.04 0.019 0.091" />
      </geometry>
    </visual>
    <collision>
      <geometry>
        <box size="0.04 0.019 0.091" />
      </geometry>
    </collision>
    <inertial>
      <mass value="0.021" />
      <inertia ixx="0.0" iyy="0.0" izz="0.0" ixy="0" ixz="0" iyz="0" />
    </inertial>
  </link>
  <joint name="joint_link_1_1_to_link_1_2" type="revolute">
    <origin xyz="0.0 0.0 0.017" rpy="0 0 0" />
    <parent link="link_1_1" />
    <child link="link_1_2" />
    <axis xyz="0.97 0.241 0.617" />
    <limit lower="-3.142" upper="3.142" effort="10" velocity="10" />
  </joint>
  <link name="link_1_3">
    <visual>
      <origin xyz="0 0 0.041" rpy="0 0 0" />
      <geometry>
        <box size="0.046 0.04 0.082" />
      </geometry>
    </visual>
    <collision>
      <geometry>
        <box size="0.046 0.04 0.082" />
      </geometry>
    </collision>
    <inertial>
      <mass value="0.045" />
      <inertia ixx="0.0" iyy="0.0" izz="0.0" ixy="0" ixz="0" iyz="0" />
    </inertial>
  </link>
  <joint name="joint_link_1_2_to_link_1_3" type="revolute">
    <origin xyz="0.0 0.0 0.091" rpy="0 0 0" />
    <parent link="link_1_2" />
    <child link="link_1_3" />
    <axis xyz="0.583 0.994 0.682" />
    <limit lower="-3.142" upper="3.142" effort="10" velocity="10" />
  </joint>
  <link name="link_1_4">
    <visual>
      <origin xyz="0 0 0.0" rpy="0 0 0" />
      <geometry>
        <box size="0.0 0.0 0.0" />
      </geometry>
    </visual>
    <collision>
      <geometry>
        <box size="0.0 0.0 0.0" />
      </geometry>
    </collision>
    <inertial>
      <mass value="0.0" />
      <inertia ixx="0.0" iyy="0.0" izz="0.0" ixy="0" ixz="0" iyz="0" />
    </inertial>
  </link>
  <joint name="joint_link_1_3_to_link_1_4" type="revolute">
    <origin xyz="0.0 0.0 0.0" rpy="0 0 0" />
    <parent link="link_1_3" />
    <child link="link_1_4" />
    <axis xyz="0.0 0.0 0.0" />
    <limit lower="-3.142" upper="3.142" effort="10" velocity="10" />
  </joint>
  <link name="link_1_5">
    <visual>
      <origin xyz="0 0 0.0" rpy="0 0 0" />
      <geometry>
        <box size="0.0 0.0 0.0" />
      </geometry>
    </visual>
    <collision>
      <geometry>
        <box size="0.0 0.0 0.0" />
      </geometry>
    </collision>
    <inertial>
      <mass value="0.0" />
      <inertia ixx="0.0" iyy="0.0" izz="0.0" ixy="0" ixz="0" iyz="0" />
    </inertial>
  </link>
  <joint name="joint_link_1_4_to_link_1_5" type="revolute">
    <origin xyz="0.0 0.0 0.0" rpy="0 0 0" />
    <parent link="link_1_4" />
    <child link="link_1_5" />
    <axis xyz="0.0 0.0 0.0" />
    <limit lower="-3.142" upper="3.142" effort="10" velocity="10" />
  </joint>
  <link name="link_1_6">
    <visual>
      <origin xyz="0 0 0.0" rpy="0 0 0" />
      <geometry>
        <box size="0.0 0.0 0.0" />
      </geometry>
    </visual>
    <collision>
      <geometry>
        <box size="0.0 0.0 0.0" />
      </geometry>
    </collision>
    <inertial>
      <mass value="0.0" />
      <inertia ixx="0.0" iyy="0.0" izz="0.0" ixy="0" ixz="0" iyz="0" />
    </inertial>
  </link>
  <joint name="joint_link_1_5_to_link_1_6" type="revolute">
    <origin xyz="0.0 0.0 0.0" rpy="0 0 0" />
    <parent link="link_1_5" />
    <child link="link_1_6" />
    <axis xyz="0.0 0.0 0.0" />
    <limit lower="-3.142" upper="3.142" effort="10" velocity="10" />
  </joint>
  <link name="link_1_7">
    <visual>
      <origin xyz="0 0 0.0" rpy="0 0 0" />
      <geometry>
        <box size="0.0 0.0 0.0" />
      </geometry>
    </visual>
    <collision>
      <geometry>
        <box size="0.0 0.0 0.0" />
      </geometry>
    </collision>
    <inertial>
      <mass value="0.0" />
      <inertia ixx="0.0" iyy="0.0" izz="0.0" ixy="0" ixz="0" iyz="0" />
    </inertial>
  </link>
  <joint name="joint_link_1_6_to_link_1_7" type="revolute">
    <origin xyz="0.0 0.0 0.0" rpy="0 0 0" />
    <parent link="link_1_6" />
    <child link="link_1_7" />
    <axis xyz="0.0 0.0 0.0" />
    <limit lower="-3.142" upper="3.142" effort="10" velocity="10" />
  </joint>
  <link name="link_1_8">
    <visual>
      <origin xyz="0 0 0.0" rpy="0 0 0" />
      <geometry>
        <box size="0.0 0.0 0.0" />
      </geometry>
    </visual>
    <collision>
      <geometry>
        <box size="0.0 0.0 0.0" />
      </geometry>
    </collision>
    <inertial>
      <mass value="0.0" />
      <inertia ixx="0.0" iyy="0.0" izz="0.0" ixy="0" ixz="0" iyz="0" />
    </inertial>
  </link>
  <joint name="joint_link_1_7_to_link_1_8" type="revolute">
    <origin xyz="0.0 0.0 0.0" rpy="0 0 0" />
    <parent link="link_1_7" />
    <child link="link_1_8" />
    <axis xyz="0.0 0.0 0.0" />
    <limit lower="-3.142" upper="3.142" effort="10" velocity="10" />
  </joint>
  <link name="link_1_9">
    <visual>
      <origin xyz="0 0 0.0" rpy="0 0 0" />
      <geometry>
        <box size="0.0 0.0 0.0" />
      </geometry>
    </visual>
    <collision>
      <geometry>
        <box size="0.0 0.0 0.0" />
      </geometry>
    </collision>
    <inertial>
      <mass value="0.0" />
      <inertia ixx="0.0" iyy="0.0" izz="0.0" ixy="0" ixz="0" iyz="0" />
    </inertial>
  </link>
  <joint name="joint_link_1_8_to_link_1_9" type="revolute">
    <origin xyz="0.0 0.0 0.0" rpy="0 0 0" />
    <parent link="link_1_8" />
    <child link="link_1_9" />
    <axis xyz="0.0 0.0 0.0" />
    <limit lower="-3.142" upper="3.142" effort="10" velocity="10" />
  </joint>
  <link name="link_2_0">
    <visual>
      <origin xyz="0 0 0.049" rpy="0 0 0" />
      <geometry>
        <box size="0.022 0.029 0.098" />
      </geometry>
    </visual>
    <collision>
      <geometry>
        <box size="0.022 0.029 0.098" />
      </geometry>
    </collision>
    <inertial>
      <mass value="0.019" />
      <inertia ixx="0.0" iyy="0.0" izz="0.0" ixy="0" ixz="0" iyz="0" />
    </inertial>
  </link>
  <joint name="joint_palm_link_to_link_2_0" type="revolute">
    <origin xyz="0.125 -0.03 0.1" rpy="0 0 0" />
    <parent link="palm_link" />
    <child link="link_2_0" />
    <axis xyz="0.944 0.577 0.554" />
    <limit lower="-3.142" upper="3.142" effort="10" velocity="10" />
  </joint>
  <link name="link_2_1">
    <visual>
      <origin xyz="0 0 0.0465" rpy="0 0 0" />
      <geometry>
        <box size="0.011 0.031 0.093" />
      </geometry>
    </visual>
    <collision>
      <geometry>
        <box size="0.011 0.031 0.093" />
      </geometry>
    </collision>
    <inertial>
      <mass value="0.01" />
      <inertia ixx="0.0" iyy="0.0" izz="0.0" ixy="0" ixz="0" iyz="0" />
    </inertial>
  </link>
  <joint name="joint_link_2_0_to_link_2_1" type="revolute">
    <origin xyz="0.0 0.0 0.098" rpy="0 0 0" />
    <parent link="link_2_0" />
    <child link="link_2_1" />
    <axis xyz="0.273 0.482 0.425" />
    <limit lower="-3.142" upper="3.142" effort="10" velocity="10" />
  </joint>
  <link name="link_2_2">
    <visual>
      <origin xyz="0 0 0.0295" rpy="0 0 0" />
      <geometry>
        <box size="0.048 0.018 0.059" />
      </geometry>
    </visual>
    <collision>
      <geometry>
        <box size="0.048 0.018 0.059" />
      </geometry>
    </collision>
    <inertial>
      <mass value="0.015" />
      <inertia ixx="0.0" iyy="0.0" izz="0.0" ixy="0" ixz="0" iyz="0" />
    </inertial>
  </link>
  <joint name="joint_link_2_1_to_link_2_2" type="revolute">
    <origin xyz="0.0 0.0 0.093" rpy="0 0 0" />
    <parent link="link_2_1" />
    <child link="link_2_2" />
    <axis xyz="0.622 0.249 0.056" />
    <limit lower="-3.142" upper="3.142" effort="10" velocity="10" />
  </joint>
  <link name="link_2_3">
    <visual>
      <origin xyz="0 0 0.0415" rpy="0 0 0" />
      <geometry>
        <box size="0.027 0.033 0.083" />
      </geometry>
    </visual>
    <collision>
      <geometry>
        <box size="0.027 0.033 0.083" />
      </geometry>
    </collision>
    <inertial>
      <mass value="0.022" />
      <inertia ixx="0.0" iyy="0.0" izz="0.0" ixy="0" ixz="0" iyz="0" />
    </inertial>
  </link>
  <joint name="joint_link_2_2_to_link_2_3" type="revolute">
    <origin xyz="0.0 0.0 0.059" rpy="0 0 0" />
    <parent link="link_2_2" />
    <child link="link_2_3" />
    <axis xyz="0.344 0.721 0.858" />
    <limit lower="-3.142" upper="3.142" effort="10" velocity="10" />
  </joint>
  <link name="link_2_4">
    <visual>
      <origin xyz="0 0 0.0305" rpy="0 0 0" />
      <geometry>
        <box size="0.022 0.011 0.061" />
      </geometry>
    </visual>
    <collision>
      <geometry>
        <box size="0.022 0.011 0.061" />
      </geometry>
    </collision>
    <inertial>
      <mass value="0.004" />
      <inertia ixx="0.0" iyy="0.0" izz="0.0" ixy="0" ixz="0" iyz="0" />
    </inertial>
  </link>
  <joint name="joint_link_2_3_to_link_2_4" type="revolute">
    <origin xyz="0.0 0.0 0.083" rpy="0 0 0" />
    <parent link="link_2_3" />
    <child link="link_2_4" />
    <axis xyz="0.973 0.238 0.653" />
    <limit lower="-3.142" upper="3.142" effort="10" velocity="10" />
  </joint>
  <link name="link_2_5">
    <visual>
      <origin xyz="0 0 0.037" rpy="0 0 0" />
      <geometry>
        <box size="0.022 0.02 0.074" />
      </geometry>
    </visual>
    <collision>
      <geometry>
        <box size="0.022 0.02 0.074" />
      </geometry>
    </collision>
    <inertial>
      <mass value="0.01" />
      <inertia ixx="0.0" iyy="0.0" izz="0.0" ixy="0" ixz="0" iyz="0" />
    </inertial>
  </link>
  <joint name="joint_link_2_4_to_link_2_5" type="revolute">
    <origin xyz="0.0 0.0 0.061" rpy="0 0 0" />
    <parent link="link_2_4" />
    <child link="link_2_5" />
    <axis xyz="0.907 0.453 0.668" />
    <limit lower="-3.142" upper="3.142" effort="10" velocity="10" />
  </joint>
  <link name="link_2_6">
    <visual>
      <origin xyz="0 0 0.01" rpy="0 0 0" />
      <geometry>
        <box size="0.023 0.046 0.02" />
      </geometry>
    </visual>
    <collision>
      <geometry>
        <box size="0.023 0.046 0.02" />
      </geometry>
    </collision>
    <inertial>
      <mass value="0.006" />
      <inertia ixx="0.0" iyy="0.0" izz="0.0" ixy="0" ixz="0" iyz="0" />
    </inertial>
  </link>
  <joint name="joint_link_2_5_to_link_2_6" type="revolute">
    <origin xyz="0.0 0.0 0.074" rpy="0 0 0" />
    <parent link="link_2_5" />
    <child link="link_2_6" />
    <axis xyz="0.048 0.761 0.411" />
    <limit lower="-3.142" upper="3.142" effort="10" velocity="10" />
  </joint>
  <link name="link_2_7">
    <visual>
      <origin xyz="0 0 0.023" rpy="0 0 0" />
      <geometry>
        <box size="0.046 0.029 0.046" />
      </geometry>
    </visual>
    <collision>
      <geometry>
        <box size="0.046 0.029 0.046" />
      </geometry>
    </collision>
    <inertial>
      <mass value="0.018" />
      <inertia ixx="0.0" iyy="0.0" izz="0.0" ixy="0" ixz="0" iyz="0" />
    </inertial>
  </link>
  <joint name="joint_link_2_6_to_link_2_7" type="revolute">
    <origin xyz="0.0 0.0 0.02" rpy="0 0 0" />
    <parent link="link_2_6" />
    <child link="link_2_7" />
    <axis xyz="0.58 0.39 0.903" />
    <limit lower="-3.142" upper="3.142" effort="10" velocity="10" />
  </joint>
  <link name="link_2_8">
    <visual>
      <origin xyz="0 0 0.0" rpy="0 0 0" />
      <geometry>
        <box size="0.0 0.0 0.0" />
      </geometry>
    </visual>
    <collision>
      <geometry>
        <box size="0.0 0.0 0.0" />
      </geometry>
    </collision>
    <inertial>
      <mass value="0.0" />
      <inertia ixx="0.0" iyy="0.0" izz="0.0" ixy="0" ixz="0" iyz="0" />
    </inertial>
  </link>
  <joint name="joint_link_2_7_to_link_2_8" type="revolute">
    <origin xyz="0.0 0.0 0.0" rpy="0 0 0" />
    <parent link="link_2_7" />
    <child link="link_2_8" />
    <axis xyz="0.0 0.0 0.0" />
    <limit lower="-3.142" upper="3.142" effort="10" velocity="10" />
  </joint>
  <link name="link_2_9">
    <visual>
      <origin xyz="0 0 0.0" rpy="0 0 0" />
      <geometry>
        <box size="0.0 0.0 0.0" />
      </geometry>
    </visual>
    <collision>
      <geometry>
        <box size="0.0 0.0 0.0" />
      </geometry>
    </collision>
    <inertial>
      <mass value="0.0" />
      <inertia ixx="0.0" iyy="0.0" izz="0.0" ixy="0" ixz="0" iyz="0" />
    </inertial>
  </link>
  <joint name="joint_link_2_8_to_link_2_9" type="revolute">
    <origin xyz="0.0 0.0 0.0" rpy="0 0 0" />
    <parent link="link_2_8" />
    <child link="link_2_9" />
    <axis xyz="0.0 0.0 0.0" />
    <limit lower="-3.142" upper="3.142" effort="10" velocity="10" />
  </joint>
  <link name="link_3_0">
    <visual>
      <origin xyz="0 0 0.0425" rpy="0 0 0" />
      <geometry>
        <box size="0.016 0.025 0.085" />
      </geometry>
    </visual>
    <collision>
      <geometry>
        <box size="0.016 0.025 0.085" />
      </geometry>
    </collision>
    <inertial>
      <mass value="0.01" />
      <inertia ixx="0.0" iyy="0.0" izz="0.0" ixy="0" ixz="0" iyz="0" />
    </inertial>
  </link>
  <joint name="joint_palm_link_to_link_3_0" type="revolute">
    <origin xyz="0.125 -0.107 0.1" rpy="0 0 0" />
    <parent link="palm_link" />
    <child link="link_3_0" />
    <axis xyz="0.129 0.263 0.865" />
    <limit lower="-3.142" upper="3.142" effort="10" velocity="10" />
  </joint>
  <link name="link_3_1">
    <visual>
      <origin xyz="0 0 0.02" rpy="0 0 0" />
      <geometry>
        <box size="0.035 0.029 0.04" />
      </geometry>
    </visual>
    <collision>
      <geometry>
        <box size="0.035 0.029 0.04" />
      </geometry>
    </collision>
    <inertial>
      <mass value="0.012" />
      <inertia ixx="0.0" iyy="0.0" izz="0.0" ixy="0" ixz="0" iyz="0" />
    </inertial>
  </link>
  <joint name="joint_link_3_0_to_link_3_1" type="revolute">
    <origin xyz="0.0 0.0 0.085" rpy="0 0 0" />
    <parent link="link_3_0" />
    <child link="link_3_1" />
    <axis xyz="0.488 0.571 0.911" />
    <limit lower="-3.142" upper="3.142" effort="10" velocity="10" />
  </joint>
  <link name="link_3_2">
    <visual>
      <origin xyz="0 0 0.0185" rpy="0 0 0" />
      <geometry>
        <box size="0.043 0.043 0.037" />
      </geometry>
    </visual>
    <collision>
      <geometry>
        <box size="0.043 0.043 0.037" />
      </geometry>
    </collision>
    <inertial>
      <mass value="0.021" />
      <inertia ixx="0.0" iyy="0.0" izz="0.0" ixy="0" ixz="0" iyz="0" />
    </inertial>
  </link>
  <joint name="joint_link_3_1_to_link_3_2" type="revolute">
    <origin xyz="0.0 0.0 0.04" rpy="0 0 0" />
    <parent link="link_3_1" />
    <child link="link_3_2" />
    <axis xyz="0.741 0.562 0.513" />
    <limit lower="-3.142" upper="3.142" effort="10" velocity="10" />
  </joint>
  <link name="link_3_3">
    <visual>
      <origin xyz="0 0 0.0485" rpy="0 0 0" />
      <geometry>
        <box size="0.017 0.024 0.097" />
      </geometry>
    </visual>
    <collision>
      <geometry>
        <box size="0.017 0.024 0.097" />
      </geometry>
    </collision>
    <inertial>
      <mass value="0.012" />
      <inertia ixx="0.0" iyy="0.0" izz="0.0" ixy="0" ixz="0" iyz="0" />
    </inertial>
  </link>
  <joint name="joint_link_3_2_to_link_3_3" type="revolute">
    <origin xyz="0.0 0.0 0.037" rpy="0 0 0" />
    <parent link="link_3_2" />
    <child link="link_3_3" />
    <axis xyz="0.075 0.518 0.565" />
    <limit lower="-3.142" upper="3.142" effort="10" velocity="10" />
  </joint>
  <link name="link_3_4">
    <visual>
      <origin xyz="0 0 0.044" rpy="0 0 0" />
      <geometry>
        <box size="0.049 0.026 0.088" />
      </geometry>
    </visual>
    <collision>
      <geometry>
        <box size="0.049 0.026 0.088" />
      </geometry>
    </collision>
    <inertial>
      <mass value="0.034" />
      <inertia ixx="0.0" iyy="0.0" izz="0.0" ixy="0" ixz="0" iyz="0" />
    </inertial>
  </link>
  <joint name="joint_link_3_3_to_link_3_4" type="revolute">
    <origin xyz="0.0 0.0 0.097" rpy="0 0 0" />
    <parent link="link_3_3" />
    <child link="link_3_4" />
    <axis xyz="0.126 0.55 0.82" />
    <limit lower="-3.142" upper="3.142" effort="10" velocity="10" />
  </joint>
  <link name="link_3_5">
    <visual>
      <origin xyz="0 0 0.0335" rpy="0 0 0" />
      <geometry>
        <box size="0.022 0.03 0.067" />
      </geometry>
    </visual>
    <collision>
      <geometry>
        <box size="0.022 0.03 0.067" />
      </geometry>
    </collision>
    <inertial>
      <mass value="0.013" />
      <inertia ixx="0.0" iyy="0.0" izz="0.0" ixy="0" ixz="0" iyz="0" />
    </inertial>
  </link>
  <joint name="joint_link_3_4_to_link_3_5" type="revolute">
    <origin xyz="0.0 0.0 0.088" rpy="0 0 0" />
    <parent link="link_3_4" />
    <child link="link_3_5" />
    <axis xyz="0.731 0.741 0.838" />
    <limit lower="-3.142" upper="3.142" effort="10" velocity="10" />
  </joint>
  <link name="link_3_6">
    <visual>
      <origin xyz="0 0 0.0" rpy="0 0 0" />
      <geometry>
        <box size="0.0 0.0 0.0" />
      </geometry>
    </visual>
    <collision>
      <geometry>
        <box size="0.0 0.0 0.0" />
      </geometry>
    </collision>
    <inertial>
      <mass value="0.0" />
      <inertia ixx="0.0" iyy="0.0" izz="0.0" ixy="0" ixz="0" iyz="0" />
    </inertial>
  </link>
  <joint name="joint_link_3_5_to_link_3_6" type="revolute">
    <origin xyz="0.0 0.0 0.0" rpy="0 0 0" />
    <parent link="link_3_5" />
    <child link="link_3_6" />
    <axis xyz="0.0 0.0 0.0" />
    <limit lower="-3.142" upper="3.142" effort="10" velocity="10" />
  </joint>
  <link name="link_3_7">
    <visual>
      <origin xyz="0 0 0.0" rpy="0 0 0" />
      <geometry>
        <box size="0.0 0.0 0.0" />
      </geometry>
    </visual>
    <collision>
      <geometry>
        <box size="0.0 0.0 0.0" />
      </geometry>
    </collision>
    <inertial>
      <mass value="0.0" />
      <inertia ixx="0.0" iyy="0.0" izz="0.0" ixy="0" ixz="0" iyz="0" />
    </inertial>
  </link>
  <joint name="joint_link_3_6_to_link_3_7" type="revolute">
    <origin xyz="0.0 0.0 0.0" rpy="0 0 0" />
    <parent link="link_3_6" />
    <child link="link_3_7" />
    <axis xyz="0.0 0.0 0.0" />
    <limit lower="-3.142" upper="3.142" effort="10" velocity="10" />
  </joint>
  <link name="link_3_8">
    <visual>
      <origin xyz="0 0 0.0" rpy="0 0 0" />
      <geometry>
        <box size="0.0 0.0 0.0" />
      </geometry>
    </visual>
    <collision>
      <geometry>
        <box size="0.0 0.0 0.0" />
      </geometry>
    </collision>
    <inertial>
      <mass value="0.0" />
      <inertia ixx="0.0" iyy="0.0" izz="0.0" ixy="0" ixz="0" iyz="0" />
    </inertial>
  </link>
  <joint name="joint_link_3_7_to_link_3_8" type="revolute">
    <origin xyz="0.0 0.0 0.0" rpy="0 0 0" />
    <parent link="link_3_7" />
    <child link="link_3_8" />
    <axis xyz="0.0 0.0 0.0" />
    <limit lower="-3.142" upper="3.142" effort="10" velocity="10" />
  </joint>
  <link name="link_3_9">
    <visual>
      <origin xyz="0 0 0.0" rpy="0 0 0" />
      <geometry>
        <box size="0.0 0.0 0.0" />
      </geometry>
    </visual>
    <collision>
      <geometry>
        <box size="0.0 0.0 0.0" />
      </geometry>
    </collision>
    <inertial>
      <mass value="0.0" />
      <inertia ixx="0.0" iyy="0.0" izz="0.0" ixy="0" ixz="0" iyz="0" />
    </inertial>
  </link>
  <joint name="joint_link_3_8_to_link_3_9" type="revolute">
    <origin xyz="0.0 0.0 0.0" rpy="0 0 0" />
    <parent link="link_3_8" />
    <child link="link_3_9" />
    <axis xyz="0.0 0.0 0.0" />
    <limit lower="-3.142" upper="3.142" effort="10" velocity="10" />
  </joint>
  <link name="link_4_0">
    <visual>
      <origin xyz="0 0 0.05" rpy="0 0 0" />
      <geometry>
        <box size="0.044 0.041 0.1" />
      </geometry>
    </visual>
    <collision>
      <geometry>
        <box size="0.044 0.041 0.1" />
      </geometry>
    </collision>
    <inertial>
      <mass value="0.054" />
      <inertia ixx="0.0" iyy="0.0" izz="0.0" ixy="0" ixz="0" iyz="0" />
    </inertial>
  </link>
  <joint name="joint_palm_link_to_link_4_0" type="revolute">
    <origin xyz="-0.125 -0.069 0.1" rpy="0 0 0" />
    <parent link="palm_link" />
    <child link="link_4_0" />
    <axis xyz="0.526 0.785 0.115" />
    <limit lower="-3.142" upper="3.142" effort="10" velocity="10" />
  </joint>
  <link name="link_4_1">
    <visual>
      <origin xyz="0 0 0.027" rpy="0 0 0" />
      <geometry>
        <box size="0.015 0.017 0.054" />
      </geometry>
    </visual>
    <collision>
      <geometry>
        <box size="0.015 0.017 0.054" />
      </geometry>
    </collision>
    <inertial>
      <mass value="0.004" />
      <inertia ixx="0.0" iyy="0.0" izz="0.0" ixy="0" ixz="0" iyz="0" />
    </inertial>
  </link>
  <joint name="joint_link_4_0_to_link_4_1" type="revolute">
    <origin xyz="0.0 0.0 0.1" rpy="0 0 0" />
    <parent link="link_4_0" />
    <child link="link_4_1" />
    <axis xyz="0.651 0.104 0.717" />
    <limit lower="-3.142" upper="3.142" effort="10" velocity="10" />
  </joint>
  <link name="link_4_2">
    <visual>
      <origin xyz="0 0 0.0485" rpy="0 0 0" />
      <geometry>
        <box size="0.026 0.031 0.097" />
      </geometry>
    </visual>
    <collision>
      <geometry>
        <box size="0.026 0.031 0.097" />
      </geometry>
    </collision>
    <inertial>
      <mass value="0.023" />
      <inertia ixx="0.0" iyy="0.0" izz="0.0" ixy="0" ixz="0" iyz="0" />
    </inertial>
  </link>
  <joint name="joint_link_4_1_to_link_4_2" type="revolute">
    <origin xyz="0.0 0.0 0.054" rpy="0 0 0" />
    <parent link="link_4_1" />
    <child link="link_4_2" />
    <axis xyz="0.453 0.04 0.812" />
    <limit lower="-3.142" upper="3.142" effort="10" velocity="10" />
  </joint>
  <link name="link_4_3">
    <visual>
      <origin xyz="0 0 0.0345" rpy="0 0 0" />
      <geometry>
        <box size="0.026 0.017 0.069" />
      </geometry>
    </visual>
    <collision>
      <geometry>
        <box size="0.026 0.017 0.069" />
      </geometry>
    </collision>
    <inertial>
      <mass value="0.009" />
      <inertia ixx="0.0" iyy="0.0" izz="0.0" ixy="0" ixz="0" iyz="0" />
    </inertial>
  </link>
  <joint name="joint_link_4_2_to_link_4_3" type="revolute">
    <origin xyz="0.0 0.0 0.097" rpy="0 0 0" />
    <parent link="link_4_2" />
    <child link="link_4_3" />
    <axis xyz="0.488 0.503 0.681" />
    <limit lower="-3.142" upper="3.142" effort="10" velocity="10" />
  </joint>
  <link name="link_4_4">
    <visual>
      <origin xyz="0 0 0.026" rpy="0 0 0" />
      <geometry>
        <box size="0.047 0.044 0.052" />
      </geometry>
    </visual>
    <collision>
      <geometry>
        <box size="0.047 0.044 0.052" />
      </geometry>
    </collision>
    <inertial>
      <mass value="0.032" />
      <inertia ixx="0.0" iyy="0.0" izz="0.0" ixy="0" ixz="0" iyz="0" />
    </inertial>
  </link>
  <joint name="joint_link_4_3_to_link_4_4" type="revolute">
    <origin xyz="0.0 0.0 0.069" rpy="0 0 0" />
    <parent link="link_4_3" />
    <child link="link_4_4" />
    <axis xyz="0.206 0.691 0.489" />
    <limit lower="-3.142" upper="3.142" effort="10" velocity="10" />
  </joint>
  <link name="link_4_5">
    <visual>
      <origin xyz="0 0 0.016" rpy="0 0 0" />
      <geometry>
        <box size="0.021 0.023 0.032" />
      </geometry>
    </visual>
    <collision>
      <geometry>
        <box size="0.021 0.023 0.032" />
      </geometry>
    </collision>
    <inertial>
      <mass value="0.005" />
      <inertia ixx="0.0" iyy="0.0" izz="0.0" ixy="0" ixz="0" iyz="0" />
    </inertial>
  </link>
  <joint name="joint_link_4_4_to_link_4_5" type="revolute">
    <origin xyz="0.0 0.0 0.052" rpy="0 0 0" />
    <parent link="link_4_4" />
    <child link="link_4_5" />
    <axis xyz="0.725 0.24 0.755" />
    <limit lower="-3.142" upper="3.142" effort="10" velocity="10" />
  </joint>
  <link name="link_4_6">
    <visual>
      <origin xyz="0 0 0.0" rpy="0 0 0" />
      <geometry>
        <box size="0.0 0.0 0.0" />
      </geometry>
    </visual>
    <collision>
      <geometry>
        <box size="0.0 0.0 0.0" />
      </geometry>
    </collision>
    <inertial>
      <mass value="0.0" />
      <inertia ixx="0.0" iyy="0.0" izz="0.0" ixy="0" ixz="0" iyz="0" />
    </inertial>
  </link>
  <joint name="joint_link_4_5_to_link_4_6" type="revolute">
    <origin xyz="0.0 0.0 0.0" rpy="0 0 0" />
    <parent link="link_4_5" />
    <child link="link_4_6" />
    <axis xyz="0.0 0.0 0.0" />
    <limit lower="-3.142" upper="3.142" effort="10" velocity="10" />
  </joint>
  <link name="link_4_7">
    <visual>
      <origin xyz="0 0 0.0" rpy="0 0 0" />
      <geometry>
        <box size="0.0 0.0 0.0" />
      </geometry>
    </visual>
    <collision>
      <geometry>
        <box size="0.0 0.0 0.0" />
      </geometry>
    </collision>
    <inertial>
      <mass value="0.0" />
      <inertia ixx="0.0" iyy="0.0" izz="0.0" ixy="0" ixz="0" iyz="0" />
    </inertial>
  </link>
  <joint name="joint_link_4_6_to_link_4_7" type="revolute">
    <origin xyz="0.0 0.0 0.0" rpy="0 0 0" />
    <parent link="link_4_6" />
    <child link="link_4_7" />
    <axis xyz="0.0 0.0 0.0" />
    <limit lower="-3.142" upper="3.142" effort="10" velocity="10" />
  </joint>
  <link name="link_4_8">
    <visual>
      <origin xyz="0 0 0.0" rpy="0 0 0" />
      <geometry>
        <box size="0.0 0.0 0.0" />
      </geometry>
    </visual>
    <collision>
      <geometry>
        <box size="0.0 0.0 0.0" />
      </geometry>
    </collision>
    <inertial>
      <mass value="0.0" />
      <inertia ixx="0.0" iyy="0.0" izz="0.0" ixy="0" ixz="0" iyz="0" />
    </inertial>
  </link>
  <joint name="joint_link_4_7_to_link_4_8" type="revolute">
    <origin xyz="0.0 0.0 0.0" rpy="0 0 0" />
    <parent link="link_4_7" />
    <child link="link_4_8" />
    <axis xyz="0.0 0.0 0.0" />
    <limit lower="-3.142" upper="3.142" effort="10" velocity="10" />
  </joint>
  <link name="link_4_9">
    <visual>
      <origin xyz="0 0 0.0" rpy="0 0 0" />
      <geometry>
        <box size="0.0 0.0 0.0" />
      </geometry>
    </visual>
    <collision>
      <geometry>
        <box size="0.0 0.0 0.0" />
      </geometry>
    </collision>
    <inertial>
      <mass value="0.0" />
      <inertia ixx="0.0" iyy="0.0" izz="0.0" ixy="0" ixz="0" iyz="0" />
    </inertial>
  </link>
  <joint name="joint_link_4_8_to_link_4_9" type="revolute">
    <origin xyz="0.0 0.0 0.0" rpy="0 0 0" />
    <parent link="link_4_8" />
    <child link="link_4_9" />
    <axis xyz="0.0 0.0 0.0" />
    <limit lower="-3.142" upper="3.142" effort="10" velocity="10" />
  </joint>
  <link name="link_5_0">
    <visual>
      <origin xyz="0 0 0.0" rpy="0 0 0" />
      <geometry>
        <box size="0.0 0.0 0.0" />
      </geometry>
    </visual>
    <collision>
      <geometry>
        <box size="0.0 0.0 0.0" />
      </geometry>
    </collision>
    <inertial>
      <mass value="0.0" />
      <inertia ixx="0.0" iyy="0.0" izz="0.0" ixy="0" ixz="0" iyz="0" />
    </inertial>
  </link>
  <joint name="joint_palm_link_to_link_5_0" type="revolute">
    <origin xyz="0.0 0.0 0.0" rpy="0 0 0" />
    <parent link="palm_link" />
    <child link="link_5_0" />
    <axis xyz="0.0 0.0 0.0" />
    <limit lower="-3.142" upper="3.142" effort="10" velocity="10" />
  </joint>
  <link name="link_5_1">
    <visual>
      <origin xyz="0 0 0.0" rpy="0 0 0" />
      <geometry>
        <box size="0.0 0.0 0.0" />
      </geometry>
    </visual>
    <collision>
      <geometry>
        <box size="0.0 0.0 0.0" />
      </geometry>
    </collision>
    <inertial>
      <mass value="0.0" />
      <inertia ixx="0.0" iyy="0.0" izz="0.0" ixy="0" ixz="0" iyz="0" />
    </inertial>
  </link>
  <joint name="joint_link_5_0_to_link_5_1" type="revolute">
    <origin xyz="0.0 0.0 0.0" rpy="0 0 0" />
    <parent link="link_5_0" />
    <child link="link_5_1" />
    <axis xyz="0.0 0.0 0.0" />
    <limit lower="-3.142" upper="3.142" effort="10" velocity="10" />
  </joint>
  <link name="link_5_2">
    <visual>
      <origin xyz="0 0 0.0" rpy="0 0 0" />
      <geometry>
        <box size="0.0 0.0 0.0" />
      </geometry>
    </visual>
    <collision>
      <geometry>
        <box size="0.0 0.0 0.0" />
      </geometry>
    </collision>
    <inertial>
      <mass value="0.0" />
      <inertia ixx="0.0" iyy="0.0" izz="0.0" ixy="0" ixz="0" iyz="0" />
    </inertial>
  </link>
  <joint name="joint_link_5_1_to_link_5_2" type="revolute">
    <origin xyz="0.0 0.0 0.0" rpy="0 0 0" />
    <parent link="link_5_1" />
    <child link="link_5_2" />
    <axis xyz="0.0 0.0 0.0" />
    <limit lower="-3.142" upper="3.142" effort="10" velocity="10" />
  </joint>
  <link name="link_5_3">
    <visual>
      <origin xyz="0 0 0.0" rpy="0 0 0" />
      <geometry>
        <box size="0.0 0.0 0.0" />
      </geometry>
    </visual>
    <collision>
      <geometry>
        <box size="0.0 0.0 0.0" />
      </geometry>
    </collision>
    <inertial>
      <mass value="0.0" />
      <inertia ixx="0.0" iyy="0.0" izz="0.0" ixy="0" ixz="0" iyz="0" />
    </inertial>
  </link>
  <joint name="joint_link_5_2_to_link_5_3" type="revolute">
    <origin xyz="0.0 0.0 0.0" rpy="0 0 0" />
    <parent link="link_5_2" />
    <child link="link_5_3" />
    <axis xyz="0.0 0.0 0.0" />
    <limit lower="-3.142" upper="3.142" effort="10" velocity="10" />
  </joint>
  <link name="link_5_4">
    <visual>
      <origin xyz="0 0 0.0" rpy="0 0 0" />
      <geometry>
        <box size="0.0 0.0 0.0" />
      </geometry>
    </visual>
    <collision>
      <geometry>
        <box size="0.0 0.0 0.0" />
      </geometry>
    </collision>
    <inertial>
      <mass value="0.0" />
      <inertia ixx="0.0" iyy="0.0" izz="0.0" ixy="0" ixz="0" iyz="0" />
    </inertial>
  </link>
  <joint name="joint_link_5_3_to_link_5_4" type="revolute">
    <origin xyz="0.0 0.0 0.0" rpy="0 0 0" />
    <parent link="link_5_3" />
    <child link="link_5_4" />
    <axis xyz="0.0 0.0 0.0" />
    <limit lower="-3.142" upper="3.142" effort="10" velocity="10" />
  </joint>
  <link name="link_5_5">
    <visual>
      <origin xyz="0 0 0.0" rpy="0 0 0" />
      <geometry>
        <box size="0.0 0.0 0.0" />
      </geometry>
    </visual>
    <collision>
      <geometry>
        <box size="0.0 0.0 0.0" />
      </geometry>
    </collision>
    <inertial>
      <mass value="0.0" />
      <inertia ixx="0.0" iyy="0.0" izz="0.0" ixy="0" ixz="0" iyz="0" />
    </inertial>
  </link>
  <joint name="joint_link_5_4_to_link_5_5" type="revolute">
    <origin xyz="0.0 0.0 0.0" rpy="0 0 0" />
    <parent link="link_5_4" />
    <child link="link_5_5" />
    <axis xyz="0.0 0.0 0.0" />
    <limit lower="-3.142" upper="3.142" effort="10" velocity="10" />
  </joint>
  <link name="link_5_6">
    <visual>
      <origin xyz="0 0 0.0" rpy="0 0 0" />
      <geometry>
        <box size="0.0 0.0 0.0" />
      </geometry>
    </visual>
    <collision>
      <geometry>
        <box size="0.0 0.0 0.0" />
      </geometry>
    </collision>
    <inertial>
      <mass value="0.0" />
      <inertia ixx="0.0" iyy="0.0" izz="0.0" ixy="0" ixz="0" iyz="0" />
    </inertial>
  </link>
  <joint name="joint_link_5_5_to_link_5_6" type="revolute">
    <origin xyz="0.0 0.0 0.0" rpy="0 0 0" />
    <parent link="link_5_5" />
    <child link="link_5_6" />
    <axis xyz="0.0 0.0 0.0" />
    <limit lower="-3.142" upper="3.142" effort="10" velocity="10" />
  </joint>
  <link name="link_5_7">
    <visual>
      <origin xyz="0 0 0.0" rpy="0 0 0" />
      <geometry>
        <box size="0.0 0.0 0.0" />
      </geometry>
    </visual>
    <collision>
      <geometry>
        <box size="0.0 0.0 0.0" />
      </geometry>
    </collision>
    <inertial>
      <mass value="0.0" />
      <inertia ixx="0.0" iyy="0.0" izz="0.0" ixy="0" ixz="0" iyz="0" />
    </inertial>
  </link>
  <joint name="joint_link_5_6_to_link_5_7" type="revolute">
    <origin xyz="0.0 0.0 0.0" rpy="0 0 0" />
    <parent link="link_5_6" />
    <child link="link_5_7" />
    <axis xyz="0.0 0.0 0.0" />
    <limit lower="-3.142" upper="3.142" effort="10" velocity="10" />
  </joint>
  <link name="link_5_8">
    <visual>
      <origin xyz="0 0 0.0" rpy="0 0 0" />
      <geometry>
        <box size="0.0 0.0 0.0" />
      </geometry>
    </visual>
    <collision>
      <geometry>
        <box size="0.0 0.0 0.0" />
      </geometry>
    </collision>
    <inertial>
      <mass value="0.0" />
      <inertia ixx="0.0" iyy="0.0" izz="0.0" ixy="0" ixz="0" iyz="0" />
    </inertial>
  </link>
  <joint name="joint_link_5_7_to_link_5_8" type="revolute">
    <origin xyz="0.0 0.0 0.0" rpy="0 0 0" />
    <parent link="link_5_7" />
    <child link="link_5_8" />
    <axis xyz="0.0 0.0 0.0" />
    <limit lower="-3.142" upper="3.142" effort="10" velocity="10" />
  </joint>
  <link name="link_5_9">
    <visual>
      <origin xyz="0 0 0.0" rpy="0 0 0" />
      <geometry>
        <box size="0.0 0.0 0.0" />
      </geometry>
    </visual>
    <collision>
      <geometry>
        <box size="0.0 0.0 0.0" />
      </geometry>
    </collision>
    <inertial>
      <mass value="0.0" />
      <inertia ixx="0.0" iyy="0.0" izz="0.0" ixy="0" ixz="0" iyz="0" />
    </inertial>
  </link>
  <joint name="joint_link_5_8_to_link_5_9" type="revolute">
    <origin xyz="0.0 0.0 0.0" rpy="0 0 0" />
    <parent link="link_5_8" />
    <child link="link_5_9" />
    <axis xyz="0.0 0.0 0.0" />
    <limit lower="-3.142" upper="3.142" effort="10" velocity="10" />
  </joint>
  <link name="link_6_0">
    <visual>
      <origin xyz="0 0 0.0" rpy="0 0 0" />
      <geometry>
        <box size="0.0 0.0 0.0" />
      </geometry>
    </visual>
    <collision>
      <geometry>
        <box size="0.0 0.0 0.0" />
      </geometry>
    </collision>
    <inertial>
      <mass value="0.0" />
      <inertia ixx="0.0" iyy="0.0" izz="0.0" ixy="0" ixz="0" iyz="0" />
    </inertial>
  </link>
  <joint name="joint_palm_link_to_link_6_0" type="revolute">
    <origin xyz="0.0 0.0 0.0" rpy="0 0 0" />
    <parent link="palm_link" />
    <child link="link_6_0" />
    <axis xyz="0.0 0.0 0.0" />
    <limit lower="-3.142" upper="3.142" effort="10" velocity="10" />
  </joint>
  <link name="link_6_1">
    <visual>
      <origin xyz="0 0 0.0" rpy="0 0 0" />
      <geometry>
        <box size="0.0 0.0 0.0" />
      </geometry>
    </visual>
    <collision>
      <geometry>
        <box size="0.0 0.0 0.0" />
      </geometry>
    </collision>
    <inertial>
      <mass value="0.0" />
      <inertia ixx="0.0" iyy="0.0" izz="0.0" ixy="0" ixz="0" iyz="0" />
    </inertial>
  </link>
  <joint name="joint_link_6_0_to_link_6_1" type="revolute">
    <origin xyz="0.0 0.0 0.0" rpy="0 0 0" />
    <parent link="link_6_0" />
    <child link="link_6_1" />
    <axis xyz="0.0 0.0 0.0" />
    <limit lower="-3.142" upper="3.142" effort="10" velocity="10" />
  </joint>
  <link name="link_6_2">
    <visual>
      <origin xyz="0 0 0.0" rpy="0 0 0" />
      <geometry>
        <box size="0.0 0.0 0.0" />
      </geometry>
    </visual>
    <collision>
      <geometry>
        <box size="0.0 0.0 0.0" />
      </geometry>
    </collision>
    <inertial>
      <mass value="0.0" />
      <inertia ixx="0.0" iyy="0.0" izz="0.0" ixy="0" ixz="0" iyz="0" />
    </inertial>
  </link>
  <joint name="joint_link_6_1_to_link_6_2" type="revolute">
    <origin xyz="0.0 0.0 0.0" rpy="0 0 0" />
    <parent link="link_6_1" />
    <child link="link_6_2" />
    <axis xyz="0.0 0.0 0.0" />
    <limit lower="-3.142" upper="3.142" effort="10" velocity="10" />
  </joint>
  <link name="link_6_3">
    <visual>
      <origin xyz="0 0 0.0" rpy="0 0 0" />
      <geometry>
        <box size="0.0 0.0 0.0" />
      </geometry>
    </visual>
    <collision>
      <geometry>
        <box size="0.0 0.0 0.0" />
      </geometry>
    </collision>
    <inertial>
      <mass value="0.0" />
      <inertia ixx="0.0" iyy="0.0" izz="0.0" ixy="0" ixz="0" iyz="0" />
    </inertial>
  </link>
  <joint name="joint_link_6_2_to_link_6_3" type="revolute">
    <origin xyz="0.0 0.0 0.0" rpy="0 0 0" />
    <parent link="link_6_2" />
    <child link="link_6_3" />
    <axis xyz="0.0 0.0 0.0" />
    <limit lower="-3.142" upper="3.142" effort="10" velocity="10" />
  </joint>
  <link name="link_6_4">
    <visual>
      <origin xyz="0 0 0.0" rpy="0 0 0" />
      <geometry>
        <box size="0.0 0.0 0.0" />
      </geometry>
    </visual>
    <collision>
      <geometry>
        <box size="0.0 0.0 0.0" />
      </geometry>
    </collision>
    <inertial>
      <mass value="0.0" />
      <inertia ixx="0.0" iyy="0.0" izz="0.0" ixy="0" ixz="0" iyz="0" />
    </inertial>
  </link>
  <joint name="joint_link_6_3_to_link_6_4" type="revolute">
    <origin xyz="0.0 0.0 0.0" rpy="0 0 0" />
    <parent link="link_6_3" />
    <child link="link_6_4" />
    <axis xyz="0.0 0.0 0.0" />
    <limit lower="-3.142" upper="3.142" effort="10" velocity="10" />
  </joint>
  <link name="link_6_5">
    <visual>
      <origin xyz="0 0 0.0" rpy="0 0 0" />
      <geometry>
        <box size="0.0 0.0 0.0" />
      </geometry>
    </visual>
    <collision>
      <geometry>
        <box size="0.0 0.0 0.0" />
      </geometry>
    </collision>
    <inertial>
      <mass value="0.0" />
      <inertia ixx="0.0" iyy="0.0" izz="0.0" ixy="0" ixz="0" iyz="0" />
    </inertial>
  </link>
  <joint name="joint_link_6_4_to_link_6_5" type="revolute">
    <origin xyz="0.0 0.0 0.0" rpy="0 0 0" />
    <parent link="link_6_4" />
    <child link="link_6_5" />
    <axis xyz="0.0 0.0 0.0" />
    <limit lower="-3.142" upper="3.142" effort="10" velocity="10" />
  </joint>
  <link name="link_6_6">
    <visual>
      <origin xyz="0 0 0.0" rpy="0 0 0" />
      <geometry>
        <box size="0.0 0.0 0.0" />
      </geometry>
    </visual>
    <collision>
      <geometry>
        <box size="0.0 0.0 0.0" />
      </geometry>
    </collision>
    <inertial>
      <mass value="0.0" />
      <inertia ixx="0.0" iyy="0.0" izz="0.0" ixy="0" ixz="0" iyz="0" />
    </inertial>
  </link>
  <joint name="joint_link_6_5_to_link_6_6" type="revolute">
    <origin xyz="0.0 0.0 0.0" rpy="0 0 0" />
    <parent link="link_6_5" />
    <child link="link_6_6" />
    <axis xyz="0.0 0.0 0.0" />
    <limit lower="-3.142" upper="3.142" effort="10" velocity="10" />
  </joint>
  <link name="link_6_7">
    <visual>
      <origin xyz="0 0 0.0" rpy="0 0 0" />
      <geometry>
        <box size="0.0 0.0 0.0" />
      </geometry>
    </visual>
    <collision>
      <geometry>
        <box size="0.0 0.0 0.0" />
      </geometry>
    </collision>
    <inertial>
      <mass value="0.0" />
      <inertia ixx="0.0" iyy="0.0" izz="0.0" ixy="0" ixz="0" iyz="0" />
    </inertial>
  </link>
  <joint name="joint_link_6_6_to_link_6_7" type="revolute">
    <origin xyz="0.0 0.0 0.0" rpy="0 0 0" />
    <parent link="link_6_6" />
    <child link="link_6_7" />
    <axis xyz="0.0 0.0 0.0" />
    <limit lower="-3.142" upper="3.142" effort="10" velocity="10" />
  </joint>
  <link name="link_6_8">
    <visual>
      <origin xyz="0 0 0.0" rpy="0 0 0" />
      <geometry>
        <box size="0.0 0.0 0.0" />
      </geometry>
    </visual>
    <collision>
      <geometry>
        <box size="0.0 0.0 0.0" />
      </geometry>
    </collision>
    <inertial>
      <mass value="0.0" />
      <inertia ixx="0.0" iyy="0.0" izz="0.0" ixy="0" ixz="0" iyz="0" />
    </inertial>
  </link>
  <joint name="joint_link_6_7_to_link_6_8" type="revolute">
    <origin xyz="0.0 0.0 0.0" rpy="0 0 0" />
    <parent link="link_6_7" />
    <child link="link_6_8" />
    <axis xyz="0.0 0.0 0.0" />
    <limit lower="-3.142" upper="3.142" effort="10" velocity="10" />
  </joint>
  <link name="link_6_9">
    <visual>
      <origin xyz="0 0 0.0" rpy="0 0 0" />
      <geometry>
        <box size="0.0 0.0 0.0" />
      </geometry>
    </visual>
    <collision>
      <geometry>
        <box size="0.0 0.0 0.0" />
      </geometry>
    </collision>
    <inertial>
      <mass value="0.0" />
      <inertia ixx="0.0" iyy="0.0" izz="0.0" ixy="0" ixz="0" iyz="0" />
    </inertial>
  </link>
  <joint name="joint_link_6_8_to_link_6_9" type="revolute">
    <origin xyz="0.0 0.0 0.0" rpy="0 0 0" />
    <parent link="link_6_8" />
    <child link="link_6_9" />
    <axis xyz="0.0 0.0 0.0" />
    <limit lower="-3.142" upper="3.142" effort="10" velocity="10" />
  </joint>
</robot>