<?xml version='1.0' encoding='utf-8'?>
<robot name="robot">
  <link name="base_link">
    <visual>
      <origin xyz="0 0 0.125" rpy="0 0 0" />
      <geometry>
        <box size="0.75 0.75 0.25" />
      </geometry>
      <material name="green" />
    </visual>
    <visual>
      <origin xyz="0 0 0.375" rpy="0 0 0" />
      <geometry>
        <cylinder length="0.25" radius="0.25" />
      </geometry>
      <material name="green">
        <color rgba="0 1 0 1" />
      </material>
    </visual>
    <collision>
      <geometry>
        <box size="0.75 0.75 0.5" />
      </geometry>
    </collision>
    <inertial>
      <mass value="0.5" />
      <inertia ixx="0.034" ixy="0.0" ixz="0.0" iyy="0.034" iyz="0.0" izz="0.034" />
    </inertial>
  </link>
  <link name="support_link">
    <visual>
      <origin xyz="0 0 0.5" rpy="0 0 0" />
      <geometry>
        <box size="0.2 0.2 1" />
      </geometry>
      <material name="white">
        <color rgba="1 1 1 1" />
      </material>
    </visual>
    <collision>
      <geometry>
        <box size="0.2 0.2 1" />
      </geometry>
    </collision>
    <inertial>
      <mass value="0.1" />
      <inertia ixx="0.01" ixy="0.0" ixz="0.0" iyy="0.01" iyz="0.0" izz="0.01" />
    </inertial>
  </link>
  <joint name="support_joint" type="continuous">
    <origin xyz="0 0 0.5" rpy="0 0 0" />
    <parent link="base_link" />
    <child link="support_link" />
    <axis xyz="0 0 1" />
  </joint>
  <link name="arm_link">
    <visual>
      <origin xyz="0 0 0.5" rpy="0 0 0" />
      <geometry>
        <box size="0.2 0.2 1" />
      </geometry>
      <material name="blue">
        <color rgba="0 0 1 1" />
      </material>
    </visual>
    <collision>
      <geometry>
        <box size="0.2 0.2 1" />
      </geometry>
    </collision>
    <inertial>
      <mass value="0.1" />
      <inertia ixx="0.01" ixy="0.0" ixz="0.0" iyy="0.01" iyz="0.0" izz="0.01" />
    </inertial>
  </link>
  <joint name="arm_joint" type="revolute">
    <origin xyz="-0.1 0 1" rpy="0 0 0" />
    <parent link="support_link" />
    <child link="arm_link" />
    <axis xyz="0 1 0" />
    <limit lower="-3.14" upper="3.14" effort="1.0" velocity="1.0" />
  </joint>
  <link name="wrist_link">
    <visual>
      <origin xyz="0 0 0.25" rpy="0 0 0" />
      <geometry>
        <box size="0.15 0.15 0.5" />
      </geometry>
      <material name="orange">
        <color rgba="1 0.5 0 1" />
      </material>
    </visual>
    <collision>
      <geometry>
        <box size="0.15 0.15 0.5" />
      </geometry>
    </collision>
    <inertial>
      <mass value="0.1" />
      <inertia ixx="0.01" ixy="0.0" ixz="0.0" iyy="0.01" iyz="0.0" izz="0.01" />
    </inertial>
  </link>
  <joint name="wrist_joint" type="fixed">
    <origin xyz="0 0 0.9" rpy="0 1.571 0" />
    <parent link="arm_link" />
    <child link="wrist_link" />
  </joint>
  <link name="palm_link">
    <visual>
      <origin xyz="0 0 0.05" rpy="0 0 0" />
      <geometry>
        <box size="0.25 0.25 0.1" />
      </geometry>
      <material name="orange" />
    </visual>
    <collision>
      <geometry>
        <box size="0.25 0.25 0.1" />
      </geometry>
    </collision>
    <inertial>
      <mass value="0.1" />
      <inertia ixx="0.01" ixy="0.0" ixz="0.0" iyy="0.01" iyz="0.0" izz="0.01" />
    </inertial>
  </link>
  <joint name="palm_joint" type="fixed">
    <origin xyz="0 0 0.45" rpy="0 0 0" />
    <parent link="wrist_link" />
    <child link="palm_link" />
  </joint>
  <link name="link_0_0">
    <visual>
      <origin xyz="0 0 0.0335" rpy="0 0 0" />
      <geometry>
        <box size="0.017 0.025 0.067" />
      </geometry>
    </visual>
    <collision>
      <geometry>
        <box size="0.017 0.025 0.067" />
      </geometry>
    </collision>
    <inertial>
      <mass value="0.009" />
      <inertia ixx="0.0" iyy="0.0" izz="0.0" ixy="0" ixz="0" iyz="0" />
    </inertial>
  </link>
  <joint name="joint_palm_link_to_link_0_0" type="revolute">
    <origin xyz="0.125 -0.103 0.1" rpy="0 0 0" />
    <parent link="palm_link" />
    <child link="link_0_0" />
    <axis xyz="0.732 0.15 0.524" />
    <limit lower="-3.142" upper="3.142" effort="10" velocity="10" />
  </joint>
  <link name="link_0_1">
    <visual>
      <origin xyz="0 0 0.0135" rpy="0 0 0" />
      <geometry>
        <box size="0.022 0.046 0.027" />
      </geometry>
    </visual>
    <collision>
      <geometry>
        <box size="0.022 0.046 0.027" />
      </geometry>
    </collision>
    <inertial>
      <mass value="0.008" />
      <inertia ixx="0.0" iyy="0.0" izz="0.0" ixy="0" ixz="0" iyz="0" />
    </inertial>
  </link>
  <joint name="joint_link_0_0_to_link_0_1" type="revolute">
    <origin xyz="0.0 0.0 0.067" rpy="0 0 0" />
    <parent link="link_0_0" />
    <child link="link_0_1" />
    <axis xyz="0.336 0.07 0.08" />
    <limit lower="-3.142" upper="3.142" effort="10" velocity="10" />
  </joint>
  <link name="link_0_2">
    <visual>
      <origin xyz="0 0 0.041" rpy="0 0 0" />
      <geometry>
        <box size="0.046 0.045 0.082" />
      </geometry>
    </visual>
    <collision>
      <geometry>
        <box size="0.046 0.045 0.082" />
      </geometry>
    </collision>
    <inertial>
      <mass value="0.051" />
      <inertia ixx="0.0" iyy="0.0" izz="0.0" ixy="0" ixz="0" iyz="0" />
    </inertial>
  </link>
  <joint name="joint_link_0_1_to_link_0_2" type="revolute">
    <origin xyz="0.0 0.0 0.027" rpy="0 0 0" />
    <parent link="link_0_1" />
    <child link="link_0_2" />
    <axis xyz="0.15 0.318 0.125" />
    <limit lower="-3.142" upper="3.142" effort="10" velocity="10" />
  </joint>
  <link name="link_1_0">
    <visual>
      <origin xyz="0 0 0.013" rpy="0 0 0" />
      <geometry>
        <box size="0.041 0.041 0.026" />
      </geometry>
    </visual>
    <collision>
      <geometry>
        <box size="0.041 0.041 0.026" />
      </geometry>
    </collision>
    <inertial>
      <mass value="0.013" />
      <inertia ixx="0.0" iyy="0.0" izz="0.0" ixy="0" ixz="0" iyz="0" />
    </inertial>
  </link>
  <joint name="joint_palm_link_to_link_1_0" type="revolute">
    <origin xyz="-0.125 0.107 0.1" rpy="0 0 0" />
    <parent link="palm_link" />
    <child link="link_1_0" />
    <axis xyz="0.886 0.58 0.092" />
    <limit lower="-3.142" upper="3.142" effort="10" velocity="10" />
  </joint>
  <link name="link_1_1">
    <visual>
      <origin xyz="0 0 0.0345" rpy="0 0 0" />
      <geometry>
        <box size="0.047 0.04 0.069" />
      </geometry>
    </visual>
    <collision>
      <geometry>
        <box size="0.047 0.04 0.069" />
      </geometry>
    </collision>
    <inertial>
      <mass value="0.039" />
      <inertia ixx="0.0" iyy="0.0" izz="0.0" ixy="0" ixz="0" iyz="0" />
    </inertial>
  </link>
  <joint name="joint_link_1_0_to_link_1_1" type="revolute">
    <origin xyz="0.0 0.0 0.026" rpy="0 0 0" />
    <parent link="link_1_0" />
    <child link="link_1_1" />
    <axis xyz="0.572 0.681 0.102" />
    <limit lower="-3.142" upper="3.142" effort="10" velocity="10" />
  </joint>
  <link name="link_1_2">
    <visual>
      <origin xyz="0 0 0.0105" rpy="0 0 0" />
      <geometry>
        <box size="0.031 0.024 0.021" />
      </geometry>
    </visual>
    <collision>
      <geometry>
        <box size="0.031 0.024 0.021" />
      </geometry>
    </collision>
    <inertial>
      <mass value="0.005" />
      <inertia ixx="0.0" iyy="0.0" izz="0.0" ixy="0" ixz="0" iyz="0" />
    </inertial>
  </link>
  <joint name="joint_link_1_1_to_link_1_2" type="revolute">
    <origin xyz="0.0 0.0 0.069" rpy="0 0 0" />
    <parent link="link_1_1" />
    <child link="link_1_2" />
    <axis xyz="0.956 0.829 0.532" />
    <limit lower="-3.142" upper="3.142" effort="10" velocity="10" />
  </joint>
  <link name="link_1_3">
    <visual>
      <origin xyz="0 0 0.039" rpy="0 0 0" />
      <geometry>
        <box size="0.027 0.038 0.078" />
      </geometry>
    </visual>
    <collision>
      <geometry>
        <box size="0.027 0.038 0.078" />
      </geometry>
    </collision>
    <inertial>
      <mass value="0.024" />
      <inertia ixx="0.0" iyy="0.0" izz="0.0" ixy="0" ixz="0" iyz="0" />
    </inertial>
  </link>
  <joint name="joint_link_1_2_to_link_1_3" type="revolute">
    <origin xyz="0.0 0.0 0.021" rpy="0 0 0" />
    <parent link="link_1_2" />
    <child link="link_1_3" />
    <axis xyz="0.564 0.66 0.775" />
    <limit lower="-3.142" upper="3.142" effort="10" velocity="10" />
  </joint>
  <link name="link_1_4">
    <visual>
      <origin xyz="0 0 0.0275" rpy="0 0 0" />
      <geometry>
        <box size="0.021 0.039 0.055" />
      </geometry>
    </visual>
    <collision>
      <geometry>
        <box size="0.021 0.039 0.055" />
      </geometry>
    </collision>
    <inertial>
      <mass value="0.014" />
      <inertia ixx="0.0" iyy="0.0" izz="0.0" ixy="0" ixz="0" iyz="0" />
    </inertial>
  </link>
  <joint name="joint_link_1_3_to_link_1_4" type="revolute">
    <origin xyz="0.0 0.0 0.078" rpy="0 0 0" />
    <parent link="link_1_3" />
    <child link="link_1_4" />
    <axis xyz="0.414 0.577 0.816" />
    <limit lower="-3.142" upper="3.142" effort="10" velocity="10" />
  </joint>
  <link name="link_1_5">
    <visual>
      <origin xyz="0 0 0.0285" rpy="0 0 0" />
      <geometry>
        <box size="0.014 0.011 0.057" />
      </geometry>
    </visual>
    <collision>
      <geometry>
        <box size="0.014 0.011 0.057" />
      </geometry>
    </collision>
    <inertial>
      <mass value="0.003" />
      <inertia ixx="0.0" iyy="0.0" izz="0.0" ixy="0" ixz="0" iyz="0" />
    </inertial>
  </link>
  <joint name="joint_link_1_4_to_link_1_5" type="revolute">
    <origin xyz="0.0 0.0 0.055" rpy="0 0 0" />
    <parent link="link_1_4" />
    <child link="link_1_5" />
    <axis xyz="0.737 0.439 0.884" />
    <limit lower="-3.142" upper="3.142" effort="10" velocity="10" />
  </joint>
  <link name="link_2_0">
    <visual>
      <origin xyz="0 0 0.0265" rpy="0 0 0" />
      <geometry>
        <box size="0.026 0.041 0.053" />
      </geometry>
    </visual>
    <collision>
      <geometry>
        <box size="0.026 0.041 0.053" />
      </geometry>
    </collision>
    <inertial>
      <mass value="0.017" />
      <inertia ixx="0.0" iyy="0.0" izz="0.0" ixy="0" ixz="0" iyz="0" />
    </inertial>
  </link>
  <joint name="joint_palm_link_to_link_2_0" type="revolute">
    <origin xyz="0.125 0.056 0.1" rpy="0 0 0" />
    <parent link="palm_link" />
    <child link="link_2_0" />
    <axis xyz="0.189 0.704 0.58" />
    <limit lower="-3.142" upper="3.142" effort="10" velocity="10" />
  </joint>
  <link name="link_2_1">
    <visual>
      <origin xyz="0 0 0.026" rpy="0 0 0" />
      <geometry>
        <box size="0.042 0.016 0.052" />
      </geometry>
    </visual>
    <collision>
      <geometry>
        <box size="0.042 0.016 0.052" />
      </geometry>
    </collision>
    <inertial>
      <mass value="0.01" />
      <inertia ixx="0.0" iyy="0.0" izz="0.0" ixy="0" ixz="0" iyz="0" />
    </inertial>
  </link>
  <joint name="joint_link_2_0_to_link_2_1" type="revolute">
    <origin xyz="0.0 0.0 0.053" rpy="0 0 0" />
    <parent link="link_2_0" />
    <child link="link_2_1" />
    <axis xyz="0.388 0.807 0.044" />
    <limit lower="-3.142" upper="3.142" effort="10" velocity="10" />
  </joint>
  <link name="link_2_2">
    <visual>
      <origin xyz="0 0 0.0395" rpy="0 0 0" />
      <geometry>
        <box size="0.039 0.032 0.079" />
      </geometry>
    </visual>
    <collision>
      <geometry>
        <box size="0.039 0.032 0.079" />
      </geometry>
    </collision>
    <inertial>
      <mass value="0.03" />
      <inertia ixx="0.0" iyy="0.0" izz="0.0" ixy="0" ixz="0" iyz="0" />
    </inertial>
  </link>
  <joint name="joint_link_2_1_to_link_2_2" type="revolute">
    <origin xyz="0.0 0.0 0.052" rpy="0 0 0" />
    <parent link="link_2_1" />
    <child link="link_2_2" />
    <axis xyz="0.392 0.246 0.621" />
    <limit lower="-3.142" upper="3.142" effort="10" velocity="10" />
  </joint>
  <link name="link_2_3">
    <visual>
      <origin xyz="0 0 0.019" rpy="0 0 0" />
      <geometry>
        <box size="0.042 0.037 0.038" />
      </geometry>
    </visual>
    <collision>
      <geometry>
        <box size="0.042 0.037 0.038" />
      </geometry>
    </collision>
    <inertial>
      <mass value="0.018" />
      <inertia ixx="0.0" iyy="0.0" izz="0.0" ixy="0" ixz="0" iyz="0" />
    </inertial>
  </link>
  <joint name="joint_link_2_2_to_link_2_3" type="revolute">
    <origin xyz="0.0 0.0 0.079" rpy="0 0 0" />
    <parent link="link_2_2" />
    <child link="link_2_3" />
    <axis xyz="0.855 0.961 0.991" />
    <limit lower="-3.142" upper="3.142" effort="10" velocity="10" />
  </joint>
  <link name="link_2_4">
    <visual>
      <origin xyz="0 0 0.0075" rpy="0 0 0" />
      <geometry>
        <box size="0.049 0.046 0.015" />
      </geometry>
    </visual>
    <collision>
      <geometry>
        <box size="0.049 0.046 0.015" />
      </geometry>
    </collision>
    <inertial>
      <mass value="0.01" />
      <inertia ixx="0.0" iyy="0.0" izz="0.0" ixy="0" ixz="0" iyz="0" />
    </inertial>
  </link>
  <joint name="joint_link_2_3_to_link_2_4" type="revolute">
    <origin xyz="0.0 0.0 0.038" rpy="0 0 0" />
    <parent link="link_2_3" />
    <child link="link_2_4" />
    <axis xyz="0.528 0.997 0.399" />
    <limit lower="-3.142" upper="3.142" effort="10" velocity="10" />
  </joint>
  <link name="link_2_5">
    <visual>
      <origin xyz="0 0 0.0215" rpy="0 0 0" />
      <geometry>
        <box size="0.038 0.031 0.043" />
      </geometry>
    </visual>
    <collision>
      <geometry>
        <box size="0.038 0.031 0.043" />
      </geometry>
    </collision>
    <inertial>
      <mass value="0.015" />
      <inertia ixx="0.0" iyy="0.0" izz="0.0" ixy="0" ixz="0" iyz="0" />
    </inertial>
  </link>
  <joint name="joint_link_2_4_to_link_2_5" type="revolute">
    <origin xyz="0.0 0.0 0.015" rpy="0 0 0" />
    <parent link="link_2_4" />
    <child link="link_2_5" />
    <axis xyz="0.311 0.192 0.194" />
    <limit lower="-3.142" upper="3.142" effort="10" velocity="10" />
  </joint>
  <link name="link_2_6">
    <visual>
      <origin xyz="0 0 0.045" rpy="0 0 0" />
      <geometry>
        <box size="0.015 0.043 0.09" />
      </geometry>
    </visual>
    <collision>
      <geometry>
        <box size="0.015 0.043 0.09" />
      </geometry>
    </collision>
    <inertial>
      <mass value="0.017" />
      <inertia ixx="0.0" iyy="0.0" izz="0.0" ixy="0" ixz="0" iyz="0" />
    </inertial>
  </link>
  <joint name="joint_link_2_5_to_link_2_6" type="revolute">
    <origin xyz="0.0 0.0 0.043" rpy="0 0 0" />
    <parent link="link_2_5" />
    <child link="link_2_6" />
    <axis xyz="0.897 0.053 0.452" />
    <limit lower="-3.142" upper="3.142" effort="10" velocity="10" />
  </joint>
  <link name="link_2_7">
    <visual>
      <origin xyz="0 0 0.017" rpy="0 0 0" />
      <geometry>
        <box size="0.03 0.047 0.034" />
      </geometry>
    </visual>
    <collision>
      <geometry>
        <box size="0.03 0.047 0.034" />
      </geometry>
    </collision>
    <inertial>
      <mass value="0.014" />
      <inertia ixx="0.0" iyy="0.0" izz="0.0" ixy="0" ixz="0" iyz="0" />
    </inertial>
  </link>
  <joint name="joint_link_2_6_to_link_2_7" type="revolute">
    <origin xyz="0.0 0.0 0.09" rpy="0 0 0" />
    <parent link="link_2_6" />
    <child link="link_2_7" />
    <axis xyz="0.748 0.563 0.88" />
    <limit lower="-3.142" upper="3.142" effort="10" velocity="10" />
  </joint>
  <link name="link_3_0">
    <visual>
      <origin xyz="0 0 0.0245" rpy="0 0 0" />
      <geometry>
        <box size="0.026 0.014 0.049" />
      </geometry>
    </visual>
    <collision>
      <geometry>
        <box size="0.026 0.014 0.049" />
      </geometry>
    </collision>
    <inertial>
      <mass value="0.005" />
      <inertia ixx="0.0" iyy="0.0" izz="0.0" ixy="0" ixz="0" iyz="0" />
    </inertial>
  </link>
  <joint name="joint_palm_link_to_link_3_0" type="revolute">
    <origin xyz="-0.125 0.073 0.1" rpy="0 0 0" />
    <parent link="palm_link" />
    <child link="link_3_0" />
    <axis xyz="0.945 0.922 0.926" />
    <limit lower="-3.142" upper="3.142" effort="10" velocity="10" />
  </joint>
  <link name="link_3_1">
    <visual>
      <origin xyz="0 0 0.0175" rpy="0 0 0" />
      <geometry>
        <box size="0.031 0.029 0.035" />
      </geometry>
    </visual>
    <collision>
      <geometry>
        <box size="0.031 0.029 0.035" />
      </geometry>
    </collision>
    <inertial>
      <mass value="0.009" />
      <inertia ixx="0.0" iyy="0.0" izz="0.0" ixy="0" ixz="0" iyz="0" />
    </inertial>
  </link>
  <joint name="joint_link_3_0_to_link_3_1" type="revolute">
    <origin xyz="0.0 0.0 0.049" rpy="0 0 0" />
    <parent link="link_3_0" />
    <child link="link_3_1" />
    <axis xyz="0.455 0.737 0.254" />
    <limit lower="-3.142" upper="3.142" effort="10" velocity="10" />
  </joint>
  <link name="link_3_2">
    <visual>
      <origin xyz="0 0 0.038" rpy="0 0 0" />
      <geometry>
        <box size="0.047 0.02 0.076" />
      </geometry>
    </visual>
    <collision>
      <geometry>
        <box size="0.047 0.02 0.076" />
      </geometry>
    </collision>
    <inertial>
      <mass value="0.021" />
      <inertia ixx="0.0" iyy="0.0" izz="0.0" ixy="0" ixz="0" iyz="0" />
    </inertial>
  </link>
  <joint name="joint_link_3_1_to_link_3_2" type="revolute">
    <origin xyz="0.0 0.0 0.035" rpy="0 0 0" />
    <parent link="link_3_1" />
    <child link="link_3_2" />
    <axis xyz="0.787 0.27 0.972" />
    <limit lower="-3.142" upper="3.142" effort="10" velocity="10" />
  </joint>
  <link name="link_4_0">
    <visual>
      <origin xyz="0 0 0.025" rpy="0 0 0" />
      <geometry>
        <box size="0.038 0.019 0.05" />
      </geometry>
    </visual>
    <collision>
      <geometry>
        <box size="0.038 0.019 0.05" />
      </geometry>
    </collision>
    <inertial>
      <mass value="0.011" />
      <inertia ixx="0.0" iyy="0.0" izz="0.0" ixy="0" ixz="0" iyz="0" />
    </inertial>
  </link>
  <joint name="joint_palm_link_to_link_4_0" type="revolute">
    <origin xyz="0.125 0.046 0.1" rpy="0 0 0" />
    <parent link="palm_link" />
    <child link="link_4_0" />
    <axis xyz="0.806 0.416 0.963" />
    <limit lower="-3.142" upper="3.142" effort="10" velocity="10" />
  </joint>
  <link name="link_4_1">
    <visual>
      <origin xyz="0 0 0.0275" rpy="0 0 0" />
      <geometry>
        <box size="0.03 0.039 0.055" />
      </geometry>
    </visual>
    <collision>
      <geometry>
        <box size="0.03 0.039 0.055" />
      </geometry>
    </collision>
    <inertial>
      <mass value="0.019" />
      <inertia ixx="0.0" iyy="0.0" izz="0.0" ixy="0" ixz="0" iyz="0" />
    </inertial>
  </link>
  <joint name="joint_link_4_0_to_link_4_1" type="revolute">
    <origin xyz="0.0 0.0 0.05" rpy="0 0 0" />
    <parent link="link_4_0" />
    <child link="link_4_1" />
    <axis xyz="0.393 0.895 0.839" />
    <limit lower="-3.142" upper="3.142" effort="10" velocity="10" />
  </joint>
  <link name="link_4_2">
    <visual>
      <origin xyz="0 0 0.011" rpy="0 0 0" />
      <geometry>
        <box size="0.023 0.036 0.022" />
      </geometry>
    </visual>
    <collision>
      <geometry>
        <box size="0.023 0.036 0.022" />
      </geometry>
    </collision>
    <inertial>
      <mass value="0.005" />
      <inertia ixx="0.0" iyy="0.0" izz="0.0" ixy="0" ixz="0" iyz="0" />
    </inertial>
  </link>
  <joint name="joint_link_4_1_to_link_4_2" type="revolute">
    <origin xyz="0.0 0.0 0.055" rpy="0 0 0" />
    <parent link="link_4_1" />
    <child link="link_4_2" />
    <axis xyz="0.306 0.581 0.851" />
    <limit lower="-3.142" upper="3.142" effort="10" velocity="10" />
  </joint>
  <link name="link_4_3">
    <visual>
      <origin xyz="0 0 0.0205" rpy="0 0 0" />
      <geometry>
        <box size="0.018 0.035 0.041" />
      </geometry>
    </visual>
    <collision>
      <geometry>
        <box size="0.018 0.035 0.041" />
      </geometry>
    </collision>
    <inertial>
      <mass value="0.008" />
      <inertia ixx="0.0" iyy="0.0" izz="0.0" ixy="0" ixz="0" iyz="0" />
    </inertial>
  </link>
  <joint name="joint_link_4_2_to_link_4_3" type="revolute">
    <origin xyz="0.0 0.0 0.022" rpy="0 0 0" />
    <parent link="link_4_2" />
    <child link="link_4_3" />
    <axis xyz="0.35 0.275 0.744" />
    <limit lower="-3.142" upper="3.142" effort="10" velocity="10" />
  </joint>
  <link name="link_4_4">
    <visual>
      <origin xyz="0 0 0.0465" rpy="0 0 0" />
      <geometry>
        <box size="0.038 0.013 0.093" />
      </geometry>
    </visual>
    <collision>
      <geometry>
        <box size="0.038 0.013 0.093" />
      </geometry>
    </collision>
    <inertial>
      <mass value="0.014" />
      <inertia ixx="0.0" iyy="0.0" izz="0.0" ixy="0" ixz="0" iyz="0" />
    </inertial>
  </link>
  <joint name="joint_link_4_3_to_link_4_4" type="revolute">
    <origin xyz="0.0 0.0 0.041" rpy="0 0 0" />
    <parent link="link_4_3" />
    <child link="link_4_4" />
    <axis xyz="0.847 0.121 0.88" />
    <limit lower="-3.142" upper="3.142" effort="10" velocity="10" />
  </joint>
  <link name="link_4_5">
    <visual>
      <origin xyz="0 0 0.006" rpy="0 0 0" />
      <geometry>
        <box size="0.024 0.026 0.012" />
      </geometry>
    </visual>
    <collision>
      <geometry>
        <box size="0.024 0.026 0.012" />
      </geometry>
    </collision>
    <inertial>
      <mass value="0.002" />
      <inertia ixx="0.0" iyy="0.0" izz="0.0" ixy="0" ixz="0" iyz="0" />
    </inertial>
  </link>
  <joint name="joint_link_4_4_to_link_4_5" type="revolute">
    <origin xyz="0.0 0.0 0.093" rpy="0 0 0" />
    <parent link="link_4_4" />
    <child link="link_4_5" />
    <axis xyz="0.766 0.869 0.781" />
    <limit lower="-3.142" upper="3.142" effort="10" velocity="10" />
  </joint>
</robot>