<?xml version='1.0' encoding='utf-8'?>
<robot name="robot">
  <link name="base_link">
    <visual>
      <origin xyz="0 0 0.125" rpy="0 0 0" />
      <geometry>
        <box size="0.75 0.75 0.25" />
      </geometry>
      <material name="green" />
    </visual>
    <visual>
      <origin xyz="0 0 0.375" rpy="0 0 0" />
      <geometry>
        <cylinder length="0.25" radius="0.25" />
      </geometry>
      <material name="green">
        <color rgba="0 1 0 1" />
      </material>
    </visual>
    <collision>
      <geometry>
        <box size="0.75 0.75 0.5" />
      </geometry>
    </collision>
    <inertial>
      <mass value="0.5" />
      <inertia ixx="0.034" ixy="0.0" ixz="0.0" iyy="0.034" iyz="0.0" izz="0.034" />
    </inertial>
  </link>
  <link name="support_link">
    <visual>
      <origin xyz="0 0 0.5" rpy="0 0 0" />
      <geometry>
        <box size="0.2 0.2 1" />
      </geometry>
      <material name="white">
        <color rgba="1 1 1 1" />
      </material>
    </visual>
    <collision>
      <geometry>
        <box size="0.2 0.2 1" />
      </geometry>
    </collision>
    <inertial>
      <mass value="0.1" />
      <inertia ixx="0.01" ixy="0.0" ixz="0.0" iyy="0.01" iyz="0.0" izz="0.01" />
    </inertial>
  </link>
  <joint name="support_joint" type="continuous">
    <origin xyz="0 0 0.5" rpy="0 0 0" />
    <parent link="base_link" />
    <child link="support_link" />
    <axis xyz="0 0 1" />
  </joint>
  <link name="arm_link">
    <visual>
      <origin xyz="0 0 0.5" rpy="0 0 0" />
      <geometry>
        <box size="0.2 0.2 1" />
      </geometry>
      <material name="blue">
        <color rgba="0 0 1 1" />
      </material>
    </visual>
    <collision>
      <geometry>
        <box size="0.2 0.2 1" />
      </geometry>
    </collision>
    <inertial>
      <mass value="0.1" />
      <inertia ixx="0.01" ixy="0.0" ixz="0.0" iyy="0.01" iyz="0.0" izz="0.01" />
    </inertial>
  </link>
  <joint name="arm_joint" type="revolute">
    <origin xyz="-0.1 0 1" rpy="0 0 0" />
    <parent link="support_link" />
    <child link="arm_link" />
    <axis xyz="0 1 0" />
    <limit lower="-3.14" upper="3.14" effort="1.0" velocity="1.0" />
  </joint>
  <link name="wrist_link">
    <visual>
      <origin xyz="0 0 0.25" rpy="0 0 0" />
      <geometry>
        <box size="0.15 0.15 0.5" />
      </geometry>
      <material name="orange">
        <color rgba="1 0.5 0 1" />
      </material>
    </visual>
    <collision>
      <geometry>
        <box size="0.15 0.15 0.5" />
      </geometry>
    </collision>
    <inertial>
      <mass value="0.1" />
      <inertia ixx="0.01" ixy="0.0" ixz="0.0" iyy="0.01" iyz="0.0" izz="0.01" />
    </inertial>
  </link>
  <joint name="wrist_joint" type="fixed">
    <origin xyz="0 0 0.9" rpy="0 1.571 0" />
    <parent link="arm_link" />
    <child link="wrist_link" />
  </joint>
  <link name="palm_link">
    <visual>
      <origin xyz="0 0 0.05" rpy="0 0 0" />
      <geometry>
        <box size="0.25 0.25 0.1" />
      </geometry>
      <material name="orange" />
    </visual>
    <collision>
      <geometry>
        <box size="0.25 0.25 0.1" />
      </geometry>
    </collision>
    <inertial>
      <mass value="0.1" />
      <inertia ixx="0.01" ixy="0.0" ixz="0.0" iyy="0.01" iyz="0.0" izz="0.01" />
    </inertial>
  </link>
  <joint name="palm_joint" type="fixed">
    <origin xyz="0 0 0.45" rpy="0 0 0" />
    <parent link="wrist_link" />
    <child link="palm_link" />
  </joint>
  <link name="finger_link_0_0">
    <visual>
      <origin xyz="0 0 0.042" rpy="0 0 0" />
      <geometry>
        <box size="0.029 0.024 0.084" />
      </geometry>
    </visual>
    <collision>
      <geometry>
        <box size="0.029 0.024 0.084" />
      </geometry>
    </collision>
    <inertial>
      <mass value="0.018" />
      <inertia ixx="0.0" iyy="0.0" izz="0.0" ixy="0" ixz="0" iyz="0" />
    </inertial>
  </link>
  <joint name="finger_joint_palm_link_to_finger_link_0_0" type="revolute">
    <origin xyz="-0.125 -0.065 0.1" rpy="0 0 0" />
    <parent link="palm_link" />
    <child link="finger_link_0_0" />
    <axis xyz="1.0 1.0 0.0" />
    <limit lower="-3.142" upper="3.142" effort="10" velocity="10" />
  </joint>
  <link name="finger_link_0_1">
    <visual>
      <origin xyz="0 0 0.0165" rpy="0 0 0" />
      <geometry>
        <box size="0.018 0.024 0.033" />
      </geometry>
    </visual>
    <collision>
      <geometry>
        <box size="0.018 0.024 0.033" />
      </geometry>
    </collision>
    <inertial>
      <mass value="0.004" />
      <inertia ixx="0.0" iyy="0.0" izz="0.0" ixy="0" ixz="0" iyz="0" />
    </inertial>
  </link>
  <joint name="finger_joint_finger_link_0_0_to_finger_link_0_1" type="revolute">
    <origin xyz="0.0 0.0 0.084" rpy="0 0 0" />
    <parent link="finger_link_0_0" />
    <child link="finger_link_0_1" />
    <axis xyz="1.0 1.0 0.0" />
    <limit lower="-3.142" upper="3.142" effort="10" velocity="10" />
  </joint>
  <link name="finger_link_0_2">
    <visual>
      <origin xyz="0 0 0.0345" rpy="0 0 0" />
      <geometry>
        <box size="0.019 0.014 0.069" />
      </geometry>
    </visual>
    <collision>
      <geometry>
        <box size="0.019 0.014 0.069" />
      </geometry>
    </collision>
    <inertial>
      <mass value="0.006" />
      <inertia ixx="0.0" iyy="0.0" izz="0.0" ixy="0" ixz="0" iyz="0" />
    </inertial>
  </link>
  <joint name="finger_joint_finger_link_0_1_to_finger_link_0_2" type="revolute">
    <origin xyz="0.0 0.0 0.033" rpy="0 0 0" />
    <parent link="finger_link_0_1" />
    <child link="finger_link_0_2" />
    <axis xyz="0.0 1.0 0.0" />
    <limit lower="-3.142" upper="3.142" effort="10" velocity="10" />
  </joint>
  <link name="finger_link_0_3">
    <visual>
      <origin xyz="0 0 0.008" rpy="0 0 0" />
      <geometry>
        <box size="0.05 0.046 0.016" />
      </geometry>
    </visual>
    <collision>
      <geometry>
        <box size="0.05 0.046 0.016" />
      </geometry>
    </collision>
    <inertial>
      <mass value="0.011" />
      <inertia ixx="0.0" iyy="0.0" izz="0.0" ixy="0" ixz="0" iyz="0" />
    </inertial>
  </link>
  <joint name="finger_joint_finger_link_0_2_to_finger_link_0_3" type="revolute">
    <origin xyz="0.0 0.0 0.069" rpy="0 0 0" />
    <parent link="finger_link_0_2" />
    <child link="finger_link_0_3" />
    <axis xyz="1.0 1.0 0.0" />
    <limit lower="-3.142" upper="3.142" effort="10" velocity="10" />
  </joint>
  <link name="finger_link_1_0">
    <visual>
      <origin xyz="0 0 0.0335" rpy="0 0 0" />
      <geometry>
        <box size="0.024 0.046 0.067" />
      </geometry>
    </visual>
    <collision>
      <geometry>
        <box size="0.024 0.046 0.067" />
      </geometry>
    </collision>
    <inertial>
      <mass value="0.022" />
      <inertia ixx="0.0" iyy="0.0" izz="0.0" ixy="0" ixz="0" iyz="0" />
    </inertial>
  </link>
  <joint name="finger_joint_palm_link_to_finger_link_1_0" type="revolute">
    <origin xyz="0.047 -0.125 0.1" rpy="0 0 0" />
    <parent link="palm_link" />
    <child link="finger_link_1_0" />
    <axis xyz="1.0 1.0 0.0" />
    <limit lower="-3.142" upper="3.142" effort="10" velocity="10" />
  </joint>
  <link name="finger_link_1_1">
    <visual>
      <origin xyz="0 0 0.042" rpy="0 0 0" />
      <geometry>
        <box size="0.011 0.033 0.084" />
      </geometry>
    </visual>
    <collision>
      <geometry>
        <box size="0.011 0.033 0.084" />
      </geometry>
    </collision>
    <inertial>
      <mass value="0.009" />
      <inertia ixx="0.0" iyy="0.0" izz="0.0" ixy="0" ixz="0" iyz="0" />
    </inertial>
  </link>
  <joint name="finger_joint_finger_link_1_0_to_finger_link_1_1" type="revolute">
    <origin xyz="0.0 0.0 0.067" rpy="0 0 0" />
    <parent link="finger_link_1_0" />
    <child link="finger_link_1_1" />
    <axis xyz="1.0 1.0 0.0" />
    <limit lower="-3.142" upper="3.142" effort="10" velocity="10" />
  </joint>
  <link name="finger_link_1_2">
    <visual>
      <origin xyz="0 0 0.0435" rpy="0 0 0" />
      <geometry>
        <box size="0.019 0.016 0.087" />
      </geometry>
    </visual>
    <collision>
      <geometry>
        <box size="0.019 0.016 0.087" />
      </geometry>
    </collision>
    <inertial>
      <mass value="0.008" />
      <inertia ixx="0.0" iyy="0.0" izz="0.0" ixy="0" ixz="0" iyz="0" />
    </inertial>
  </link>
  <joint name="finger_joint_finger_link_1_1_to_finger_link_1_2" type="revolute">
    <origin xyz="0.0 0.0 0.084" rpy="0 0 0" />
    <parent link="finger_link_1_1" />
    <child link="finger_link_1_2" />
    <axis xyz="1.0 1.0 0.0" />
    <limit lower="-3.142" upper="3.142" effort="10" velocity="10" />
  </joint>
  <link name="finger_link_1_3">
    <visual>
      <origin xyz="0 0 0.0225" rpy="0 0 0" />
      <geometry>
        <box size="0.015 0.022 0.045" />
      </geometry>
    </visual>
    <collision>
      <geometry>
        <box size="0.015 0.022 0.045" />
      </geometry>
    </collision>
    <inertial>
      <mass value="0.004" />
      <inertia ixx="0.0" iyy="0.0" izz="0.0" ixy="0" ixz="0" iyz="0" />
    </inertial>
  </link>
  <joint name="finger_joint_finger_link_1_2_to_finger_link_1_3" type="revolute">
    <origin xyz="0.0 0.0 0.087" rpy="0 0 0" />
    <parent link="finger_link_1_2" />
    <child link="finger_link_1_3" />
    <axis xyz="0.0 1.0 0.0" />
    <limit lower="-3.142" upper="3.142" effort="10" velocity="10" />
  </joint>
  <link name="finger_link_1_4">
    <visual>
      <origin xyz="0 0 0.0215" rpy="0 0 0" />
      <geometry>
        <box size="0.025 0.044 0.043" />
      </geometry>
    </visual>
    <collision>
      <geometry>
        <box size="0.025 0.044 0.043" />
      </geometry>
    </collision>
    <inertial>
      <mass value="0.014" />
      <inertia ixx="0.0" iyy="0.0" izz="0.0" ixy="0" ixz="0" iyz="0" />
    </inertial>
  </link>
  <joint name="finger_joint_finger_link_1_3_to_finger_link_1_4" type="revolute">
    <origin xyz="0.0 0.0 0.045" rpy="0 0 0" />
    <parent link="finger_link_1_3" />
    <child link="finger_link_1_4" />
    <axis xyz="1.0 1.0 0.0" />
    <limit lower="-3.142" upper="3.142" effort="10" velocity="10" />
  </joint>
  <link name="finger_link_1_5">
    <visual>
      <origin xyz="0 0 0.0415" rpy="0 0 0" />
      <geometry>
        <box size="0.049 0.033 0.083" />
      </geometry>
    </visual>
    <collision>
      <geometry>
        <box size="0.049 0.033 0.083" />
      </geometry>
    </collision>
    <inertial>
      <mass value="0.04" />
      <inertia ixx="0.0" iyy="0.0" izz="0.0" ixy="0" ixz="0" iyz="0" />
    </inertial>
  </link>
  <joint name="finger_joint_finger_link_1_4_to_finger_link_1_5" type="revolute">
    <origin xyz="0.0 0.0 0.043" rpy="0 0 0" />
    <parent link="finger_link_1_4" />
    <child link="finger_link_1_5" />
    <axis xyz="0.0 1.0 0.0" />
    <limit lower="-3.142" upper="3.142" effort="10" velocity="10" />
  </joint>
  <link name="finger_link_1_6">
    <visual>
      <origin xyz="0 0 0.0375" rpy="0 0 0" />
      <geometry>
        <box size="0.014 0.017 0.075" />
      </geometry>
    </visual>
    <collision>
      <geometry>
        <box size="0.014 0.017 0.075" />
      </geometry>
    </collision>
    <inertial>
      <mass value="0.005" />
      <inertia ixx="0.0" iyy="0.0" izz="0.0" ixy="0" ixz="0" iyz="0" />
    </inertial>
  </link>
  <joint name="finger_joint_finger_link_1_5_to_finger_link_1_6" type="revolute">
    <origin xyz="0.0 0.0 0.083" rpy="0 0 0" />
    <parent link="finger_link_1_5" />
    <child link="finger_link_1_6" />
    <axis xyz="0.0 1.0 0.0" />
    <limit lower="-3.142" upper="3.142" effort="10" velocity="10" />
  </joint>
  <link name="finger_link_2_0">
    <visual>
      <origin xyz="0 0 0.0445" rpy="0 0 0" />
      <geometry>
        <box size="0.015 0.036 0.089" />
      </geometry>
    </visual>
    <collision>
      <geometry>
        <box size="0.015 0.036 0.089" />
      </geometry>
    </collision>
    <inertial>
      <mass value="0.014" />
      <inertia ixx="0.0" iyy="0.0" izz="0.0" ixy="0" ixz="0" iyz="0" />
    </inertial>
  </link>
  <joint name="finger_joint_palm_link_to_finger_link_2_0" type="revolute">
    <origin xyz="-0.125 0.068 0.1" rpy="0 0 0" />
    <parent link="palm_link" />
    <child link="finger_link_2_0" />
    <axis xyz="1.0 1.0 0.0" />
    <limit lower="-3.142" upper="3.142" effort="10" velocity="10" />
  </joint>
  <link name="finger_link_2_1">
    <visual>
      <origin xyz="0 0 0.047" rpy="0 0 0" />
      <geometry>
        <box size="0.011 0.044 0.094" />
      </geometry>
    </visual>
    <collision>
      <geometry>
        <box size="0.011 0.044 0.094" />
      </geometry>
    </collision>
    <inertial>
      <mass value="0.014" />
      <inertia ixx="0.0" iyy="0.0" izz="0.0" ixy="0" ixz="0" iyz="0" />
    </inertial>
  </link>
  <joint name="finger_joint_finger_link_2_0_to_finger_link_2_1" type="revolute">
    <origin xyz="0.0 0.0 0.089" rpy="0 0 0" />
    <parent link="finger_link_2_0" />
    <child link="finger_link_2_1" />
    <axis xyz="1.0 0.0 0.0" />
    <limit lower="-3.142" upper="3.142" effort="10" velocity="10" />
  </joint>
  <link name="finger_link_2_2">
    <visual>
      <origin xyz="0 0 0.0255" rpy="0 0 0" />
      <geometry>
        <box size="0.025 0.043 0.051" />
      </geometry>
    </visual>
    <collision>
      <geometry>
        <box size="0.025 0.043 0.051" />
      </geometry>
    </collision>
    <inertial>
      <mass value="0.016" />
      <inertia ixx="0.0" iyy="0.0" izz="0.0" ixy="0" ixz="0" iyz="0" />
    </inertial>
  </link>
  <joint name="finger_joint_finger_link_2_1_to_finger_link_2_2" type="revolute">
    <origin xyz="0.0 0.0 0.094" rpy="0 0 0" />
    <parent link="finger_link_2_1" />
    <child link="finger_link_2_2" />
    <axis xyz="0.0 1.0 0.0" />
    <limit lower="-3.142" upper="3.142" effort="10" velocity="10" />
  </joint>
  <link name="finger_link_2_3">
    <visual>
      <origin xyz="0 0 0.02" rpy="0 0 0" />
      <geometry>
        <box size="0.036 0.027 0.04" />
      </geometry>
    </visual>
    <collision>
      <geometry>
        <box size="0.036 0.027 0.04" />
      </geometry>
    </collision>
    <inertial>
      <mass value="0.012" />
      <inertia ixx="0.0" iyy="0.0" izz="0.0" ixy="0" ixz="0" iyz="0" />
    </inertial>
  </link>
  <joint name="finger_joint_finger_link_2_2_to_finger_link_2_3" type="revolute">
    <origin xyz="0.0 0.0 0.051" rpy="0 0 0" />
    <parent link="finger_link_2_2" />
    <child link="finger_link_2_3" />
    <axis xyz="0.0 1.0 0.0" />
    <limit lower="-3.142" upper="3.142" effort="10" velocity="10" />
  </joint>
  <link name="finger_link_2_4">
    <visual>
      <origin xyz="0 0 0.0085" rpy="0 0 0" />
      <geometry>
        <box size="0.048 0.045 0.017" />
      </geometry>
    </visual>
    <collision>
      <geometry>
        <box size="0.048 0.045 0.017" />
      </geometry>
    </collision>
    <inertial>
      <mass value="0.011" />
      <inertia ixx="0.0" iyy="0.0" izz="0.0" ixy="0" ixz="0" iyz="0" />
    </inertial>
  </link>
  <joint name="finger_joint_finger_link_2_3_to_finger_link_2_4" type="revolute">
    <origin xyz="0.0 0.0 0.04" rpy="0 0 0" />
    <parent link="finger_link_2_3" />
    <child link="finger_link_2_4" />
    <axis xyz="0.0 1.0 0.0" />
    <limit lower="-3.142" upper="3.142" effort="10" velocity="10" />
  </joint>
  <link name="finger_link_3_0">
    <visual>
      <origin xyz="0 0 0.0195" rpy="0 0 0" />
      <geometry>
        <box size="0.024 0.03 0.039" />
      </geometry>
    </visual>
    <collision>
      <geometry>
        <box size="0.024 0.03 0.039" />
      </geometry>
    </collision>
    <inertial>
      <mass value="0.008" />
      <inertia ixx="0.0" iyy="0.0" izz="0.0" ixy="0" ixz="0" iyz="0" />
    </inertial>
  </link>
  <joint name="finger_joint_palm_link_to_finger_link_3_0" type="revolute">
    <origin xyz="0.039 -0.125 0.1" rpy="0 0 0" />
    <parent link="palm_link" />
    <child link="finger_link_3_0" />
    <axis xyz="0.0 1.0 0.0" />
    <limit lower="-3.142" upper="3.142" effort="10" velocity="10" />
  </joint>
  <link name="finger_link_3_1">
    <visual>
      <origin xyz="0 0 0.007" rpy="0 0 0" />
      <geometry>
        <box size="0.03 0.012 0.014" />
      </geometry>
    </visual>
    <collision>
      <geometry>
        <box size="0.03 0.012 0.014" />
      </geometry>
    </collision>
    <inertial>
      <mass value="0.002" />
      <inertia ixx="0.0" iyy="0.0" izz="0.0" ixy="0" ixz="0" iyz="0" />
    </inertial>
  </link>
  <joint name="finger_joint_finger_link_3_0_to_finger_link_3_1" type="revolute">
    <origin xyz="0.0 0.0 0.039" rpy="0 0 0" />
    <parent link="finger_link_3_0" />
    <child link="finger_link_3_1" />
    <axis xyz="1.0 1.0 0.0" />
    <limit lower="-3.142" upper="3.142" effort="10" velocity="10" />
  </joint>
</robot>