<?xml version='1.0' encoding='utf-8'?>
<robot name="robot">
  <link name="base_link">
    <visual>
      <origin xyz="0 0 0.125" rpy="0 0 0" />
      <geometry>
        <box size="0.75 0.75 0.25" />
      </geometry>
      <material name="green" />
    </visual>
    <visual>
      <origin xyz="0 0 0.375" rpy="0 0 0" />
      <geometry>
        <cylinder length="0.25" radius="0.25" />
      </geometry>
      <material name="green">
        <color rgba="0 1 0 1" />
      </material>
    </visual>
    <collision>
      <geometry>
        <box size="0.75 0.75 0.5" />
      </geometry>
    </collision>
    <inertial>
      <mass value="0.5" />
      <inertia ixx="0.034" ixy="0.0" ixz="0.0" iyy="0.034" iyz="0.0" izz="0.034" />
    </inertial>
  </link>
  <link name="support_link">
    <visual>
      <origin xyz="0 0 0.5" rpy="0 0 0" />
      <geometry>
        <box size="0.2 0.2 1" />
      </geometry>
      <material name="white">
        <color rgba="1 1 1 1" />
      </material>
    </visual>
    <collision>
      <geometry>
        <box size="0.2 0.2 1" />
      </geometry>
    </collision>
    <inertial>
      <mass value="0.1" />
      <inertia ixx="0.01" ixy="0.0" ixz="0.0" iyy="0.01" iyz="0.0" izz="0.01" />
    </inertial>
  </link>
  <joint name="support_joint" type="continuous">
    <origin xyz="0 0 0.5" rpy="0 0 0" />
    <parent link="base_link" />
    <child link="support_link" />
    <axis xyz="0 0 1" />
  </joint>
  <link name="arm_link">
    <visual>
      <origin xyz="0 0 0.5" rpy="0 0 0" />
      <geometry>
        <box size="0.2 0.2 1" />
      </geometry>
      <material name="blue">
        <color rgba="0 0 1 1" />
      </material>
    </visual>
    <collision>
      <geometry>
        <box size="0.2 0.2 1" />
      </geometry>
    </collision>
    <inertial>
      <mass value="0.1" />
      <inertia ixx="0.01" ixy="0.0" ixz="0.0" iyy="0.01" iyz="0.0" izz="0.01" />
    </inertial>
  </link>
  <joint name="arm_joint" type="revolute">
    <origin xyz="-0.1 0 1" rpy="0 0 0" />
    <parent link="support_link" />
    <child link="arm_link" />
    <axis xyz="0 1 0" />
    <limit lower="-3.14" upper="3.14" effort="1.0" velocity="1.0" />
  </joint>
  <link name="wrist_link">
    <visual>
      <origin xyz="0 0 0.25" rpy="0 0 0" />
      <geometry>
        <box size="0.15 0.15 0.5" />
      </geometry>
      <material name="orange">
        <color rgba="1 0.5 0 1" />
      </material>
    </visual>
    <collision>
      <geometry>
        <box size="0.15 0.15 0.5" />
      </geometry>
    </collision>
    <inertial>
      <mass value="0.1" />
      <inertia ixx="0.01" ixy="0.0" ixz="0.0" iyy="0.01" iyz="0.0" izz="0.01" />
    </inertial>
  </link>
  <joint name="wrist_joint" type="fixed">
    <origin xyz="0 0 0.9" rpy="0 1.571 0" />
    <parent link="arm_link" />
    <child link="wrist_link" />
  </joint>
  <link name="palm_link">
    <visual>
      <origin xyz="0 0 0.05" rpy="0 0 0" />
      <geometry>
        <box size="0.25 0.25 0.1" />
      </geometry>
      <material name="orange" />
    </visual>
    <collision>
      <geometry>
        <box size="0.25 0.25 0.1" />
      </geometry>
    </collision>
    <inertial>
      <mass value="0.1" />
      <inertia ixx="0.01" ixy="0.0" ixz="0.0" iyy="0.01" iyz="0.0" izz="0.01" />
    </inertial>
  </link>
  <joint name="palm_joint" type="fixed">
    <origin xyz="0 0 0.45" rpy="0 0 0" />
    <parent link="wrist_link" />
    <child link="palm_link" />
  </joint>
  <link name="finger_link_0_0">
    <visual>
      <origin xyz="0 0 0.0455" rpy="0 0 0" />
      <geometry>
        <box size="0.044 0.017 0.091" />
      </geometry>
    </visual>
    <collision>
      <geometry>
        <box size="0.044 0.017 0.091" />
      </geometry>
    </collision>
    <inertial>
      <mass value="0.02" />
      <inertia ixx="0.0" iyy="0.0" izz="0.0" ixy="0" ixz="0" iyz="0" />
    </inertial>
  </link>
  <joint name="finger_joint_palm_link_to_finger_link_0_0" type="revolute">
    <origin xyz="-0.102 -0.125 0.1" rpy="0 0 0" />
    <parent link="palm_link" />
    <child link="finger_link_0_0" />
    <axis xyz="1.0 0.0 0.0" />
    <limit lower="-3.142" upper="3.142" effort="10" velocity="10" />
  </joint>
  <link name="finger_link_0_1">
    <visual>
      <origin xyz="0 0 0.0155" rpy="0 0 0" />
      <geometry>
        <box size="0.024 0.035 0.031" />
      </geometry>
    </visual>
    <collision>
      <geometry>
        <box size="0.024 0.035 0.031" />
      </geometry>
    </collision>
    <inertial>
      <mass value="0.008" />
      <inertia ixx="0.0" iyy="0.0" izz="0.0" ixy="0" ixz="0" iyz="0" />
    </inertial>
  </link>
  <joint name="finger_joint_finger_link_0_0_to_finger_link_0_1" type="revolute">
    <origin xyz="0.0 0.0 0.091" rpy="0 0 0" />
    <parent link="finger_link_0_0" />
    <child link="finger_link_0_1" />
    <axis xyz="1.0 0.0 0.0" />
    <limit lower="-3.142" upper="3.142" effort="10" velocity="10" />
  </joint>
  <link name="finger_link_0_2">
    <visual>
      <origin xyz="0 0 0.0485" rpy="0 0 0" />
      <geometry>
        <box size="0.05 0.012 0.097" />
      </geometry>
    </visual>
    <collision>
      <geometry>
        <box size="0.05 0.012 0.097" />
      </geometry>
    </collision>
    <inertial>
      <mass value="0.017" />
      <inertia ixx="0.0" iyy="0.0" izz="0.0" ixy="0" ixz="0" iyz="0" />
    </inertial>
  </link>
  <joint name="finger_joint_finger_link_0_1_to_finger_link_0_2" type="revolute">
    <origin xyz="0.0 0.0 0.031" rpy="0 0 0" />
    <parent link="finger_link_0_1" />
    <child link="finger_link_0_2" />
    <axis xyz="0.0 1.0 0.0" />
    <limit lower="-3.142" upper="3.142" effort="10" velocity="10" />
  </joint>
  <link name="finger_link_0_3">
    <visual>
      <origin xyz="0 0 0.0215" rpy="0 0 0" />
      <geometry>
        <box size="0.04 0.035 0.043" />
      </geometry>
    </visual>
    <collision>
      <geometry>
        <box size="0.04 0.035 0.043" />
      </geometry>
    </collision>
    <inertial>
      <mass value="0.018" />
      <inertia ixx="0.0" iyy="0.0" izz="0.0" ixy="0" ixz="0" iyz="0" />
    </inertial>
  </link>
  <joint name="finger_joint_finger_link_0_2_to_finger_link_0_3" type="revolute">
    <origin xyz="0.0 0.0 0.097" rpy="0 0 0" />
    <parent link="finger_link_0_2" />
    <child link="finger_link_0_3" />
    <axis xyz="1.0 0.0 0.0" />
    <limit lower="-3.142" upper="3.142" effort="10" velocity="10" />
  </joint>
  <link name="finger_link_0_4">
    <visual>
      <origin xyz="0 0 0.0185" rpy="0 0 0" />
      <geometry>
        <box size="0.037 0.024 0.037" />
      </geometry>
    </visual>
    <collision>
      <geometry>
        <box size="0.037 0.024 0.037" />
      </geometry>
    </collision>
    <inertial>
      <mass value="0.01" />
      <inertia ixx="0.0" iyy="0.0" izz="0.0" ixy="0" ixz="0" iyz="0" />
    </inertial>
  </link>
  <joint name="finger_joint_finger_link_0_3_to_finger_link_0_4" type="revolute">
    <origin xyz="0.0 0.0 0.043" rpy="0 0 0" />
    <parent link="finger_link_0_3" />
    <child link="finger_link_0_4" />
    <axis xyz="1.0 0.0 0.0" />
    <limit lower="-3.142" upper="3.142" effort="10" velocity="10" />
  </joint>
  <link name="finger_link_0_5">
    <visual>
      <origin xyz="0 0 0.0335" rpy="0 0 0" />
      <geometry>
        <box size="0.042 0.012 0.067" />
      </geometry>
    </visual>
    <collision>
      <geometry>
        <box size="0.042 0.012 0.067" />
      </geometry>
    </collision>
    <inertial>
      <mass value="0.01" />
      <inertia ixx="0.0" iyy="0.0" izz="0.0" ixy="0" ixz="0" iyz="0" />
    </inertial>
  </link>
  <joint name="finger_joint_finger_link_0_4_to_finger_link_0_5" type="revolute">
    <origin xyz="0.0 0.0 0.037" rpy="0 0 0" />
    <parent link="finger_link_0_4" />
    <child link="finger_link_0_5" />
    <axis xyz="0.0 1.0 0.0" />
    <limit lower="-3.142" upper="3.142" effort="10" velocity="10" />
  </joint>
  <link name="finger_link_0_6">
    <visual>
      <origin xyz="0 0 0.022" rpy="0 0 0" />
      <geometry>
        <box size="0.039 0.019 0.044" />
      </geometry>
    </visual>
    <collision>
      <geometry>
        <box size="0.039 0.019 0.044" />
      </geometry>
    </collision>
    <inertial>
      <mass value="0.01" />
      <inertia ixx="0.0" iyy="0.0" izz="0.0" ixy="0" ixz="0" iyz="0" />
    </inertial>
  </link>
  <joint name="finger_joint_finger_link_0_5_to_finger_link_0_6" type="revolute">
    <origin xyz="0.0 0.0 0.067" rpy="0 0 0" />
    <parent link="finger_link_0_5" />
    <child link="finger_link_0_6" />
    <axis xyz="0.0 1.0 0.0" />
    <limit lower="-3.142" upper="3.142" effort="10" velocity="10" />
  </joint>
  <link name="finger_link_1_0">
    <visual>
      <origin xyz="0 0 0.0265" rpy="0 0 0" />
      <geometry>
        <box size="0.025 0.037 0.053" />
      </geometry>
    </visual>
    <collision>
      <geometry>
        <box size="0.025 0.037 0.053" />
      </geometry>
    </collision>
    <inertial>
      <mass value="0.015" />
      <inertia ixx="0.0" iyy="0.0" izz="0.0" ixy="0" ixz="0" iyz="0" />
    </inertial>
  </link>
  <joint name="finger_joint_palm_link_to_finger_link_1_0" type="revolute">
    <origin xyz="-0.125 0.101 0.1" rpy="0 0 0" />
    <parent link="palm_link" />
    <child link="finger_link_1_0" />
    <axis xyz="0.0 -1.0 0.0" />
    <limit lower="-3.142" upper="3.142" effort="10" velocity="10" />
  </joint>
  <link name="finger_link_1_1">
    <visual>
      <origin xyz="0 0 0.046" rpy="0 0 0" />
      <geometry>
        <box size="0.027 0.037 0.092" />
      </geometry>
    </visual>
    <collision>
      <geometry>
        <box size="0.027 0.037 0.092" />
      </geometry>
    </collision>
    <inertial>
      <mass value="0.028" />
      <inertia ixx="0.0" iyy="0.0" izz="0.0" ixy="0" ixz="0" iyz="0" />
    </inertial>
  </link>
  <joint name="finger_joint_finger_link_1_0_to_finger_link_1_1" type="revolute">
    <origin xyz="0.0 0.0 0.053" rpy="0 0 0" />
    <parent link="finger_link_1_0" />
    <child link="finger_link_1_1" />
    <axis xyz="1.0 0.0 0.0" />
    <limit lower="-3.142" upper="3.142" effort="10" velocity="10" />
  </joint>
  <link name="finger_link_2_0">
    <visual>
      <origin xyz="0 0 0.034" rpy="0 0 0" />
      <geometry>
        <box size="0.016 0.018 0.068" />
      </geometry>
    </visual>
    <collision>
      <geometry>
        <box size="0.016 0.018 0.068" />
      </geometry>
    </collision>
    <inertial>
      <mass value="0.006" />
      <inertia ixx="0.0" iyy="0.0" izz="0.0" ixy="0" ixz="0" iyz="0" />
    </inertial>
  </link>
  <joint name="finger_joint_palm_link_to_finger_link_2_0" type="revolute">
    <origin xyz="0.125 -0.108 0.1" rpy="0 0 0" />
    <parent link="palm_link" />
    <child link="finger_link_2_0" />
    <axis xyz="0.0 1.0 0.0" />
    <limit lower="-3.142" upper="3.142" effort="10" velocity="10" />
  </joint>
  <link name="finger_link_2_1">
    <visual>
      <origin xyz="0 0 0.047" rpy="0 0 0" />
      <geometry>
        <box size="0.011 0.021 0.094" />
      </geometry>
    </visual>
    <collision>
      <geometry>
        <box size="0.011 0.021 0.094" />
      </geometry>
    </collision>
    <inertial>
      <mass value="0.007" />
      <inertia ixx="0.0" iyy="0.0" izz="0.0" ixy="0" ixz="0" iyz="0" />
    </inertial>
  </link>
  <joint name="finger_joint_finger_link_2_0_to_finger_link_2_1" type="revolute">
    <origin xyz="0.0 0.0 0.068" rpy="0 0 0" />
    <parent link="finger_link_2_0" />
    <child link="finger_link_2_1" />
    <axis xyz="0.0 1.0 0.0" />
    <limit lower="-3.142" upper="3.142" effort="10" velocity="10" />
  </joint>
  <link name="finger_link_2_2">
    <visual>
      <origin xyz="0 0 0.043" rpy="0 0 0" />
      <geometry>
        <box size="0.049 0.016 0.086" />
      </geometry>
    </visual>
    <collision>
      <geometry>
        <box size="0.049 0.016 0.086" />
      </geometry>
    </collision>
    <inertial>
      <mass value="0.02" />
      <inertia ixx="0.0" iyy="0.0" izz="0.0" ixy="0" ixz="0" iyz="0" />
    </inertial>
  </link>
  <joint name="finger_joint_finger_link_2_1_to_finger_link_2_2" type="revolute">
    <origin xyz="0.0 0.0 0.094" rpy="0 0 0" />
    <parent link="finger_link_2_1" />
    <child link="finger_link_2_2" />
    <axis xyz="1.0 0.0 0.0" />
    <limit lower="-3.142" upper="3.142" effort="10" velocity="10" />
  </joint>
  <link name="finger_link_3_0">
    <visual>
      <origin xyz="0 0 0.017" rpy="0 0 0" />
      <geometry>
        <box size="0.049 0.046 0.034" />
      </geometry>
    </visual>
    <collision>
      <geometry>
        <box size="0.049 0.046 0.034" />
      </geometry>
    </collision>
    <inertial>
      <mass value="0.023" />
      <inertia ixx="0.0" iyy="0.0" izz="0.0" ixy="0" ixz="0" iyz="0" />
    </inertial>
  </link>
  <joint name="finger_joint_palm_link_to_finger_link_3_0" type="revolute">
    <origin xyz="-0.016 0.125 0.1" rpy="0 0 0" />
    <parent link="palm_link" />
    <child link="finger_link_3_0" />
    <axis xyz="-1.0 0.0 0.0" />
    <limit lower="-3.142" upper="3.142" effort="10" velocity="10" />
  </joint>
  <link name="finger_link_3_1">
    <visual>
      <origin xyz="0 0 0.026" rpy="0 0 0" />
      <geometry>
        <box size="0.023 0.016 0.052" />
      </geometry>
    </visual>
    <collision>
      <geometry>
        <box size="0.023 0.016 0.052" />
      </geometry>
    </collision>
    <inertial>
      <mass value="0.006" />
      <inertia ixx="0.0" iyy="0.0" izz="0.0" ixy="0" ixz="0" iyz="0" />
    </inertial>
  </link>
  <joint name="finger_joint_finger_link_3_0_to_finger_link_3_1" type="revolute">
    <origin xyz="0.0 0.0 0.034" rpy="0 0 0" />
    <parent link="finger_link_3_0" />
    <child link="finger_link_3_1" />
    <axis xyz="0.0 1.0 0.0" />
    <limit lower="-3.142" upper="3.142" effort="10" velocity="10" />
  </joint>
  <link name="finger_link_3_2">
    <visual>
      <origin xyz="0 0 0.0405" rpy="0 0 0" />
      <geometry>
        <box size="0.013 0.03 0.081" />
      </geometry>
    </visual>
    <collision>
      <geometry>
        <box size="0.013 0.03 0.081" />
      </geometry>
    </collision>
    <inertial>
      <mass value="0.009" />
      <inertia ixx="0.0" iyy="0.0" izz="0.0" ixy="0" ixz="0" iyz="0" />
    </inertial>
  </link>
  <joint name="finger_joint_finger_link_3_1_to_finger_link_3_2" type="revolute">
    <origin xyz="0.0 0.0 0.052" rpy="0 0 0" />
    <parent link="finger_link_3_1" />
    <child link="finger_link_3_2" />
    <axis xyz="0.0 1.0 0.0" />
    <limit lower="-3.142" upper="3.142" effort="10" velocity="10" />
  </joint>
  <link name="finger_link_3_3">
    <visual>
      <origin xyz="0 0 0.0115" rpy="0 0 0" />
      <geometry>
        <box size="0.043 0.018 0.023" />
      </geometry>
    </visual>
    <collision>
      <geometry>
        <box size="0.043 0.018 0.023" />
      </geometry>
    </collision>
    <inertial>
      <mass value="0.005" />
      <inertia ixx="0.0" iyy="0.0" izz="0.0" ixy="0" ixz="0" iyz="0" />
    </inertial>
  </link>
  <joint name="finger_joint_finger_link_3_2_to_finger_link_3_3" type="revolute">
    <origin xyz="0.0 0.0 0.081" rpy="0 0 0" />
    <parent link="finger_link_3_2" />
    <child link="finger_link_3_3" />
    <axis xyz="1.0 0.0 0.0" />
    <limit lower="-3.142" upper="3.142" effort="10" velocity="10" />
  </joint>
  <link name="finger_link_4_0">
    <visual>
      <origin xyz="0 0 0.0365" rpy="0 0 0" />
      <geometry>
        <box size="0.044 0.042 0.073" />
      </geometry>
    </visual>
    <collision>
      <geometry>
        <box size="0.044 0.042 0.073" />
      </geometry>
    </collision>
    <inertial>
      <mass value="0.04" />
      <inertia ixx="0.0" iyy="0.0" izz="0.0" ixy="0" ixz="0" iyz="0" />
    </inertial>
  </link>
  <joint name="finger_joint_palm_link_to_finger_link_4_0" type="revolute">
    <origin xyz="-0.125 0.005 0.1" rpy="0 0 0" />
    <parent link="palm_link" />
    <child link="finger_link_4_0" />
    <axis xyz="0.0 -1.0 0.0" />
    <limit lower="-3.142" upper="3.142" effort="10" velocity="10" />
  </joint>
  <link name="finger_link_4_1">
    <visual>
      <origin xyz="0 0 0.0495" rpy="0 0 0" />
      <geometry>
        <box size="0.012 0.018 0.099" />
      </geometry>
    </visual>
    <collision>
      <geometry>
        <box size="0.012 0.018 0.099" />
      </geometry>
    </collision>
    <inertial>
      <mass value="0.006" />
      <inertia ixx="0.0" iyy="0.0" izz="0.0" ixy="0" ixz="0" iyz="0" />
    </inertial>
  </link>
  <joint name="finger_joint_finger_link_4_0_to_finger_link_4_1" type="revolute">
    <origin xyz="0.0 0.0 0.073" rpy="0 0 0" />
    <parent link="finger_link_4_0" />
    <child link="finger_link_4_1" />
    <axis xyz="1.0 0.0 0.0" />
    <limit lower="-3.142" upper="3.142" effort="10" velocity="10" />
  </joint>
  <link name="finger_link_4_2">
    <visual>
      <origin xyz="0 0 0.0295" rpy="0 0 0" />
      <geometry>
        <box size="0.025 0.019 0.059" />
      </geometry>
    </visual>
    <collision>
      <geometry>
        <box size="0.025 0.019 0.059" />
      </geometry>
    </collision>
    <inertial>
      <mass value="0.008" />
      <inertia ixx="0.0" iyy="0.0" izz="0.0" ixy="0" ixz="0" iyz="0" />
    </inertial>
  </link>
  <joint name="finger_joint_finger_link_4_1_to_finger_link_4_2" type="revolute">
    <origin xyz="0.0 0.0 0.099" rpy="0 0 0" />
    <parent link="finger_link_4_1" />
    <child link="finger_link_4_2" />
    <axis xyz="0.0 1.0 0.0" />
    <limit lower="-3.142" upper="3.142" effort="10" velocity="10" />
  </joint>
  <link name="finger_link_4_3">
    <visual>
      <origin xyz="0 0 0.0445" rpy="0 0 0" />
      <geometry>
        <box size="0.022 0.043 0.089" />
      </geometry>
    </visual>
    <collision>
      <geometry>
        <box size="0.022 0.043 0.089" />
      </geometry>
    </collision>
    <inertial>
      <mass value="0.025" />
      <inertia ixx="0.0" iyy="0.0" izz="0.0" ixy="0" ixz="0" iyz="0" />
    </inertial>
  </link>
  <joint name="finger_joint_finger_link_4_2_to_finger_link_4_3" type="revolute">
    <origin xyz="0.0 0.0 0.059" rpy="0 0 0" />
    <parent link="finger_link_4_2" />
    <child link="finger_link_4_3" />
    <axis xyz="0.0 1.0 0.0" />
    <limit lower="-3.142" upper="3.142" effort="10" velocity="10" />
  </joint>
  <link name="finger_link_4_4">
    <visual>
      <origin xyz="0 0 0.026" rpy="0 0 0" />
      <geometry>
        <box size="0.017 0.043 0.052" />
      </geometry>
    </visual>
    <collision>
      <geometry>
        <box size="0.017 0.043 0.052" />
      </geometry>
    </collision>
    <inertial>
      <mass value="0.011" />
      <inertia ixx="0.0" iyy="0.0" izz="0.0" ixy="0" ixz="0" iyz="0" />
    </inertial>
  </link>
  <joint name="finger_joint_finger_link_4_3_to_finger_link_4_4" type="revolute">
    <origin xyz="0.0 0.0 0.089" rpy="0 0 0" />
    <parent link="finger_link_4_3" />
    <child link="finger_link_4_4" />
    <axis xyz="0.0 1.0 0.0" />
    <limit lower="-3.142" upper="3.142" effort="10" velocity="10" />
  </joint>
  <link name="finger_link_5_0">
    <visual>
      <origin xyz="0 0 0.0215" rpy="0 0 0" />
      <geometry>
        <box size="0.047 0.032 0.043" />
      </geometry>
    </visual>
    <collision>
      <geometry>
        <box size="0.047 0.032 0.043" />
      </geometry>
    </collision>
    <inertial>
      <mass value="0.019" />
      <inertia ixx="0.0" iyy="0.0" izz="0.0" ixy="0" ixz="0" iyz="0" />
    </inertial>
  </link>
  <joint name="finger_joint_palm_link_to_finger_link_5_0" type="revolute">
    <origin xyz="-0.125 -0.002 0.1" rpy="0 0 0" />
    <parent link="palm_link" />
    <child link="finger_link_5_0" />
    <axis xyz="0.0 -1.0 0.0" />
    <limit lower="-3.142" upper="3.142" effort="10" velocity="10" />
  </joint>
  <link name="finger_link_5_1">
    <visual>
      <origin xyz="0 0 0.03" rpy="0 0 0" />
      <geometry>
        <box size="0.038 0.037 0.06" />
      </geometry>
    </visual>
    <collision>
      <geometry>
        <box size="0.038 0.037 0.06" />
      </geometry>
    </collision>
    <inertial>
      <mass value="0.025" />
      <inertia ixx="0.0" iyy="0.0" izz="0.0" ixy="0" ixz="0" iyz="0" />
    </inertial>
  </link>
  <joint name="finger_joint_finger_link_5_0_to_finger_link_5_1" type="revolute">
    <origin xyz="0.0 0.0 0.043" rpy="0 0 0" />
    <parent link="finger_link_5_0" />
    <child link="finger_link_5_1" />
    <axis xyz="0.0 1.0 0.0" />
    <limit lower="-3.142" upper="3.142" effort="10" velocity="10" />
  </joint>
  <link name="finger_link_5_2">
    <visual>
      <origin xyz="0 0 0.011" rpy="0 0 0" />
      <geometry>
        <box size="0.038 0.016 0.022" />
      </geometry>
    </visual>
    <collision>
      <geometry>
        <box size="0.038 0.016 0.022" />
      </geometry>
    </collision>
    <inertial>
      <mass value="0.004" />
      <inertia ixx="0.0" iyy="0.0" izz="0.0" ixy="0" ixz="0" iyz="0" />
    </inertial>
  </link>
  <joint name="finger_joint_finger_link_5_1_to_finger_link_5_2" type="revolute">
    <origin xyz="0.0 0.0 0.06" rpy="0 0 0" />
    <parent link="finger_link_5_1" />
    <child link="finger_link_5_2" />
    <axis xyz="1.0 0.0 0.0" />
    <limit lower="-3.142" upper="3.142" effort="10" velocity="10" />
  </joint>
  <link name="finger_link_5_3">
    <visual>
      <origin xyz="0 0 0.0125" rpy="0 0 0" />
      <geometry>
        <box size="0.027 0.046 0.025" />
      </geometry>
    </visual>
    <collision>
      <geometry>
        <box size="0.027 0.046 0.025" />
      </geometry>
    </collision>
    <inertial>
      <mass value="0.009" />
      <inertia ixx="0.0" iyy="0.0" izz="0.0" ixy="0" ixz="0" iyz="0" />
    </inertial>
  </link>
  <joint name="finger_joint_finger_link_5_2_to_finger_link_5_3" type="revolute">
    <origin xyz="0.0 0.0 0.022" rpy="0 0 0" />
    <parent link="finger_link_5_2" />
    <child link="finger_link_5_3" />
    <axis xyz="0.0 1.0 0.0" />
    <limit lower="-3.142" upper="3.142" effort="10" velocity="10" />
  </joint>
  <link name="finger_link_5_4">
    <visual>
      <origin xyz="0 0 0.036" rpy="0 0 0" />
      <geometry>
        <box size="0.036 0.045 0.072" />
      </geometry>
    </visual>
    <collision>
      <geometry>
        <box size="0.036 0.045 0.072" />
      </geometry>
    </collision>
    <inertial>
      <mass value="0.035" />
      <inertia ixx="0.0" iyy="0.0" izz="0.0" ixy="0" ixz="0" iyz="0" />
    </inertial>
  </link>
  <joint name="finger_joint_finger_link_5_3_to_finger_link_5_4" type="revolute">
    <origin xyz="0.0 0.0 0.025" rpy="0 0 0" />
    <parent link="finger_link_5_3" />
    <child link="finger_link_5_4" />
    <axis xyz="1.0 0.0 0.0" />
    <limit lower="-3.142" upper="3.142" effort="10" velocity="10" />
  </joint>
  <link name="finger_link_5_5">
    <visual>
      <origin xyz="0 0 0.0325" rpy="0 0 0" />
      <geometry>
        <box size="0.024 0.035 0.065" />
      </geometry>
    </visual>
    <collision>
      <geometry>
        <box size="0.024 0.035 0.065" />
      </geometry>
    </collision>
    <inertial>
      <mass value="0.016" />
      <inertia ixx="0.0" iyy="0.0" izz="0.0" ixy="0" ixz="0" iyz="0" />
    </inertial>
  </link>
  <joint name="finger_joint_finger_link_5_4_to_finger_link_5_5" type="revolute">
    <origin xyz="0.0 0.0 0.072" rpy="0 0 0" />
    <parent link="finger_link_5_4" />
    <child link="finger_link_5_5" />
    <axis xyz="1.0 0.0 0.0" />
    <limit lower="-3.142" upper="3.142" effort="10" velocity="10" />
  </joint>
  <link name="finger_link_5_6">
    <visual>
      <origin xyz="0 0 0.043" rpy="0 0 0" />
      <geometry>
        <box size="0.02 0.05 0.086" />
      </geometry>
    </visual>
    <collision>
      <geometry>
        <box size="0.02 0.05 0.086" />
      </geometry>
    </collision>
    <inertial>
      <mass value="0.026" />
      <inertia ixx="0.0" iyy="0.0" izz="0.0" ixy="0" ixz="0" iyz="0" />
    </inertial>
  </link>
  <joint name="finger_joint_finger_link_5_5_to_finger_link_5_6" type="revolute">
    <origin xyz="0.0 0.0 0.065" rpy="0 0 0" />
    <parent link="finger_link_5_5" />
    <child link="finger_link_5_6" />
    <axis xyz="1.0 0.0 0.0" />
    <limit lower="-3.142" upper="3.142" effort="10" velocity="10" />
  </joint>
  <link name="finger_link_5_7">
    <visual>
      <origin xyz="0 0 0.041" rpy="0 0 0" />
      <geometry>
        <box size="0.014 0.012 0.082" />
      </geometry>
    </visual>
    <collision>
      <geometry>
        <box size="0.014 0.012 0.082" />
      </geometry>
    </collision>
    <inertial>
      <mass value="0.004" />
      <inertia ixx="0.0" iyy="0.0" izz="0.0" ixy="0" ixz="0" iyz="0" />
    </inertial>
  </link>
  <joint name="finger_joint_finger_link_5_6_to_finger_link_5_7" type="revolute">
    <origin xyz="0.0 0.0 0.086" rpy="0 0 0" />
    <parent link="finger_link_5_6" />
    <child link="finger_link_5_7" />
    <axis xyz="0.0 1.0 0.0" />
    <limit lower="-3.142" upper="3.142" effort="10" velocity="10" />
  </joint>
</robot>