<?xml version='1.0' encoding='utf-8'?>
<robot name="robot">
  <link name="base_link">
    <visual>
      <origin xyz="0 0 0.125" rpy="0 0 0" />
      <geometry>
        <box size="0.75 0.75 0.25" />
      </geometry>
      <material name="green" />
    </visual>
    <visual>
      <origin xyz="0 0 0.375" rpy="0 0 0" />
      <geometry>
        <cylinder length="0.25" radius="0.25" />
      </geometry>
      <material name="green">
        <color rgba="0 1 0 1" />
      </material>
    </visual>
    <collision>
      <geometry>
        <box size="0.75 0.75 0.5" />
      </geometry>
    </collision>
    <inertial>
      <mass value="0.5" />
      <inertia ixx="0.034" ixy="0.0" ixz="0.0" iyy="0.034" iyz="0.0" izz="0.034" />
    </inertial>
  </link>
  <link name="support_link">
    <visual>
      <origin xyz="0 0 0.5" rpy="0 0 0" />
      <geometry>
        <box size="0.2 0.2 1" />
      </geometry>
      <material name="white">
        <color rgba="1 1 1 1" />
      </material>
    </visual>
    <collision>
      <geometry>
        <box size="0.2 0.2 1" />
      </geometry>
    </collision>
    <inertial>
      <mass value="0.1" />
      <inertia ixx="0.01" ixy="0.0" ixz="0.0" iyy="0.01" iyz="0.0" izz="0.01" />
    </inertial>
  </link>
  <joint name="support_joint" type="continuous">
    <origin xyz="0 0 0.5" rpy="0 0 0" />
    <parent link="base_link" />
    <child link="support_link" />
    <axis xyz="0 0 1" />
  </joint>
  <link name="arm_link">
    <visual>
      <origin xyz="0 0 0.5" rpy="0 0 0" />
      <geometry>
        <box size="0.2 0.2 1" />
      </geometry>
      <material name="blue">
        <color rgba="0 0 1 1" />
      </material>
    </visual>
    <collision>
      <geometry>
        <box size="0.2 0.2 1" />
      </geometry>
    </collision>
    <inertial>
      <mass value="0.1" />
      <inertia ixx="0.01" ixy="0.0" ixz="0.0" iyy="0.01" iyz="0.0" izz="0.01" />
    </inertial>
  </link>
  <joint name="arm_joint" type="revolute">
    <origin xyz="-0.1 0 1" rpy="0 0 0" />
    <parent link="support_link" />
    <child link="arm_link" />
    <axis xyz="0 1 0" />
    <limit lower="-3.14" upper="3.14" effort="1.0" velocity="1.0" />
  </joint>
  <link name="wrist_link">
    <visual>
      <origin xyz="0 0 0.25" rpy="0 0 0" />
      <geometry>
        <box size="0.15 0.15 0.5" />
      </geometry>
      <material name="orange">
        <color rgba="1 0.5 0 1" />
      </material>
    </visual>
    <collision>
      <geometry>
        <box size="0.15 0.15 0.5" />
      </geometry>
    </collision>
    <inertial>
      <mass value="0.1" />
      <inertia ixx="0.01" ixy="0.0" ixz="0.0" iyy="0.01" iyz="0.0" izz="0.01" />
    </inertial>
  </link>
  <joint name="wrist_joint" type="fixed">
    <origin xyz="0 0 0.9" rpy="0 1.571 0" />
    <parent link="arm_link" />
    <child link="wrist_link" />
  </joint>
  <link name="palm_link">
    <visual>
      <origin xyz="0 0 0.05" rpy="0 0 0" />
      <geometry>
        <box size="0.25 0.25 0.1" />
      </geometry>
      <material name="orange" />
    </visual>
    <collision>
      <geometry>
        <box size="0.25 0.25 0.1" />
      </geometry>
    </collision>
    <inertial>
      <mass value="0.1" />
      <inertia ixx="0.01" ixy="0.0" ixz="0.0" iyy="0.01" iyz="0.0" izz="0.01" />
    </inertial>
  </link>
  <joint name="palm_joint" type="fixed">
    <origin xyz="0 0 0.45" rpy="0 0 0" />
    <parent link="wrist_link" />
    <child link="palm_link" />
  </joint>
  <link name="finger_link_0_0">
    <visual>
      <origin xyz="0 0 0.0345" rpy="0 0 0" />
      <geometry>
        <box size="0.032 0.039 0.069" />
      </geometry>
    </visual>
    <collision>
      <geometry>
        <box size="0.032 0.039 0.069" />
      </geometry>
    </collision>
    <inertial>
      <mass value="0.026" />
      <inertia ixx="0.0" iyy="0.0" izz="0.0" ixy="0" ixz="0" iyz="0" />
    </inertial>
  </link>
  <joint name="finger_joint_palm_link_to_finger_link_0_0" type="revolute">
    <origin xyz="0.125 -0.114 0.1" rpy="0 0 0" />
    <parent link="palm_link" />
    <child link="finger_link_0_0" />
    <axis xyz="0.0 1.0 0.0" />
    <limit lower="-3.142" upper="3.142" effort="10" velocity="10" />
  </joint>
  <link name="finger_link_0_1">
    <visual>
      <origin xyz="0 0 0.007" rpy="0 0 0" />
      <geometry>
        <box size="0.027 0.024 0.014" />
      </geometry>
    </visual>
    <collision>
      <geometry>
        <box size="0.027 0.024 0.014" />
      </geometry>
    </collision>
    <inertial>
      <mass value="0.003" />
      <inertia ixx="0.0" iyy="0.0" izz="0.0" ixy="0" ixz="0" iyz="0" />
    </inertial>
  </link>
  <joint name="finger_joint_finger_link_0_0_to_finger_link_0_1" type="revolute">
    <origin xyz="0.0 0.0 0.069" rpy="0 0 0" />
    <parent link="finger_link_0_0" />
    <child link="finger_link_0_1" />
    <axis xyz="0.0 1.0 0.0" />
    <limit lower="-3.142" upper="3.142" effort="10" velocity="10" />
  </joint>
  <link name="finger_link_1_0">
    <visual>
      <origin xyz="0 0 0.036" rpy="0 0 0" />
      <geometry>
        <box size="0.04 0.041 0.072" />
      </geometry>
    </visual>
    <collision>
      <geometry>
        <box size="0.04 0.041 0.072" />
      </geometry>
    </collision>
    <inertial>
      <mass value="0.035" />
      <inertia ixx="0.0" iyy="0.0" izz="0.0" ixy="0" ixz="0" iyz="0" />
    </inertial>
  </link>
  <joint name="finger_joint_palm_link_to_finger_link_1_0" type="revolute">
    <origin xyz="0.125 -0.006 0.1" rpy="0 0 0" />
    <parent link="palm_link" />
    <child link="finger_link_1_0" />
    <axis xyz="0.0 1.0 0.0" />
    <limit lower="-3.142" upper="3.142" effort="10" velocity="10" />
  </joint>
  <link name="finger_link_1_1">
    <visual>
      <origin xyz="0 0 0.0095" rpy="0 0 0" />
      <geometry>
        <box size="0.02 0.038 0.019" />
      </geometry>
    </visual>
    <collision>
      <geometry>
        <box size="0.02 0.038 0.019" />
      </geometry>
    </collision>
    <inertial>
      <mass value="0.004" />
      <inertia ixx="0.0" iyy="0.0" izz="0.0" ixy="0" ixz="0" iyz="0" />
    </inertial>
  </link>
  <joint name="finger_joint_finger_link_1_0_to_finger_link_1_1" type="revolute">
    <origin xyz="0.0 0.0 0.072" rpy="0 0 0" />
    <parent link="finger_link_1_0" />
    <child link="finger_link_1_1" />
    <axis xyz="1.0 1.0 0.0" />
    <limit lower="-3.142" upper="3.142" effort="10" velocity="10" />
  </joint>
  <link name="finger_link_1_2">
    <visual>
      <origin xyz="0 0 0.025" rpy="0 0 0" />
      <geometry>
        <box size="0.025 0.023 0.05" />
      </geometry>
    </visual>
    <collision>
      <geometry>
        <box size="0.025 0.023 0.05" />
      </geometry>
    </collision>
    <inertial>
      <mass value="0.009" />
      <inertia ixx="0.0" iyy="0.0" izz="0.0" ixy="0" ixz="0" iyz="0" />
    </inertial>
  </link>
  <joint name="finger_joint_finger_link_1_1_to_finger_link_1_2" type="revolute">
    <origin xyz="0.0 0.0 0.019" rpy="0 0 0" />
    <parent link="finger_link_1_1" />
    <child link="finger_link_1_2" />
    <axis xyz="1.0 0.0 0.0" />
    <limit lower="-3.142" upper="3.142" effort="10" velocity="10" />
  </joint>
  <link name="finger_link_1_3">
    <visual>
      <origin xyz="0 0 0.038" rpy="0 0 0" />
      <geometry>
        <box size="0.025 0.038 0.076" />
      </geometry>
    </visual>
    <collision>
      <geometry>
        <box size="0.025 0.038 0.076" />
      </geometry>
    </collision>
    <inertial>
      <mass value="0.022" />
      <inertia ixx="0.0" iyy="0.0" izz="0.0" ixy="0" ixz="0" iyz="0" />
    </inertial>
  </link>
  <joint name="finger_joint_finger_link_1_2_to_finger_link_1_3" type="revolute">
    <origin xyz="0.0 0.0 0.05" rpy="0 0 0" />
    <parent link="finger_link_1_2" />
    <child link="finger_link_1_3" />
    <axis xyz="1.0 1.0 0.0" />
    <limit lower="-3.142" upper="3.142" effort="10" velocity="10" />
  </joint>
  <link name="finger_link_1_4">
    <visual>
      <origin xyz="0 0 0.0375" rpy="0 0 0" />
      <geometry>
        <box size="0.049 0.03 0.075" />
      </geometry>
    </visual>
    <collision>
      <geometry>
        <box size="0.049 0.03 0.075" />
      </geometry>
    </collision>
    <inertial>
      <mass value="0.033" />
      <inertia ixx="0.0" iyy="0.0" izz="0.0" ixy="0" ixz="0" iyz="0" />
    </inertial>
  </link>
  <joint name="finger_joint_finger_link_1_3_to_finger_link_1_4" type="revolute">
    <origin xyz="0.0 0.0 0.076" rpy="0 0 0" />
    <parent link="finger_link_1_3" />
    <child link="finger_link_1_4" />
    <axis xyz="1.0 0.0 0.0" />
    <limit lower="-3.142" upper="3.142" effort="10" velocity="10" />
  </joint>
  <link name="finger_link_1_5">
    <visual>
      <origin xyz="0 0 0.034" rpy="0 0 0" />
      <geometry>
        <box size="0.023 0.043 0.068" />
      </geometry>
    </visual>
    <collision>
      <geometry>
        <box size="0.023 0.043 0.068" />
      </geometry>
    </collision>
    <inertial>
      <mass value="0.02" />
      <inertia ixx="0.0" iyy="0.0" izz="0.0" ixy="0" ixz="0" iyz="0" />
    </inertial>
  </link>
  <joint name="finger_joint_finger_link_1_4_to_finger_link_1_5" type="revolute">
    <origin xyz="0.0 0.0 0.075" rpy="0 0 0" />
    <parent link="finger_link_1_4" />
    <child link="finger_link_1_5" />
    <axis xyz="0.0 1.0 0.0" />
    <limit lower="-3.142" upper="3.142" effort="10" velocity="10" />
  </joint>
  <link name="finger_link_1_6">
    <visual>
      <origin xyz="0 0 0.0435" rpy="0 0 0" />
      <geometry>
        <box size="0.021 0.018 0.087" />
      </geometry>
    </visual>
    <collision>
      <geometry>
        <box size="0.021 0.018 0.087" />
      </geometry>
    </collision>
    <inertial>
      <mass value="0.01" />
      <inertia ixx="0.0" iyy="0.0" izz="0.0" ixy="0" ixz="0" iyz="0" />
    </inertial>
  </link>
  <joint name="finger_joint_finger_link_1_5_to_finger_link_1_6" type="revolute">
    <origin xyz="0.0 0.0 0.068" rpy="0 0 0" />
    <parent link="finger_link_1_5" />
    <child link="finger_link_1_6" />
    <axis xyz="0.0 1.0 0.0" />
    <limit lower="-3.142" upper="3.142" effort="10" velocity="10" />
  </joint>
  <link name="finger_link_1_7">
    <visual>
      <origin xyz="0 0 0.0395" rpy="0 0 0" />
      <geometry>
        <box size="0.029 0.05 0.079" />
      </geometry>
    </visual>
    <collision>
      <geometry>
        <box size="0.029 0.05 0.079" />
      </geometry>
    </collision>
    <inertial>
      <mass value="0.034" />
      <inertia ixx="0.0" iyy="0.0" izz="0.0" ixy="0" ixz="0" iyz="0" />
    </inertial>
  </link>
  <joint name="finger_joint_finger_link_1_6_to_finger_link_1_7" type="revolute">
    <origin xyz="0.0 0.0 0.087" rpy="0 0 0" />
    <parent link="finger_link_1_6" />
    <child link="finger_link_1_7" />
    <axis xyz="1.0 0.0 0.0" />
    <limit lower="-3.142" upper="3.142" effort="10" velocity="10" />
  </joint>
  <link name="finger_link_1_8">
    <visual>
      <origin xyz="0 0 0.032" rpy="0 0 0" />
      <geometry>
        <box size="0.044 0.03 0.064" />
      </geometry>
    </visual>
    <collision>
      <geometry>
        <box size="0.044 0.03 0.064" />
      </geometry>
    </collision>
    <inertial>
      <mass value="0.025" />
      <inertia ixx="0.0" iyy="0.0" izz="0.0" ixy="0" ixz="0" iyz="0" />
    </inertial>
  </link>
  <joint name="finger_joint_finger_link_1_7_to_finger_link_1_8" type="revolute">
    <origin xyz="0.0 0.0 0.079" rpy="0 0 0" />
    <parent link="finger_link_1_7" />
    <child link="finger_link_1_8" />
    <axis xyz="1.0 0.0 0.0" />
    <limit lower="-3.142" upper="3.142" effort="10" velocity="10" />
  </joint>
  <link name="finger_link_2_0">
    <visual>
      <origin xyz="0 0 0.015" rpy="0 0 0" />
      <geometry>
        <box size="0.032 0.037 0.03" />
      </geometry>
    </visual>
    <collision>
      <geometry>
        <box size="0.032 0.037 0.03" />
      </geometry>
    </collision>
    <inertial>
      <mass value="0.011" />
      <inertia ixx="0.0" iyy="0.0" izz="0.0" ixy="0" ixz="0" iyz="0" />
    </inertial>
  </link>
  <joint name="finger_joint_palm_link_to_finger_link_2_0" type="revolute">
    <origin xyz="0.103 0.125 0.1" rpy="0 0 0" />
    <parent link="palm_link" />
    <child link="finger_link_2_0" />
    <axis xyz="-1.0 0.0 0.0" />
    <limit lower="-3.142" upper="3.142" effort="10" velocity="10" />
  </joint>
  <link name="finger_link_2_1">
    <visual>
      <origin xyz="0 0 0.037" rpy="0 0 0" />
      <geometry>
        <box size="0.047 0.017 0.074" />
      </geometry>
    </visual>
    <collision>
      <geometry>
        <box size="0.047 0.017 0.074" />
      </geometry>
    </collision>
    <inertial>
      <mass value="0.018" />
      <inertia ixx="0.0" iyy="0.0" izz="0.0" ixy="0" ixz="0" iyz="0" />
    </inertial>
  </link>
  <joint name="finger_joint_finger_link_2_0_to_finger_link_2_1" type="revolute">
    <origin xyz="0.0 0.0 0.03" rpy="0 0 0" />
    <parent link="finger_link_2_0" />
    <child link="finger_link_2_1" />
    <axis xyz="1.0 0.0 0.0" />
    <limit lower="-3.142" upper="3.142" effort="10" velocity="10" />
  </joint>
  <link name="finger_link_2_2">
    <visual>
      <origin xyz="0 0 0.0075" rpy="0 0 0" />
      <geometry>
        <box size="0.046 0.023 0.015" />
      </geometry>
    </visual>
    <collision>
      <geometry>
        <box size="0.046 0.023 0.015" />
      </geometry>
    </collision>
    <inertial>
      <mass value="0.005" />
      <inertia ixx="0.0" iyy="0.0" izz="0.0" ixy="0" ixz="0" iyz="0" />
    </inertial>
  </link>
  <joint name="finger_joint_finger_link_2_1_to_finger_link_2_2" type="revolute">
    <origin xyz="0.0 0.0 0.074" rpy="0 0 0" />
    <parent link="finger_link_2_1" />
    <child link="finger_link_2_2" />
    <axis xyz="0.0 1.0 0.0" />
    <limit lower="-3.142" upper="3.142" effort="10" velocity="10" />
  </joint>
  <link name="finger_link_2_3">
    <visual>
      <origin xyz="0 0 0.036" rpy="0 0 0" />
      <geometry>
        <box size="0.016 0.048 0.072" />
      </geometry>
    </visual>
    <collision>
      <geometry>
        <box size="0.016 0.048 0.072" />
      </geometry>
    </collision>
    <inertial>
      <mass value="0.017" />
      <inertia ixx="0.0" iyy="0.0" izz="0.0" ixy="0" ixz="0" iyz="0" />
    </inertial>
  </link>
  <joint name="finger_joint_finger_link_2_2_to_finger_link_2_3" type="revolute">
    <origin xyz="0.0 0.0 0.015" rpy="0 0 0" />
    <parent link="finger_link_2_2" />
    <child link="finger_link_2_3" />
    <axis xyz="0.0 1.0 0.0" />
    <limit lower="-3.142" upper="3.142" effort="10" velocity="10" />
  </joint>
  <link name="finger_link_2_4">
    <visual>
      <origin xyz="0 0 0.0185" rpy="0 0 0" />
      <geometry>
        <box size="0.04 0.049 0.037" />
      </geometry>
    </visual>
    <collision>
      <geometry>
        <box size="0.04 0.049 0.037" />
      </geometry>
    </collision>
    <inertial>
      <mass value="0.022" />
      <inertia ixx="0.0" iyy="0.0" izz="0.0" ixy="0" ixz="0" iyz="0" />
    </inertial>
  </link>
  <joint name="finger_joint_finger_link_2_3_to_finger_link_2_4" type="revolute">
    <origin xyz="0.0 0.0 0.072" rpy="0 0 0" />
    <parent link="finger_link_2_3" />
    <child link="finger_link_2_4" />
    <axis xyz="1.0 0.0 0.0" />
    <limit lower="-3.142" upper="3.142" effort="10" velocity="10" />
  </joint>
  <link name="finger_link_3_0">
    <visual>
      <origin xyz="0 0 0.031" rpy="0 0 0" />
      <geometry>
        <box size="0.043 0.037 0.062" />
      </geometry>
    </visual>
    <collision>
      <geometry>
        <box size="0.043 0.037 0.062" />
      </geometry>
    </collision>
    <inertial>
      <mass value="0.03" />
      <inertia ixx="0.0" iyy="0.0" izz="0.0" ixy="0" ixz="0" iyz="0" />
    </inertial>
  </link>
  <joint name="finger_joint_palm_link_to_finger_link_3_0" type="revolute">
    <origin xyz="0.043 -0.125 0.1" rpy="0 0 0" />
    <parent link="palm_link" />
    <child link="finger_link_3_0" />
    <axis xyz="1.0 0.0 0.0" />
    <limit lower="-3.142" upper="3.142" effort="10" velocity="10" />
  </joint>
  <link name="finger_link_3_1">
    <visual>
      <origin xyz="0 0 0.0395" rpy="0 0 0" />
      <geometry>
        <box size="0.045 0.046 0.079" />
      </geometry>
    </visual>
    <collision>
      <geometry>
        <box size="0.045 0.046 0.079" />
      </geometry>
    </collision>
    <inertial>
      <mass value="0.049" />
      <inertia ixx="0.0" iyy="0.0" izz="0.0" ixy="0" ixz="0" iyz="0" />
    </inertial>
  </link>
  <joint name="finger_joint_finger_link_3_0_to_finger_link_3_1" type="revolute">
    <origin xyz="0.0 0.0 0.062" rpy="0 0 0" />
    <parent link="finger_link_3_0" />
    <child link="finger_link_3_1" />
    <axis xyz="1.0 0.0 0.0" />
    <limit lower="-3.142" upper="3.142" effort="10" velocity="10" />
  </joint>
  <link name="finger_link_3_2">
    <visual>
      <origin xyz="0 0 0.038" rpy="0 0 0" />
      <geometry>
        <box size="0.012 0.048 0.076" />
      </geometry>
    </visual>
    <collision>
      <geometry>
        <box size="0.012 0.048 0.076" />
      </geometry>
    </collision>
    <inertial>
      <mass value="0.013" />
      <inertia ixx="0.0" iyy="0.0" izz="0.0" ixy="0" ixz="0" iyz="0" />
    </inertial>
  </link>
  <joint name="finger_joint_finger_link_3_1_to_finger_link_3_2" type="revolute">
    <origin xyz="0.0 0.0 0.079" rpy="0 0 0" />
    <parent link="finger_link_3_1" />
    <child link="finger_link_3_2" />
    <axis xyz="0.0 1.0 0.0" />
    <limit lower="-3.142" upper="3.142" effort="10" velocity="10" />
  </joint>
  <link name="finger_link_3_3">
    <visual>
      <origin xyz="0 0 0.032" rpy="0 0 0" />
      <geometry>
        <box size="0.031 0.017 0.064" />
      </geometry>
    </visual>
    <collision>
      <geometry>
        <box size="0.031 0.017 0.064" />
      </geometry>
    </collision>
    <inertial>
      <mass value="0.01" />
      <inertia ixx="0.0" iyy="0.0" izz="0.0" ixy="0" ixz="0" iyz="0" />
    </inertial>
  </link>
  <joint name="finger_joint_finger_link_3_2_to_finger_link_3_3" type="revolute">
    <origin xyz="0.0 0.0 0.076" rpy="0 0 0" />
    <parent link="finger_link_3_2" />
    <child link="finger_link_3_3" />
    <axis xyz="0.0 1.0 0.0" />
    <limit lower="-3.142" upper="3.142" effort="10" velocity="10" />
  </joint>
  <link name="finger_link_3_4">
    <visual>
      <origin xyz="0 0 0.0105" rpy="0 0 0" />
      <geometry>
        <box size="0.029 0.04 0.021" />
      </geometry>
    </visual>
    <collision>
      <geometry>
        <box size="0.029 0.04 0.021" />
      </geometry>
    </collision>
    <inertial>
      <mass value="0.007" />
      <inertia ixx="0.0" iyy="0.0" izz="0.0" ixy="0" ixz="0" iyz="0" />
    </inertial>
  </link>
  <joint name="finger_joint_finger_link_3_3_to_finger_link_3_4" type="revolute">
    <origin xyz="0.0 0.0 0.064" rpy="0 0 0" />
    <parent link="finger_link_3_3" />
    <child link="finger_link_3_4" />
    <axis xyz="0.0 1.0 0.0" />
    <limit lower="-3.142" upper="3.142" effort="10" velocity="10" />
  </joint>
  <link name="finger_link_3_5">
    <visual>
      <origin xyz="0 0 0.0485" rpy="0 0 0" />
      <geometry>
        <box size="0.011 0.017 0.097" />
      </geometry>
    </visual>
    <collision>
      <geometry>
        <box size="0.011 0.017 0.097" />
      </geometry>
    </collision>
    <inertial>
      <mass value="0.005" />
      <inertia ixx="0.0" iyy="0.0" izz="0.0" ixy="0" ixz="0" iyz="0" />
    </inertial>
  </link>
  <joint name="finger_joint_finger_link_3_4_to_finger_link_3_5" type="revolute">
    <origin xyz="0.0 0.0 0.021" rpy="0 0 0" />
    <parent link="finger_link_3_4" />
    <child link="finger_link_3_5" />
    <axis xyz="1.0 1.0 0.0" />
    <limit lower="-3.142" upper="3.142" effort="10" velocity="10" />
  </joint>
</robot>