<?xml version='1.0' encoding='utf-8'?>
<robot name="robot">
  <link name="base_link">
    <visual>
      <origin xyz="0 0 0.125" rpy="0 0 0" />
      <geometry>
        <box size="0.75 0.75 0.25" />
      </geometry>
      <material name="green" />
    </visual>
    <visual>
      <origin xyz="0 0 0.375" rpy="0 0 0" />
      <geometry>
        <cylinder length="0.25" radius="0.25" />
      </geometry>
      <material name="green">
        <color rgba="0 1 0 1" />
      </material>
    </visual>
    <collision>
      <geometry>
        <box size="0.75 0.75 0.5" />
      </geometry>
    </collision>
    <inertial>
      <mass value="0.5" />
      <inertia ixx="0.034" ixy="0.0" ixz="0.0" iyy="0.034" iyz="0.0" izz="0.034" />
    </inertial>
  </link>
  <link name="support_link">
    <visual>
      <origin xyz="0 0 0.5" rpy="0 0 0" />
      <geometry>
        <box size="0.2 0.2 1" />
      </geometry>
      <material name="white">
        <color rgba="1 1 1 1" />
      </material>
    </visual>
    <collision>
      <geometry>
        <box size="0.2 0.2 1" />
      </geometry>
    </collision>
    <inertial>
      <mass value="0.1" />
      <inertia ixx="0.01" ixy="0.0" ixz="0.0" iyy="0.01" iyz="0.0" izz="0.01" />
    </inertial>
  </link>
  <joint name="support_joint" type="continuous">
    <origin xyz="0 0 0.5" rpy="0 0 0" />
    <parent link="base_link" />
    <child link="support_link" />
    <axis xyz="0 0 1" />
  </joint>
  <link name="arm_link">
    <visual>
      <origin xyz="0 0 0.5" rpy="0 0 0" />
      <geometry>
        <box size="0.2 0.2 1" />
      </geometry>
      <material name="blue">
        <color rgba="0 0 1 1" />
      </material>
    </visual>
    <collision>
      <geometry>
        <box size="0.2 0.2 1" />
      </geometry>
    </collision>
    <inertial>
      <mass value="0.1" />
      <inertia ixx="0.01" ixy="0.0" ixz="0.0" iyy="0.01" iyz="0.0" izz="0.01" />
    </inertial>
  </link>
  <joint name="arm_joint" type="revolute">
    <origin xyz="-0.1 0 1" rpy="0 0 0" />
    <parent link="support_link" />
    <child link="arm_link" />
    <axis xyz="0 1 0" />
    <limit lower="-3.14" upper="3.14" effort="1.0" velocity="1.0" />
  </joint>
  <link name="wrist_link">
    <visual>
      <origin xyz="0 0 0.25" rpy="0 0 0" />
      <geometry>
        <box size="0.15 0.15 0.5" />
      </geometry>
      <material name="orange">
        <color rgba="1 0.5 0 1" />
      </material>
    </visual>
    <collision>
      <geometry>
        <box size="0.15 0.15 0.5" />
      </geometry>
    </collision>
    <inertial>
      <mass value="0.1" />
      <inertia ixx="0.01" ixy="0.0" ixz="0.0" iyy="0.01" iyz="0.0" izz="0.01" />
    </inertial>
  </link>
  <joint name="wrist_joint" type="fixed">
    <origin xyz="0 0 0.9" rpy="0 1.571 0" />
    <parent link="arm_link" />
    <child link="wrist_link" />
  </joint>
  <link name="palm_link">
    <visual>
      <origin xyz="0 0 0.05" rpy="0 0 0" />
      <geometry>
        <box size="0.25 0.25 0.1" />
      </geometry>
      <material name="orange" />
    </visual>
    <collision>
      <geometry>
        <box size="0.25 0.25 0.1" />
      </geometry>
    </collision>
    <inertial>
      <mass value="0.1" />
      <inertia ixx="0.01" ixy="0.0" ixz="0.0" iyy="0.01" iyz="0.0" izz="0.01" />
    </inertial>
  </link>
  <joint name="palm_joint" type="fixed">
    <origin xyz="0 0 0.45" rpy="0 0 0" />
    <parent link="wrist_link" />
    <child link="palm_link" />
  </joint>
  <link name="finger_link_0_0">
    <visual>
      <origin xyz="0 0 0.034" rpy="0 0 0" />
      <geometry>
        <box size="0.026 0.024 0.068" />
      </geometry>
    </visual>
    <collision>
      <geometry>
        <box size="0.026 0.024 0.068" />
      </geometry>
    </collision>
    <inertial>
      <mass value="0.013" />
      <inertia ixx="0.0" iyy="0.0" izz="0.0" ixy="0" ixz="0" iyz="0" />
    </inertial>
  </link>
  <joint name="finger_joint_palm_link_to_finger_link_0_0" type="revolute">
    <origin xyz="0.125 0.071 0.1" rpy="0 0 0" />
    <parent link="palm_link" />
    <child link="finger_link_0_0" />
    <axis xyz="0.0 1.0 0.0" />
    <limit lower="-3.142" upper="3.142" effort="10" velocity="10" />
  </joint>
  <link name="finger_link_0_1">
    <visual>
      <origin xyz="0 0 0.022" rpy="0 0 0" />
      <geometry>
        <box size="0.023 0.014 0.044" />
      </geometry>
    </visual>
    <collision>
      <geometry>
        <box size="0.023 0.014 0.044" />
      </geometry>
    </collision>
    <inertial>
      <mass value="0.004" />
      <inertia ixx="0.0" iyy="0.0" izz="0.0" ixy="0" ixz="0" iyz="0" />
    </inertial>
  </link>
  <joint name="finger_joint_finger_link_0_0_to_finger_link_0_1" type="revolute">
    <origin xyz="0.0 0.0 0.068" rpy="0 0 0" />
    <parent link="finger_link_0_0" />
    <child link="finger_link_0_1" />
    <axis xyz="0.0 1.0 0.0" />
    <limit lower="-3.142" upper="3.142" effort="10" velocity="10" />
  </joint>
  <link name="finger_link_0_2">
    <visual>
      <origin xyz="0 0 0.049" rpy="0 0 0" />
      <geometry>
        <box size="0.031 0.042 0.098" />
      </geometry>
    </visual>
    <collision>
      <geometry>
        <box size="0.031 0.042 0.098" />
      </geometry>
    </collision>
    <inertial>
      <mass value="0.038" />
      <inertia ixx="0.0" iyy="0.0" izz="0.0" ixy="0" ixz="0" iyz="0" />
    </inertial>
  </link>
  <joint name="finger_joint_finger_link_0_1_to_finger_link_0_2" type="revolute">
    <origin xyz="0.0 0.0 0.044" rpy="0 0 0" />
    <parent link="finger_link_0_1" />
    <child link="finger_link_0_2" />
    <axis xyz="0.0 1.0 0.0" />
    <limit lower="-3.142" upper="3.142" effort="10" velocity="10" />
  </joint>
  <link name="finger_link_1_0">
    <visual>
      <origin xyz="0 0 0.035" rpy="0 0 0" />
      <geometry>
        <box size="0.012 0.028 0.07" />
      </geometry>
    </visual>
    <collision>
      <geometry>
        <box size="0.012 0.028 0.07" />
      </geometry>
    </collision>
    <inertial>
      <mass value="0.007" />
      <inertia ixx="0.0" iyy="0.0" izz="0.0" ixy="0" ixz="0" iyz="0" />
    </inertial>
  </link>
  <joint name="finger_joint_palm_link_to_finger_link_1_0" type="revolute">
    <origin xyz="0.012 0.125 0.1" rpy="0 0 0" />
    <parent link="palm_link" />
    <child link="finger_link_1_0" />
    <axis xyz="-1.0 0.0 0.0" />
    <limit lower="-3.142" upper="3.142" effort="10" velocity="10" />
  </joint>
  <link name="finger_link_1_1">
    <visual>
      <origin xyz="0 0 0.0085" rpy="0 0 0" />
      <geometry>
        <box size="0.018 0.014 0.017" />
      </geometry>
    </visual>
    <collision>
      <geometry>
        <box size="0.018 0.014 0.017" />
      </geometry>
    </collision>
    <inertial>
      <mass value="0.001" />
      <inertia ixx="0.0" iyy="0.0" izz="0.0" ixy="0" ixz="0" iyz="0" />
    </inertial>
  </link>
  <joint name="finger_joint_finger_link_1_0_to_finger_link_1_1" type="revolute">
    <origin xyz="0.0 0.0 0.07" rpy="0 0 0" />
    <parent link="finger_link_1_0" />
    <child link="finger_link_1_1" />
    <axis xyz="0.0 1.0 0.0" />
    <limit lower="-3.142" upper="3.142" effort="10" velocity="10" />
  </joint>
  <link name="finger_link_1_2">
    <visual>
      <origin xyz="0 0 0.0235" rpy="0 0 0" />
      <geometry>
        <box size="0.022 0.011 0.047" />
      </geometry>
    </visual>
    <collision>
      <geometry>
        <box size="0.022 0.011 0.047" />
      </geometry>
    </collision>
    <inertial>
      <mass value="0.003" />
      <inertia ixx="0.0" iyy="0.0" izz="0.0" ixy="0" ixz="0" iyz="0" />
    </inertial>
  </link>
  <joint name="finger_joint_finger_link_1_1_to_finger_link_1_2" type="revolute">
    <origin xyz="0.0 0.0 0.017" rpy="0 0 0" />
    <parent link="finger_link_1_1" />
    <child link="finger_link_1_2" />
    <axis xyz="0.0 1.0 0.0" />
    <limit lower="-3.142" upper="3.142" effort="10" velocity="10" />
  </joint>
  <link name="finger_link_1_3">
    <visual>
      <origin xyz="0 0 0.032" rpy="0 0 0" />
      <geometry>
        <box size="0.042 0.018 0.064" />
      </geometry>
    </visual>
    <collision>
      <geometry>
        <box size="0.042 0.018 0.064" />
      </geometry>
    </collision>
    <inertial>
      <mass value="0.015" />
      <inertia ixx="0.0" iyy="0.0" izz="0.0" ixy="0" ixz="0" iyz="0" />
    </inertial>
  </link>
  <joint name="finger_joint_finger_link_1_2_to_finger_link_1_3" type="revolute">
    <origin xyz="0.0 0.0 0.047" rpy="0 0 0" />
    <parent link="finger_link_1_2" />
    <child link="finger_link_1_3" />
    <axis xyz="0.0 1.0 0.0" />
    <limit lower="-3.142" upper="3.142" effort="10" velocity="10" />
  </joint>
  <link name="finger_link_1_4">
    <visual>
      <origin xyz="0 0 0.012" rpy="0 0 0" />
      <geometry>
        <box size="0.034 0.019 0.024" />
      </geometry>
    </visual>
    <collision>
      <geometry>
        <box size="0.034 0.019 0.024" />
      </geometry>
    </collision>
    <inertial>
      <mass value="0.005" />
      <inertia ixx="0.0" iyy="0.0" izz="0.0" ixy="0" ixz="0" iyz="0" />
    </inertial>
  </link>
  <joint name="finger_joint_finger_link_1_3_to_finger_link_1_4" type="revolute">
    <origin xyz="0.0 0.0 0.064" rpy="0 0 0" />
    <parent link="finger_link_1_3" />
    <child link="finger_link_1_4" />
    <axis xyz="0.0 1.0 0.0" />
    <limit lower="-3.142" upper="3.142" effort="10" velocity="10" />
  </joint>
  <link name="finger_link_1_5">
    <visual>
      <origin xyz="0 0 0.02" rpy="0 0 0" />
      <geometry>
        <box size="0.015 0.02 0.04" />
      </geometry>
    </visual>
    <collision>
      <geometry>
        <box size="0.015 0.02 0.04" />
      </geometry>
    </collision>
    <inertial>
      <mass value="0.004" />
      <inertia ixx="0.0" iyy="0.0" izz="0.0" ixy="0" ixz="0" iyz="0" />
    </inertial>
  </link>
  <joint name="finger_joint_finger_link_1_4_to_finger_link_1_5" type="revolute">
    <origin xyz="0.0 0.0 0.024" rpy="0 0 0" />
    <parent link="finger_link_1_4" />
    <child link="finger_link_1_5" />
    <axis xyz="1.0 0.0 0.0" />
    <limit lower="-3.142" upper="3.142" effort="10" velocity="10" />
  </joint>
  <link name="finger_link_1_6">
    <visual>
      <origin xyz="0 0 0.0495" rpy="0 0 0" />
      <geometry>
        <box size="0.043 0.023 0.099" />
      </geometry>
    </visual>
    <collision>
      <geometry>
        <box size="0.043 0.023 0.099" />
      </geometry>
    </collision>
    <inertial>
      <mass value="0.029" />
      <inertia ixx="0.0" iyy="0.0" izz="0.0" ixy="0" ixz="0" iyz="0" />
    </inertial>
  </link>
  <joint name="finger_joint_finger_link_1_5_to_finger_link_1_6" type="revolute">
    <origin xyz="0.0 0.0 0.04" rpy="0 0 0" />
    <parent link="finger_link_1_5" />
    <child link="finger_link_1_6" />
    <axis xyz="1.0 0.0 0.0" />
    <limit lower="-3.142" upper="3.142" effort="10" velocity="10" />
  </joint>
  <link name="finger_link_1_7">
    <visual>
      <origin xyz="0 0 0.0175" rpy="0 0 0" />
      <geometry>
        <box size="0.05 0.042 0.035" />
      </geometry>
    </visual>
    <collision>
      <geometry>
        <box size="0.05 0.042 0.035" />
      </geometry>
    </collision>
    <inertial>
      <mass value="0.022" />
      <inertia ixx="0.0" iyy="0.0" izz="0.0" ixy="0" ixz="0" iyz="0" />
    </inertial>
  </link>
  <joint name="finger_joint_finger_link_1_6_to_finger_link_1_7" type="revolute">
    <origin xyz="0.0 0.0 0.099" rpy="0 0 0" />
    <parent link="finger_link_1_6" />
    <child link="finger_link_1_7" />
    <axis xyz="1.0 0.0 0.0" />
    <limit lower="-3.142" upper="3.142" effort="10" velocity="10" />
  </joint>
  <link name="finger_link_1_8">
    <visual>
      <origin xyz="0 0 0.037" rpy="0 0 0" />
      <geometry>
        <box size="0.025 0.029 0.074" />
      </geometry>
    </visual>
    <collision>
      <geometry>
        <box size="0.025 0.029 0.074" />
      </geometry>
    </collision>
    <inertial>
      <mass value="0.016" />
      <inertia ixx="0.0" iyy="0.0" izz="0.0" ixy="0" ixz="0" iyz="0" />
    </inertial>
  </link>
  <joint name="finger_joint_finger_link_1_7_to_finger_link_1_8" type="revolute">
    <origin xyz="0.0 0.0 0.035" rpy="0 0 0" />
    <parent link="finger_link_1_7" />
    <child link="finger_link_1_8" />
    <axis xyz="0.0 1.0 0.0" />
    <limit lower="-3.142" upper="3.142" effort="10" velocity="10" />
  </joint>
  <link name="finger_link_2_0">
    <visual>
      <origin xyz="0 0 0.047" rpy="0 0 0" />
      <geometry>
        <box size="0.049 0.03 0.094" />
      </geometry>
    </visual>
    <collision>
      <geometry>
        <box size="0.049 0.03 0.094" />
      </geometry>
    </collision>
    <inertial>
      <mass value="0.041" />
      <inertia ixx="0.0" iyy="0.0" izz="0.0" ixy="0" ixz="0" iyz="0" />
    </inertial>
  </link>
  <joint name="finger_joint_palm_link_to_finger_link_2_0" type="revolute">
    <origin xyz="0.039 -0.125 0.1" rpy="0 0 0" />
    <parent link="palm_link" />
    <child link="finger_link_2_0" />
    <axis xyz="1.0 0.0 0.0" />
    <limit lower="-3.142" upper="3.142" effort="10" velocity="10" />
  </joint>
  <link name="finger_link_2_1">
    <visual>
      <origin xyz="0 0 0.0305" rpy="0 0 0" />
      <geometry>
        <box size="0.048 0.03 0.061" />
      </geometry>
    </visual>
    <collision>
      <geometry>
        <box size="0.048 0.03 0.061" />
      </geometry>
    </collision>
    <inertial>
      <mass value="0.026" />
      <inertia ixx="0.0" iyy="0.0" izz="0.0" ixy="0" ixz="0" iyz="0" />
    </inertial>
  </link>
  <joint name="finger_joint_finger_link_2_0_to_finger_link_2_1" type="revolute">
    <origin xyz="0.0 0.0 0.094" rpy="0 0 0" />
    <parent link="finger_link_2_0" />
    <child link="finger_link_2_1" />
    <axis xyz="0.0 1.0 0.0" />
    <limit lower="-3.142" upper="3.142" effort="10" velocity="10" />
  </joint>
  <link name="finger_link_3_0">
    <visual>
      <origin xyz="0 0 0.0175" rpy="0 0 0" />
      <geometry>
        <box size="0.019 0.042 0.035" />
      </geometry>
    </visual>
    <collision>
      <geometry>
        <box size="0.019 0.042 0.035" />
      </geometry>
    </collision>
    <inertial>
      <mass value="0.008" />
      <inertia ixx="0.0" iyy="0.0" izz="0.0" ixy="0" ixz="0" iyz="0" />
    </inertial>
  </link>
  <joint name="finger_joint_palm_link_to_finger_link_3_0" type="revolute">
    <origin xyz="0.125 0.101 0.1" rpy="0 0 0" />
    <parent link="palm_link" />
    <child link="finger_link_3_0" />
    <axis xyz="0.0 1.0 0.0" />
    <limit lower="-3.142" upper="3.142" effort="10" velocity="10" />
  </joint>
  <link name="finger_link_3_1">
    <visual>
      <origin xyz="0 0 0.0195" rpy="0 0 0" />
      <geometry>
        <box size="0.024 0.045 0.039" />
      </geometry>
    </visual>
    <collision>
      <geometry>
        <box size="0.024 0.045 0.039" />
      </geometry>
    </collision>
    <inertial>
      <mass value="0.013" />
      <inertia ixx="0.0" iyy="0.0" izz="0.0" ixy="0" ixz="0" iyz="0" />
    </inertial>
  </link>
  <joint name="finger_joint_finger_link_3_0_to_finger_link_3_1" type="revolute">
    <origin xyz="0.0 0.0 0.035" rpy="0 0 0" />
    <parent link="finger_link_3_0" />
    <child link="finger_link_3_1" />
    <axis xyz="0.0 1.0 0.0" />
    <limit lower="-3.142" upper="3.142" effort="10" velocity="10" />
  </joint>
  <link name="finger_link_3_2">
    <visual>
      <origin xyz="0 0 0.0055" rpy="0 0 0" />
      <geometry>
        <box size="0.025 0.028 0.011" />
      </geometry>
    </visual>
    <collision>
      <geometry>
        <box size="0.025 0.028 0.011" />
      </geometry>
    </collision>
    <inertial>
      <mass value="0.002" />
      <inertia ixx="0.0" iyy="0.0" izz="0.0" ixy="0" ixz="0" iyz="0" />
    </inertial>
  </link>
  <joint name="finger_joint_finger_link_3_1_to_finger_link_3_2" type="revolute">
    <origin xyz="0.0 0.0 0.039" rpy="0 0 0" />
    <parent link="finger_link_3_1" />
    <child link="finger_link_3_2" />
    <axis xyz="0.0 1.0 0.0" />
    <limit lower="-3.142" upper="3.142" effort="10" velocity="10" />
  </joint>
  <link name="finger_link_3_3">
    <visual>
      <origin xyz="0 0 0.0055" rpy="0 0 0" />
      <geometry>
        <box size="0.049 0.04 0.011" />
      </geometry>
    </visual>
    <collision>
      <geometry>
        <box size="0.049 0.04 0.011" />
      </geometry>
    </collision>
    <inertial>
      <mass value="0.006" />
      <inertia ixx="0.0" iyy="0.0" izz="0.0" ixy="0" ixz="0" iyz="0" />
    </inertial>
  </link>
  <joint name="finger_joint_finger_link_3_2_to_finger_link_3_3" type="revolute">
    <origin xyz="0.0 0.0 0.011" rpy="0 0 0" />
    <parent link="finger_link_3_2" />
    <child link="finger_link_3_3" />
    <axis xyz="0.0 1.0 0.0" />
    <limit lower="-3.142" upper="3.142" effort="10" velocity="10" />
  </joint>
  <link name="finger_link_4_0">
    <visual>
      <origin xyz="0 0 0.0075" rpy="0 0 0" />
      <geometry>
        <box size="0.033 0.044 0.015" />
      </geometry>
    </visual>
    <collision>
      <geometry>
        <box size="0.033 0.044 0.015" />
      </geometry>
    </collision>
    <inertial>
      <mass value="0.007" />
      <inertia ixx="0.0" iyy="0.0" izz="0.0" ixy="0" ixz="0" iyz="0" />
    </inertial>
  </link>
  <joint name="finger_joint_palm_link_to_finger_link_4_0" type="revolute">
    <origin xyz="-0.107 0.125 0.1" rpy="0 0 0" />
    <parent link="palm_link" />
    <child link="finger_link_4_0" />
    <axis xyz="-1.0 0.0 0.0" />
    <limit lower="-3.142" upper="3.142" effort="10" velocity="10" />
  </joint>
  <link name="finger_link_4_1">
    <visual>
      <origin xyz="0 0 0.0165" rpy="0 0 0" />
      <geometry>
        <box size="0.013 0.038 0.033" />
      </geometry>
    </visual>
    <collision>
      <geometry>
        <box size="0.013 0.038 0.033" />
      </geometry>
    </collision>
    <inertial>
      <mass value="0.005" />
      <inertia ixx="0.0" iyy="0.0" izz="0.0" ixy="0" ixz="0" iyz="0" />
    </inertial>
  </link>
  <joint name="finger_joint_finger_link_4_0_to_finger_link_4_1" type="revolute">
    <origin xyz="0.0 0.0 0.015" rpy="0 0 0" />
    <parent link="finger_link_4_0" />
    <child link="finger_link_4_1" />
    <axis xyz="1.0 0.0 0.0" />
    <limit lower="-3.142" upper="3.142" effort="10" velocity="10" />
  </joint>
  <link name="finger_link_4_2">
    <visual>
      <origin xyz="0 0 0.0395" rpy="0 0 0" />
      <geometry>
        <box size="0.046 0.04 0.079" />
      </geometry>
    </visual>
    <collision>
      <geometry>
        <box size="0.046 0.04 0.079" />
      </geometry>
    </collision>
    <inertial>
      <mass value="0.044" />
      <inertia ixx="0.0" iyy="0.0" izz="0.0" ixy="0" ixz="0" iyz="0" />
    </inertial>
  </link>
  <joint name="finger_joint_finger_link_4_1_to_finger_link_4_2" type="revolute">
    <origin xyz="0.0 0.0 0.033" rpy="0 0 0" />
    <parent link="finger_link_4_1" />
    <child link="finger_link_4_2" />
    <axis xyz="1.0 0.0 0.0" />
    <limit lower="-3.142" upper="3.142" effort="10" velocity="10" />
  </joint>
  <link name="finger_link_4_3">
    <visual>
      <origin xyz="0 0 0.035" rpy="0 0 0" />
      <geometry>
        <box size="0.034 0.037 0.07" />
      </geometry>
    </visual>
    <collision>
      <geometry>
        <box size="0.034 0.037 0.07" />
      </geometry>
    </collision>
    <inertial>
      <mass value="0.026" />
      <inertia ixx="0.0" iyy="0.0" izz="0.0" ixy="0" ixz="0" iyz="0" />
    </inertial>
  </link>
  <joint name="finger_joint_finger_link_4_2_to_finger_link_4_3" type="revolute">
    <origin xyz="0.0 0.0 0.079" rpy="0 0 0" />
    <parent link="finger_link_4_2" />
    <child link="finger_link_4_3" />
    <axis xyz="0.0 1.0 0.0" />
    <limit lower="-3.142" upper="3.142" effort="10" velocity="10" />
  </joint>
  <link name="finger_link_4_4">
    <visual>
      <origin xyz="0 0 0.009" rpy="0 0 0" />
      <geometry>
        <box size="0.013 0.042 0.018" />
      </geometry>
    </visual>
    <collision>
      <geometry>
        <box size="0.013 0.042 0.018" />
      </geometry>
    </collision>
    <inertial>
      <mass value="0.003" />
      <inertia ixx="0.0" iyy="0.0" izz="0.0" ixy="0" ixz="0" iyz="0" />
    </inertial>
  </link>
  <joint name="finger_joint_finger_link_4_3_to_finger_link_4_4" type="revolute">
    <origin xyz="0.0 0.0 0.07" rpy="0 0 0" />
    <parent link="finger_link_4_3" />
    <child link="finger_link_4_4" />
    <axis xyz="1.0 0.0 0.0" />
    <limit lower="-3.142" upper="3.142" effort="10" velocity="10" />
  </joint>
  <link name="finger_link_5_0">
    <visual>
      <origin xyz="0 0 0.017" rpy="0 0 0" />
      <geometry>
        <box size="0.044 0.047 0.034" />
      </geometry>
    </visual>
    <collision>
      <geometry>
        <box size="0.044 0.047 0.034" />
      </geometry>
    </collision>
    <inertial>
      <mass value="0.021" />
      <inertia ixx="0.0" iyy="0.0" izz="0.0" ixy="0" ixz="0" iyz="0" />
    </inertial>
  </link>
  <joint name="finger_joint_palm_link_to_finger_link_5_0" type="revolute">
    <origin xyz="0.125 -0.081 0.1" rpy="0 0 0" />
    <parent link="palm_link" />
    <child link="finger_link_5_0" />
    <axis xyz="0.0 1.0 0.0" />
    <limit lower="-3.142" upper="3.142" effort="10" velocity="10" />
  </joint>
  <link name="finger_link_5_1">
    <visual>
      <origin xyz="0 0 0.0385" rpy="0 0 0" />
      <geometry>
        <box size="0.037 0.034 0.077" />
      </geometry>
    </visual>
    <collision>
      <geometry>
        <box size="0.037 0.034 0.077" />
      </geometry>
    </collision>
    <inertial>
      <mass value="0.029" />
      <inertia ixx="0.0" iyy="0.0" izz="0.0" ixy="0" ixz="0" iyz="0" />
    </inertial>
  </link>
  <joint name="finger_joint_finger_link_5_0_to_finger_link_5_1" type="revolute">
    <origin xyz="0.0 0.0 0.034" rpy="0 0 0" />
    <parent link="finger_link_5_0" />
    <child link="finger_link_5_1" />
    <axis xyz="1.0 0.0 0.0" />
    <limit lower="-3.142" upper="3.142" effort="10" velocity="10" />
  </joint>
  <link name="finger_link_5_2">
    <visual>
      <origin xyz="0 0 0.009" rpy="0 0 0" />
      <geometry>
        <box size="0.042 0.047 0.018" />
      </geometry>
    </visual>
    <collision>
      <geometry>
        <box size="0.042 0.047 0.018" />
      </geometry>
    </collision>
    <inertial>
      <mass value="0.011" />
      <inertia ixx="0.0" iyy="0.0" izz="0.0" ixy="0" ixz="0" iyz="0" />
    </inertial>
  </link>
  <joint name="finger_joint_finger_link_5_1_to_finger_link_5_2" type="revolute">
    <origin xyz="0.0 0.0 0.077" rpy="0 0 0" />
    <parent link="finger_link_5_1" />
    <child link="finger_link_5_2" />
    <axis xyz="1.0 0.0 0.0" />
    <limit lower="-3.142" upper="3.142" effort="10" velocity="10" />
  </joint>
  <link name="finger_link_5_3">
    <visual>
      <origin xyz="0 0 0.0335" rpy="0 0 0" />
      <geometry>
        <box size="0.037 0.019 0.067" />
      </geometry>
    </visual>
    <collision>
      <geometry>
        <box size="0.037 0.019 0.067" />
      </geometry>
    </collision>
    <inertial>
      <mass value="0.014" />
      <inertia ixx="0.0" iyy="0.0" izz="0.0" ixy="0" ixz="0" iyz="0" />
    </inertial>
  </link>
  <joint name="finger_joint_finger_link_5_2_to_finger_link_5_3" type="revolute">
    <origin xyz="0.0 0.0 0.018" rpy="0 0 0" />
    <parent link="finger_link_5_2" />
    <child link="finger_link_5_3" />
    <axis xyz="0.0 1.0 0.0" />
    <limit lower="-3.142" upper="3.142" effort="10" velocity="10" />
  </joint>
  <link name="finger_link_5_4">
    <visual>
      <origin xyz="0 0 0.0425" rpy="0 0 0" />
      <geometry>
        <box size="0.017 0.018 0.085" />
      </geometry>
    </visual>
    <collision>
      <geometry>
        <box size="0.017 0.018 0.085" />
      </geometry>
    </collision>
    <inertial>
      <mass value="0.008" />
      <inertia ixx="0.0" iyy="0.0" izz="0.0" ixy="0" ixz="0" iyz="0" />
    </inertial>
  </link>
  <joint name="finger_joint_finger_link_5_3_to_finger_link_5_4" type="revolute">
    <origin xyz="0.0 0.0 0.067" rpy="0 0 0" />
    <parent link="finger_link_5_3" />
    <child link="finger_link_5_4" />
    <axis xyz="1.0 0.0 0.0" />
    <limit lower="-3.142" upper="3.142" effort="10" velocity="10" />
  </joint>
  <link name="finger_link_5_5">
    <visual>
      <origin xyz="0 0 0.0255" rpy="0 0 0" />
      <geometry>
        <box size="0.039 0.049 0.051" />
      </geometry>
    </visual>
    <collision>
      <geometry>
        <box size="0.039 0.049 0.051" />
      </geometry>
    </collision>
    <inertial>
      <mass value="0.029" />
      <inertia ixx="0.0" iyy="0.0" izz="0.0" ixy="0" ixz="0" iyz="0" />
    </inertial>
  </link>
  <joint name="finger_joint_finger_link_5_4_to_finger_link_5_5" type="revolute">
    <origin xyz="0.0 0.0 0.085" rpy="0 0 0" />
    <parent link="finger_link_5_4" />
    <child link="finger_link_5_5" />
    <axis xyz="1.0 1.0 0.0" />
    <limit lower="-3.142" upper="3.142" effort="10" velocity="10" />
  </joint>
  <link name="finger_link_5_6">
    <visual>
      <origin xyz="0 0 0.023" rpy="0 0 0" />
      <geometry>
        <box size="0.05 0.027 0.046" />
      </geometry>
    </visual>
    <collision>
      <geometry>
        <box size="0.05 0.027 0.046" />
      </geometry>
    </collision>
    <inertial>
      <mass value="0.019" />
      <inertia ixx="0.0" iyy="0.0" izz="0.0" ixy="0" ixz="0" iyz="0" />
    </inertial>
  </link>
  <joint name="finger_joint_finger_link_5_5_to_finger_link_5_6" type="revolute">
    <origin xyz="0.0 0.0 0.051" rpy="0 0 0" />
    <parent link="finger_link_5_5" />
    <child link="finger_link_5_6" />
    <axis xyz="0.0 1.0 0.0" />
    <limit lower="-3.142" upper="3.142" effort="10" velocity="10" />
  </joint>
  <link name="finger_link_5_7">
    <visual>
      <origin xyz="0 0 0.0275" rpy="0 0 0" />
      <geometry>
        <box size="0.014 0.016 0.055" />
      </geometry>
    </visual>
    <collision>
      <geometry>
        <box size="0.014 0.016 0.055" />
      </geometry>
    </collision>
    <inertial>
      <mass value="0.004" />
      <inertia ixx="0.0" iyy="0.0" izz="0.0" ixy="0" ixz="0" iyz="0" />
    </inertial>
  </link>
  <joint name="finger_joint_finger_link_5_6_to_finger_link_5_7" type="revolute">
    <origin xyz="0.0 0.0 0.046" rpy="0 0 0" />
    <parent link="finger_link_5_6" />
    <child link="finger_link_5_7" />
    <axis xyz="1.0 0.0 0.0" />
    <limit lower="-3.142" upper="3.142" effort="10" velocity="10" />
  </joint>
  <link name="finger_link_5_8">
    <visual>
      <origin xyz="0 0 0.028" rpy="0 0 0" />
      <geometry>
        <box size="0.028 0.032 0.056" />
      </geometry>
    </visual>
    <collision>
      <geometry>
        <box size="0.028 0.032 0.056" />
      </geometry>
    </collision>
    <inertial>
      <mass value="0.015" />
      <inertia ixx="0.0" iyy="0.0" izz="0.0" ixy="0" ixz="0" iyz="0" />
    </inertial>
  </link>
  <joint name="finger_joint_finger_link_5_7_to_finger_link_5_8" type="revolute">
    <origin xyz="0.0 0.0 0.055" rpy="0 0 0" />
    <parent link="finger_link_5_7" />
    <child link="finger_link_5_8" />
    <axis xyz="0.0 1.0 0.0" />
    <limit lower="-3.142" upper="3.142" effort="10" velocity="10" />
  </joint>
</robot>