<?xml version='1.0' encoding='utf-8'?>
<robot name="robot">
  <link name="base_link">
    <visual>
      <origin xyz="0 0 0.125" rpy="0 0 0" />
      <geometry>
        <box size="0.75 0.75 0.25" />
      </geometry>
      <material name="green" />
    </visual>
    <visual>
      <origin xyz="0 0 0.375" rpy="0 0 0" />
      <geometry>
        <cylinder length="0.25" radius="0.25" />
      </geometry>
      <material name="green">
        <color rgba="0 1 0 1" />
      </material>
    </visual>
    <collision>
      <geometry>
        <box size="0.75 0.75 0.5" />
      </geometry>
    </collision>
    <inertial>
      <mass value="0.5" />
      <inertia ixx="0.034" ixy="0.0" ixz="0.0" iyy="0.034" iyz="0.0" izz="0.034" />
    </inertial>
  </link>
  <link name="support_link">
    <visual>
      <origin xyz="0 0 0.5" rpy="0 0 0" />
      <geometry>
        <box size="0.2 0.2 1" />
      </geometry>
      <material name="white">
        <color rgba="1 1 1 1" />
      </material>
    </visual>
    <collision>
      <geometry>
        <box size="0.2 0.2 1" />
      </geometry>
    </collision>
    <inertial>
      <mass value="0.1" />
      <inertia ixx="0.01" ixy="0.0" ixz="0.0" iyy="0.01" iyz="0.0" izz="0.01" />
    </inertial>
  </link>
  <joint name="support_joint" type="continuous">
    <origin xyz="0 0 0.5" rpy="0 0 0" />
    <parent link="base_link" />
    <child link="support_link" />
    <axis xyz="0 0 1" />
  </joint>
  <link name="arm_link">
    <visual>
      <origin xyz="0 0 0.5" rpy="0 0 0" />
      <geometry>
        <box size="0.2 0.2 1" />
      </geometry>
      <material name="blue">
        <color rgba="0 0 1 1" />
      </material>
    </visual>
    <collision>
      <geometry>
        <box size="0.2 0.2 1" />
      </geometry>
    </collision>
    <inertial>
      <mass value="0.1" />
      <inertia ixx="0.01" ixy="0.0" ixz="0.0" iyy="0.01" iyz="0.0" izz="0.01" />
    </inertial>
  </link>
  <joint name="arm_joint" type="revolute">
    <origin xyz="-0.1 0 1" rpy="0 0 0" />
    <parent link="support_link" />
    <child link="arm_link" />
    <axis xyz="0 1 0" />
    <limit lower="-3.14" upper="3.14" effort="1.0" velocity="1.0" />
  </joint>
  <link name="wrist_link">
    <visual>
      <origin xyz="0 0 0.25" rpy="0 0 0" />
      <geometry>
        <box size="0.15 0.15 0.5" />
      </geometry>
      <material name="orange">
        <color rgba="1 0.5 0 1" />
      </material>
    </visual>
    <collision>
      <geometry>
        <box size="0.15 0.15 0.5" />
      </geometry>
    </collision>
    <inertial>
      <mass value="0.1" />
      <inertia ixx="0.01" ixy="0.0" ixz="0.0" iyy="0.01" iyz="0.0" izz="0.01" />
    </inertial>
  </link>
  <joint name="wrist_joint" type="fixed">
    <origin xyz="0 0 0.9" rpy="0 1.571 0" />
    <parent link="arm_link" />
    <child link="wrist_link" />
  </joint>
  <link name="palm_link">
    <visual>
      <origin xyz="0 0 0.05" rpy="0 0 0" />
      <geometry>
        <box size="0.25 0.25 0.1" />
      </geometry>
      <material name="orange" />
    </visual>
    <collision>
      <geometry>
        <box size="0.25 0.25 0.1" />
      </geometry>
    </collision>
    <inertial>
      <mass value="0.1" />
      <inertia ixx="0.01" ixy="0.0" ixz="0.0" iyy="0.01" iyz="0.0" izz="0.01" />
    </inertial>
  </link>
  <joint name="palm_joint" type="fixed">
    <origin xyz="0 0 0.45" rpy="0 0 0" />
    <parent link="wrist_link" />
    <child link="palm_link" />
  </joint>
  <link name="finger_link_0_0">
    <visual>
      <origin xyz="0 0 0.01" rpy="0 0 0" />
      <geometry>
        <box size="0.023 0.017 0.02" />
      </geometry>
    </visual>
    <collision>
      <geometry>
        <box size="0.023 0.017 0.02" />
      </geometry>
    </collision>
    <inertial>
      <mass value="0.002" />
      <inertia ixx="0.0" iyy="0.0" izz="0.0" ixy="0" ixz="0" iyz="0" />
    </inertial>
  </link>
  <joint name="finger_joint_palm_link_to_finger_link_0_0" type="revolute">
    <origin xyz="-0.125 0.099 0.1" rpy="0 0 0" />
    <parent link="palm_link" />
    <child link="finger_link_0_0" />
    <axis xyz="0.0 -1.0 0.0" />
    <limit lower="-3.142" upper="3.142" effort="10" velocity="10" />
  </joint>
  <link name="finger_link_0_1">
    <visual>
      <origin xyz="0 0 0.047" rpy="0 0 0" />
      <geometry>
        <box size="0.046 0.027 0.094" />
      </geometry>
    </visual>
    <collision>
      <geometry>
        <box size="0.046 0.027 0.094" />
      </geometry>
    </collision>
    <inertial>
      <mass value="0.035" />
      <inertia ixx="0.0" iyy="0.0" izz="0.0" ixy="0" ixz="0" iyz="0" />
    </inertial>
  </link>
  <joint name="finger_joint_finger_link_0_0_to_finger_link_0_1" type="revolute">
    <origin xyz="0.0 0.0 0.02" rpy="0 0 0" />
    <parent link="finger_link_0_0" />
    <child link="finger_link_0_1" />
    <axis xyz="0.0 1.0 0.0" />
    <limit lower="-3.142" upper="3.142" effort="10" velocity="10" />
  </joint>
  <link name="finger_link_0_2">
    <visual>
      <origin xyz="0 0 0.0305" rpy="0 0 0" />
      <geometry>
        <box size="0.029 0.045 0.061" />
      </geometry>
    </visual>
    <collision>
      <geometry>
        <box size="0.029 0.045 0.061" />
      </geometry>
    </collision>
    <inertial>
      <mass value="0.024" />
      <inertia ixx="0.0" iyy="0.0" izz="0.0" ixy="0" ixz="0" iyz="0" />
    </inertial>
  </link>
  <joint name="finger_joint_finger_link_0_1_to_finger_link_0_2" type="revolute">
    <origin xyz="0.0 0.0 0.094" rpy="0 0 0" />
    <parent link="finger_link_0_1" />
    <child link="finger_link_0_2" />
    <axis xyz="0.0 1.0 0.0" />
    <limit lower="-3.142" upper="3.142" effort="10" velocity="10" />
  </joint>
  <link name="finger_link_0_3">
    <visual>
      <origin xyz="0 0 0.0425" rpy="0 0 0" />
      <geometry>
        <box size="0.018 0.042 0.085" />
      </geometry>
    </visual>
    <collision>
      <geometry>
        <box size="0.018 0.042 0.085" />
      </geometry>
    </collision>
    <inertial>
      <mass value="0.019" />
      <inertia ixx="0.0" iyy="0.0" izz="0.0" ixy="0" ixz="0" iyz="0" />
    </inertial>
  </link>
  <joint name="finger_joint_finger_link_0_2_to_finger_link_0_3" type="revolute">
    <origin xyz="0.0 0.0 0.061" rpy="0 0 0" />
    <parent link="finger_link_0_2" />
    <child link="finger_link_0_3" />
    <axis xyz="1.0 1.0 0.0" />
    <limit lower="-3.142" upper="3.142" effort="10" velocity="10" />
  </joint>
  <link name="finger_link_0_4">
    <visual>
      <origin xyz="0 0 0.0395" rpy="0 0 0" />
      <geometry>
        <box size="0.021 0.03 0.079" />
      </geometry>
    </visual>
    <collision>
      <geometry>
        <box size="0.021 0.03 0.079" />
      </geometry>
    </collision>
    <inertial>
      <mass value="0.015" />
      <inertia ixx="0.0" iyy="0.0" izz="0.0" ixy="0" ixz="0" iyz="0" />
    </inertial>
  </link>
  <joint name="finger_joint_finger_link_0_3_to_finger_link_0_4" type="revolute">
    <origin xyz="0.0 0.0 0.085" rpy="0 0 0" />
    <parent link="finger_link_0_3" />
    <child link="finger_link_0_4" />
    <axis xyz="0.0 1.0 0.0" />
    <limit lower="-3.142" upper="3.142" effort="10" velocity="10" />
  </joint>
  <link name="finger_link_0_5">
    <visual>
      <origin xyz="0 0 0.035" rpy="0 0 0" />
      <geometry>
        <box size="0.033 0.017 0.07" />
      </geometry>
    </visual>
    <collision>
      <geometry>
        <box size="0.033 0.017 0.07" />
      </geometry>
    </collision>
    <inertial>
      <mass value="0.012" />
      <inertia ixx="0.0" iyy="0.0" izz="0.0" ixy="0" ixz="0" iyz="0" />
    </inertial>
  </link>
  <joint name="finger_joint_finger_link_0_4_to_finger_link_0_5" type="revolute">
    <origin xyz="0.0 0.0 0.079" rpy="0 0 0" />
    <parent link="finger_link_0_4" />
    <child link="finger_link_0_5" />
    <axis xyz="1.0 1.0 0.0" />
    <limit lower="-3.142" upper="3.142" effort="10" velocity="10" />
  </joint>
  <link name="finger_link_0_6">
    <visual>
      <origin xyz="0 0 0.04" rpy="0 0 0" />
      <geometry>
        <box size="0.031 0.047 0.08" />
      </geometry>
    </visual>
    <collision>
      <geometry>
        <box size="0.031 0.047 0.08" />
      </geometry>
    </collision>
    <inertial>
      <mass value="0.035" />
      <inertia ixx="0.0" iyy="0.0" izz="0.0" ixy="0" ixz="0" iyz="0" />
    </inertial>
  </link>
  <joint name="finger_joint_finger_link_0_5_to_finger_link_0_6" type="revolute">
    <origin xyz="0.0 0.0 0.07" rpy="0 0 0" />
    <parent link="finger_link_0_5" />
    <child link="finger_link_0_6" />
    <axis xyz="1.0 0.0 0.0" />
    <limit lower="-3.142" upper="3.142" effort="10" velocity="10" />
  </joint>
  <link name="finger_link_0_7">
    <visual>
      <origin xyz="0 0 0.0425" rpy="0 0 0" />
      <geometry>
        <box size="0.047 0.011 0.085" />
      </geometry>
    </visual>
    <collision>
      <geometry>
        <box size="0.047 0.011 0.085" />
      </geometry>
    </collision>
    <inertial>
      <mass value="0.013" />
      <inertia ixx="0.0" iyy="0.0" izz="0.0" ixy="0" ixz="0" iyz="0" />
    </inertial>
  </link>
  <joint name="finger_joint_finger_link_0_6_to_finger_link_0_7" type="revolute">
    <origin xyz="0.0 0.0 0.08" rpy="0 0 0" />
    <parent link="finger_link_0_6" />
    <child link="finger_link_0_7" />
    <axis xyz="0.0 1.0 0.0" />
    <limit lower="-3.142" upper="3.142" effort="10" velocity="10" />
  </joint>
  <link name="finger_link_1_0">
    <visual>
      <origin xyz="0 0 0.026" rpy="0 0 0" />
      <geometry>
        <box size="0.038 0.043 0.052" />
      </geometry>
    </visual>
    <collision>
      <geometry>
        <box size="0.038 0.043 0.052" />
      </geometry>
    </collision>
    <inertial>
      <mass value="0.025" />
      <inertia ixx="0.0" iyy="0.0" izz="0.0" ixy="0" ixz="0" iyz="0" />
    </inertial>
  </link>
  <joint name="finger_joint_palm_link_to_finger_link_1_0" type="revolute">
    <origin xyz="0.125 -0.098 0.1" rpy="0 0 0" />
    <parent link="palm_link" />
    <child link="finger_link_1_0" />
    <axis xyz="0.0 1.0 0.0" />
    <limit lower="-3.142" upper="3.142" effort="10" velocity="10" />
  </joint>
  <link name="finger_link_1_1">
    <visual>
      <origin xyz="0 0 0.0175" rpy="0 0 0" />
      <geometry>
        <box size="0.016 0.017 0.035" />
      </geometry>
    </visual>
    <collision>
      <geometry>
        <box size="0.016 0.017 0.035" />
      </geometry>
    </collision>
    <inertial>
      <mass value="0.003" />
      <inertia ixx="0.0" iyy="0.0" izz="0.0" ixy="0" ixz="0" iyz="0" />
    </inertial>
  </link>
  <joint name="finger_joint_finger_link_1_0_to_finger_link_1_1" type="revolute">
    <origin xyz="0.0 0.0 0.052" rpy="0 0 0" />
    <parent link="finger_link_1_0" />
    <child link="finger_link_1_1" />
    <axis xyz="0.0 1.0 0.0" />
    <limit lower="-3.142" upper="3.142" effort="10" velocity="10" />
  </joint>
  <link name="finger_link_1_2">
    <visual>
      <origin xyz="0 0 0.038" rpy="0 0 0" />
      <geometry>
        <box size="0.048 0.041 0.076" />
      </geometry>
    </visual>
    <collision>
      <geometry>
        <box size="0.048 0.041 0.076" />
      </geometry>
    </collision>
    <inertial>
      <mass value="0.045" />
      <inertia ixx="0.0" iyy="0.0" izz="0.0" ixy="0" ixz="0" iyz="0" />
    </inertial>
  </link>
  <joint name="finger_joint_finger_link_1_1_to_finger_link_1_2" type="revolute">
    <origin xyz="0.0 0.0 0.035" rpy="0 0 0" />
    <parent link="finger_link_1_1" />
    <child link="finger_link_1_2" />
    <axis xyz="0.0 1.0 0.0" />
    <limit lower="-3.142" upper="3.142" effort="10" velocity="10" />
  </joint>
  <link name="finger_link_1_3">
    <visual>
      <origin xyz="0 0 0.03" rpy="0 0 0" />
      <geometry>
        <box size="0.015 0.043 0.06" />
      </geometry>
    </visual>
    <collision>
      <geometry>
        <box size="0.015 0.043 0.06" />
      </geometry>
    </collision>
    <inertial>
      <mass value="0.012" />
      <inertia ixx="0.0" iyy="0.0" izz="0.0" ixy="0" ixz="0" iyz="0" />
    </inertial>
  </link>
  <joint name="finger_joint_finger_link_1_2_to_finger_link_1_3" type="revolute">
    <origin xyz="0.0 0.0 0.076" rpy="0 0 0" />
    <parent link="finger_link_1_2" />
    <child link="finger_link_1_3" />
    <axis xyz="0.0 1.0 0.0" />
    <limit lower="-3.142" upper="3.142" effort="10" velocity="10" />
  </joint>
  <link name="finger_link_1_4">
    <visual>
      <origin xyz="0 0 0.0335" rpy="0 0 0" />
      <geometry>
        <box size="0.044 0.033 0.067" />
      </geometry>
    </visual>
    <collision>
      <geometry>
        <box size="0.044 0.033 0.067" />
      </geometry>
    </collision>
    <inertial>
      <mass value="0.029" />
      <inertia ixx="0.0" iyy="0.0" izz="0.0" ixy="0" ixz="0" iyz="0" />
    </inertial>
  </link>
  <joint name="finger_joint_finger_link_1_3_to_finger_link_1_4" type="revolute">
    <origin xyz="0.0 0.0 0.06" rpy="0 0 0" />
    <parent link="finger_link_1_3" />
    <child link="finger_link_1_4" />
    <axis xyz="1.0 0.0 0.0" />
    <limit lower="-3.142" upper="3.142" effort="10" velocity="10" />
  </joint>
  <link name="finger_link_1_5">
    <visual>
      <origin xyz="0 0 0.019" rpy="0 0 0" />
      <geometry>
        <box size="0.045 0.05 0.038" />
      </geometry>
    </visual>
    <collision>
      <geometry>
        <box size="0.045 0.05 0.038" />
      </geometry>
    </collision>
    <inertial>
      <mass value="0.026" />
      <inertia ixx="0.0" iyy="0.0" izz="0.0" ixy="0" ixz="0" iyz="0" />
    </inertial>
  </link>
  <joint name="finger_joint_finger_link_1_4_to_finger_link_1_5" type="revolute">
    <origin xyz="0.0 0.0 0.067" rpy="0 0 0" />
    <parent link="finger_link_1_4" />
    <child link="finger_link_1_5" />
    <axis xyz="1.0 0.0 0.0" />
    <limit lower="-3.142" upper="3.142" effort="10" velocity="10" />
  </joint>
  <link name="finger_link_1_6">
    <visual>
      <origin xyz="0 0 0.035" rpy="0 0 0" />
      <geometry>
        <box size="0.05 0.04 0.07" />
      </geometry>
    </visual>
    <collision>
      <geometry>
        <box size="0.05 0.04 0.07" />
      </geometry>
    </collision>
    <inertial>
      <mass value="0.042" />
      <inertia ixx="0.0" iyy="0.0" izz="0.0" ixy="0" ixz="0" iyz="0" />
    </inertial>
  </link>
  <joint name="finger_joint_finger_link_1_5_to_finger_link_1_6" type="revolute">
    <origin xyz="0.0 0.0 0.038" rpy="0 0 0" />
    <parent link="finger_link_1_5" />
    <child link="finger_link_1_6" />
    <axis xyz="1.0 1.0 0.0" />
    <limit lower="-3.142" upper="3.142" effort="10" velocity="10" />
  </joint>
</robot>