<?xml version='1.0' encoding='utf-8'?>
<robot name="robot">
  <link name="base_link">
    <visual>
      <origin xyz="0 0 0.125" rpy="0 0 0" />
      <geometry>
        <box size="0.75 0.75 0.25" />
      </geometry>
      <material name="green" />
    </visual>
    <visual>
      <origin xyz="0 0 0.375" rpy="0 0 0" />
      <geometry>
        <cylinder length="0.25" radius="0.25" />
      </geometry>
      <material name="green">
        <color rgba="0 1 0 1" />
      </material>
    </visual>
    <collision>
      <geometry>
        <box size="0.75 0.75 0.5" />
      </geometry>
    </collision>
    <inertial>
      <mass value="0.5" />
      <inertia ixx="0.034" ixy="0.0" ixz="0.0" iyy="0.034" iyz="0.0" izz="0.034" />
    </inertial>
  </link>
  <link name="support_link">
    <visual>
      <origin xyz="0 0 0.5" rpy="0 0 0" />
      <geometry>
        <box size="0.2 0.2 1" />
      </geometry>
      <material name="white">
        <color rgba="1 1 1 1" />
      </material>
    </visual>
    <collision>
      <geometry>
        <box size="0.2 0.2 1" />
      </geometry>
    </collision>
    <inertial>
      <mass value="0.1" />
      <inertia ixx="0.01" ixy="0.0" ixz="0.0" iyy="0.01" iyz="0.0" izz="0.01" />
    </inertial>
  </link>
  <joint name="support_joint" type="continuous">
    <origin xyz="0 0 0.5" rpy="0 0 0" />
    <parent link="base_link" />
    <child link="support_link" />
    <axis xyz="0 0 1" />
  </joint>
  <link name="arm_link">
    <visual>
      <origin xyz="0 0 0.5" rpy="0 0 0" />
      <geometry>
        <box size="0.2 0.2 1" />
      </geometry>
      <material name="blue">
        <color rgba="0 0 1 1" />
      </material>
    </visual>
    <collision>
      <geometry>
        <box size="0.2 0.2 1" />
      </geometry>
    </collision>
    <inertial>
      <mass value="0.1" />
      <inertia ixx="0.01" ixy="0.0" ixz="0.0" iyy="0.01" iyz="0.0" izz="0.01" />
    </inertial>
  </link>
  <joint name="arm_joint" type="revolute">
    <origin xyz="-0.1 0 1" rpy="0 0 0" />
    <parent link="support_link" />
    <child link="arm_link" />
    <axis xyz="0 1 0" />
    <limit lower="-3.14" upper="3.14" effort="1.0" velocity="1.0" />
  </joint>
  <link name="wrist_link">
    <visual>
      <origin xyz="0 0 0.25" rpy="0 0 0" />
      <geometry>
        <box size="0.15 0.15 0.5" />
      </geometry>
      <material name="orange">
        <color rgba="1 0.5 0 1" />
      </material>
    </visual>
    <collision>
      <geometry>
        <box size="0.15 0.15 0.5" />
      </geometry>
    </collision>
    <inertial>
      <mass value="0.1" />
      <inertia ixx="0.01" ixy="0.0" ixz="0.0" iyy="0.01" iyz="0.0" izz="0.01" />
    </inertial>
  </link>
  <joint name="wrist_joint" type="fixed">
    <origin xyz="0 0 0.9" rpy="0 1.571 0" />
    <parent link="arm_link" />
    <child link="wrist_link" />
  </joint>
  <link name="palm_link">
    <visual>
      <origin xyz="0 0 0.05" rpy="0 0 0" />
      <geometry>
        <box size="0.25 0.25 0.1" />
      </geometry>
      <material name="orange" />
    </visual>
    <collision>
      <geometry>
        <box size="0.25 0.25 0.1" />
      </geometry>
    </collision>
    <inertial>
      <mass value="0.1" />
      <inertia ixx="0.01" ixy="0.0" ixz="0.0" iyy="0.01" iyz="0.0" izz="0.01" />
    </inertial>
  </link>
  <joint name="palm_joint" type="fixed">
    <origin xyz="0 0 0.45" rpy="0 0 0" />
    <parent link="wrist_link" />
    <child link="palm_link" />
  </joint>
  <link name="finger_link_0_0">
    <visual>
      <origin xyz="0 0 0.0175" rpy="0 0 0" />
      <geometry>
        <box size="0.039 0.017 0.035" />
      </geometry>
    </visual>
    <collision>
      <geometry>
        <box size="0.039 0.017 0.035" />
      </geometry>
    </collision>
    <inertial>
      <mass value="0.007" />
      <inertia ixx="0.0" iyy="0.0" izz="0.0" ixy="0" ixz="0" iyz="0" />
    </inertial>
  </link>
  <joint name="finger_joint_palm_link_to_finger_link_0_0" type="revolute">
    <origin xyz="0.114 0.125 0.1" rpy="0 0 0" />
    <parent link="palm_link" />
    <child link="finger_link_0_0" />
    <axis xyz="-1.0 0.0 0.0" />
    <limit lower="-3.142" upper="3.142" effort="10" velocity="10" />
  </joint>
  <link name="finger_link_0_1">
    <visual>
      <origin xyz="0 0 0.0325" rpy="0 0 0" />
      <geometry>
        <box size="0.042 0.022 0.065" />
      </geometry>
    </visual>
    <collision>
      <geometry>
        <box size="0.042 0.022 0.065" />
      </geometry>
    </collision>
    <inertial>
      <mass value="0.018" />
      <inertia ixx="0.0" iyy="0.0" izz="0.0" ixy="0" ixz="0" iyz="0" />
    </inertial>
  </link>
  <joint name="finger_joint_finger_link_0_0_to_finger_link_0_1" type="revolute">
    <origin xyz="0.0 0.0 0.035" rpy="0 0 0" />
    <parent link="finger_link_0_0" />
    <child link="finger_link_0_1" />
    <axis xyz="0.0 1.0 0.0" />
    <limit lower="-3.142" upper="3.142" effort="10" velocity="10" />
  </joint>
  <link name="finger_link_1_0">
    <visual>
      <origin xyz="0 0 0.01" rpy="0 0 0" />
      <geometry>
        <box size="0.026 0.016 0.02" />
      </geometry>
    </visual>
    <collision>
      <geometry>
        <box size="0.026 0.016 0.02" />
      </geometry>
    </collision>
    <inertial>
      <mass value="0.002" />
      <inertia ixx="0.0" iyy="0.0" izz="0.0" ixy="0" ixz="0" iyz="0" />
    </inertial>
  </link>
  <joint name="finger_joint_palm_link_to_finger_link_1_0" type="revolute">
    <origin xyz="-0.112 0.125 0.1" rpy="0 0 0" />
    <parent link="palm_link" />
    <child link="finger_link_1_0" />
    <axis xyz="-1.0 0.0 0.0" />
    <limit lower="-3.142" upper="3.142" effort="10" velocity="10" />
  </joint>
  <link name="finger_link_1_1">
    <visual>
      <origin xyz="0 0 0.0065" rpy="0 0 0" />
      <geometry>
        <box size="0.036 0.013 0.013" />
      </geometry>
    </visual>
    <collision>
      <geometry>
        <box size="0.036 0.013 0.013" />
      </geometry>
    </collision>
    <inertial>
      <mass value="0.002" />
      <inertia ixx="0.0" iyy="0.0" izz="0.0" ixy="0" ixz="0" iyz="0" />
    </inertial>
  </link>
  <joint name="finger_joint_finger_link_1_0_to_finger_link_1_1" type="revolute">
    <origin xyz="0.0 0.0 0.02" rpy="0 0 0" />
    <parent link="finger_link_1_0" />
    <child link="finger_link_1_1" />
    <axis xyz="0.0 1.0 0.0" />
    <limit lower="-3.142" upper="3.142" effort="10" velocity="10" />
  </joint>
  <link name="finger_link_1_2">
    <visual>
      <origin xyz="0 0 0.027" rpy="0 0 0" />
      <geometry>
        <box size="0.032 0.046 0.054" />
      </geometry>
    </visual>
    <collision>
      <geometry>
        <box size="0.032 0.046 0.054" />
      </geometry>
    </collision>
    <inertial>
      <mass value="0.024" />
      <inertia ixx="0.0" iyy="0.0" izz="0.0" ixy="0" ixz="0" iyz="0" />
    </inertial>
  </link>
  <joint name="finger_joint_finger_link_1_1_to_finger_link_1_2" type="revolute">
    <origin xyz="0.0 0.0 0.013" rpy="0 0 0" />
    <parent link="finger_link_1_1" />
    <child link="finger_link_1_2" />
    <axis xyz="0.0 1.0 0.0" />
    <limit lower="-3.142" upper="3.142" effort="10" velocity="10" />
  </joint>
  <link name="finger_link_2_0">
    <visual>
      <origin xyz="0 0 0.049" rpy="0 0 0" />
      <geometry>
        <box size="0.048 0.037 0.098" />
      </geometry>
    </visual>
    <collision>
      <geometry>
        <box size="0.048 0.037 0.098" />
      </geometry>
    </collision>
    <inertial>
      <mass value="0.052" />
      <inertia ixx="0.0" iyy="0.0" izz="0.0" ixy="0" ixz="0" iyz="0" />
    </inertial>
  </link>
  <joint name="finger_joint_palm_link_to_finger_link_2_0" type="revolute">
    <origin xyz="-0.029 -0.125 0.1" rpy="0 0 0" />
    <parent link="palm_link" />
    <child link="finger_link_2_0" />
    <axis xyz="1.0 0.0 0.0" />
    <limit lower="-3.142" upper="3.142" effort="10" velocity="10" />
  </joint>
  <link name="finger_link_2_1">
    <visual>
      <origin xyz="0 0 0.0485" rpy="0 0 0" />
      <geometry>
        <box size="0.039 0.014 0.097" />
      </geometry>
    </visual>
    <collision>
      <geometry>
        <box size="0.039 0.014 0.097" />
      </geometry>
    </collision>
    <inertial>
      <mass value="0.016" />
      <inertia ixx="0.0" iyy="0.0" izz="0.0" ixy="0" ixz="0" iyz="0" />
    </inertial>
  </link>
  <joint name="finger_joint_finger_link_2_0_to_finger_link_2_1" type="revolute">
    <origin xyz="0.0 0.0 0.098" rpy="0 0 0" />
    <parent link="finger_link_2_0" />
    <child link="finger_link_2_1" />
    <axis xyz="1.0 0.0 0.0" />
    <limit lower="-3.142" upper="3.142" effort="10" velocity="10" />
  </joint>
  <link name="finger_link_2_2">
    <visual>
      <origin xyz="0 0 0.039" rpy="0 0 0" />
      <geometry>
        <box size="0.015 0.016 0.078" />
      </geometry>
    </visual>
    <collision>
      <geometry>
        <box size="0.015 0.016 0.078" />
      </geometry>
    </collision>
    <inertial>
      <mass value="0.006" />
      <inertia ixx="0.0" iyy="0.0" izz="0.0" ixy="0" ixz="0" iyz="0" />
    </inertial>
  </link>
  <joint name="finger_joint_finger_link_2_1_to_finger_link_2_2" type="revolute">
    <origin xyz="0.0 0.0 0.097" rpy="0 0 0" />
    <parent link="finger_link_2_1" />
    <child link="finger_link_2_2" />
    <axis xyz="1.0 1.0 0.0" />
    <limit lower="-3.142" upper="3.142" effort="10" velocity="10" />
  </joint>
  <link name="finger_link_3_0">
    <visual>
      <origin xyz="0 0 0.0225" rpy="0 0 0" />
      <geometry>
        <box size="0.021 0.046 0.045" />
      </geometry>
    </visual>
    <collision>
      <geometry>
        <box size="0.021 0.046 0.045" />
      </geometry>
    </collision>
    <inertial>
      <mass value="0.013" />
      <inertia ixx="0.0" iyy="0.0" izz="0.0" ixy="0" ixz="0" iyz="0" />
    </inertial>
  </link>
  <joint name="finger_joint_palm_link_to_finger_link_3_0" type="revolute">
    <origin xyz="0.125 0.043 0.1" rpy="0 0 0" />
    <parent link="palm_link" />
    <child link="finger_link_3_0" />
    <axis xyz="0.0 1.0 0.0" />
    <limit lower="-3.142" upper="3.142" effort="10" velocity="10" />
  </joint>
  <link name="finger_link_3_1">
    <visual>
      <origin xyz="0 0 0.014" rpy="0 0 0" />
      <geometry>
        <box size="0.024 0.024 0.028" />
      </geometry>
    </visual>
    <collision>
      <geometry>
        <box size="0.024 0.024 0.028" />
      </geometry>
    </collision>
    <inertial>
      <mass value="0.005" />
      <inertia ixx="0.0" iyy="0.0" izz="0.0" ixy="0" ixz="0" iyz="0" />
    </inertial>
  </link>
  <joint name="finger_joint_finger_link_3_0_to_finger_link_3_1" type="revolute">
    <origin xyz="0.0 0.0 0.045" rpy="0 0 0" />
    <parent link="finger_link_3_0" />
    <child link="finger_link_3_1" />
    <axis xyz="0.0 1.0 0.0" />
    <limit lower="-3.142" upper="3.142" effort="10" velocity="10" />
  </joint>
  <link name="finger_link_3_2">
    <visual>
      <origin xyz="0 0 0.047" rpy="0 0 0" />
      <geometry>
        <box size="0.048 0.02 0.094" />
      </geometry>
    </visual>
    <collision>
      <geometry>
        <box size="0.048 0.02 0.094" />
      </geometry>
    </collision>
    <inertial>
      <mass value="0.027" />
      <inertia ixx="0.0" iyy="0.0" izz="0.0" ixy="0" ixz="0" iyz="0" />
    </inertial>
  </link>
  <joint name="finger_joint_finger_link_3_1_to_finger_link_3_2" type="revolute">
    <origin xyz="0.0 0.0 0.028" rpy="0 0 0" />
    <parent link="finger_link_3_1" />
    <child link="finger_link_3_2" />
    <axis xyz="0.0 1.0 0.0" />
    <limit lower="-3.142" upper="3.142" effort="10" velocity="10" />
  </joint>
  <link name="finger_link_3_3">
    <visual>
      <origin xyz="0 0 0.0225" rpy="0 0 0" />
      <geometry>
        <box size="0.028 0.042 0.045" />
      </geometry>
    </visual>
    <collision>
      <geometry>
        <box size="0.028 0.042 0.045" />
      </geometry>
    </collision>
    <inertial>
      <mass value="0.016" />
      <inertia ixx="0.0" iyy="0.0" izz="0.0" ixy="0" ixz="0" iyz="0" />
    </inertial>
  </link>
  <joint name="finger_joint_finger_link_3_2_to_finger_link_3_3" type="revolute">
    <origin xyz="0.0 0.0 0.094" rpy="0 0 0" />
    <parent link="finger_link_3_2" />
    <child link="finger_link_3_3" />
    <axis xyz="0.0 1.0 0.0" />
    <limit lower="-3.142" upper="3.142" effort="10" velocity="10" />
  </joint>
  <link name="finger_link_3_4">
    <visual>
      <origin xyz="0 0 0.0225" rpy="0 0 0" />
      <geometry>
        <box size="0.038 0.016 0.045" />
      </geometry>
    </visual>
    <collision>
      <geometry>
        <box size="0.038 0.016 0.045" />
      </geometry>
    </collision>
    <inertial>
      <mass value="0.008" />
      <inertia ixx="0.0" iyy="0.0" izz="0.0" ixy="0" ixz="0" iyz="0" />
    </inertial>
  </link>
  <joint name="finger_joint_finger_link_3_3_to_finger_link_3_4" type="revolute">
    <origin xyz="0.0 0.0 0.045" rpy="0 0 0" />
    <parent link="finger_link_3_3" />
    <child link="finger_link_3_4" />
    <axis xyz="0.0 1.0 0.0" />
    <limit lower="-3.142" upper="3.142" effort="10" velocity="10" />
  </joint>
  <link name="finger_link_3_5">
    <visual>
      <origin xyz="0 0 0.049" rpy="0 0 0" />
      <geometry>
        <box size="0.016 0.042 0.098" />
      </geometry>
    </visual>
    <collision>
      <geometry>
        <box size="0.016 0.042 0.098" />
      </geometry>
    </collision>
    <inertial>
      <mass value="0.02" />
      <inertia ixx="0.0" iyy="0.0" izz="0.0" ixy="0" ixz="0" iyz="0" />
    </inertial>
  </link>
  <joint name="finger_joint_finger_link_3_4_to_finger_link_3_5" type="revolute">
    <origin xyz="0.0 0.0 0.045" rpy="0 0 0" />
    <parent link="finger_link_3_4" />
    <child link="finger_link_3_5" />
    <axis xyz="0.0 1.0 0.0" />
    <limit lower="-3.142" upper="3.142" effort="10" velocity="10" />
  </joint>
</robot>